Workbook

Sheet Cover
H7: Scenario Switchboard
H9: Revenue & Operating Expenses
H10: Business Segment
D11: Valuation Date: | E11: =TODAY() -> 46005 | H11: Global industrial rev(US) | I11: 2
D12: Company Name: | E12: ECOLAB inc. | H12: Global inst& spec rev(US) | I12: 2
D13: Sector: | E13: Materials | H13: Global industrial COS(US) | I13: 2
D14: Industry: | E14: Chemicals | H14: Global inst& spec COS(US) | I14: 2
D15: Rating: | E15: =IF(E23>Ke!D38,"BUY","SELL") -> SELL | H15: Goodwill | I15: 2
H16: Global industrial rev(EU) | I16: 2
D17: Current Price | E17: =DCF!B6 -> 280.06 | H17: Scenario Key
D18: Valuation Price | E18: =DCF!B24 -> 135.22598 | H18: Bull | I18: 1
D19: 12-month Valuation Price | E19: =DCF!B46 -> 140.65169 | H19: Base | I19: 2
D20: Valuation Appreciation | E20: =E18/E17-1 -> -0.51715354 | H20: Bear | I20: 3
D21: 12-mo Valuation Appreciation | E21: =E19/E17-1 -> -0.49778015
D22: Dividend Yield | E22: 0.0093
D23: Total | E23: =E21+E22 -> -0.48848015

Sheet DCF
A1: #VALUE!
H2: Share count in Millions
A3: Cost of Equity | B3: =Ke!D38 -> 0.099113049 | G3: =TODAY() -> 46005 | H3: Today | I3: =Schedules!B21 -> 282
A4: Number of Shares in thousands: | B4: =I3 -> 282 | G4: =G3+365 -> 46370 | H4: One year | I4: =Schedules!C21 -> 281.23836
G5: =G4+366 -> 46736 | H5: Two year | I5: =Schedules!D21 -> 280.60262
A6: Actual Price: | B6: 280.06 | C6: At close oct 08, 2025
G7: Price Appreciation
A8: Model Valuation: | B8: =B24 -> 135.22598 | G8: Price Appreciation | I8: =B8/$B$6-1 -> -0.51715354
A9: Model 12 Month Price Target: | B9: =B46 -> 140.65169 | G9: Price Appreciation (12 month) | I9: =B9/B6-1 -> -0.49778015
A12: Model Current Valuation with Sensitivity of Ke
C14: 46022 | D14: 46387 | E14: 46752 | F14: 47118 | G14: 47483
A15: Time period (years) | C15: =MAX((C14-$G$3)/365,0) -> 0.046575342 | D15: =MAX((D14-$G$3)/365,0) -> 1.0465753 | E15: =MAX((E14-$G$3)/365,0) -> 2.0465753 | F15: =MAX((F14-$G$3)/365,0) -> 3.0493151 | G15: =MAX((G14-$G$3)/365,0) -> 4.0493151
A16: Nominal FCFE: | C16: ='Cash flow'!F49 -> 2706.2239 | D16: ='Cash flow'!G49 -> 2337.3471 | E16: ='Cash flow'!H49 -> 2579.8435 | F16: ='Cash flow'!I49 -> 2748.9918 | G16: ='Cash flow'!J49 -> 3134.4489
A17: PV FCFE: | C17: =(C16*C15)/((1+$B$3)^C15) -> 125.48974 | D17: =D16/((1+$B$3)^D15) -> 2117.2361 | E17: =E16/((1+$B$3)^E15) -> 2126.1655 | F17: =F16/((1+$B$3)^F15) -> 2060.7359 | G17: =G16/((1+$B$3)^G15) -> 2137.8032
A19: Terminal Growth Rate | B19: 0.025
A21: Terminal Value in 2029 | B21: =G16*(1+B19)/(B3-B19) -> 43350.128 | D21: <== Implied terminal value / net income (or P/E) multiple for terminal value
A22: PV of Terminal Value | B22: =B21/(1+B3)^(G15) -> 29566.296
A23: Total PV: | B23: =SUM(C17:G17)+B22 -> 38133.726
A24: Valuation per Share ($): | B24: =B23/B4 -> 135.22598
C25: Terminal Growth Rate
B26: =B24 -> 135.22598 | C26: =D26-L27 -> 0.01 | D26: =E26-L27 -> 0.015 | E26: =F26-L27 -> 0.02 | F26: 0.025 | G26: =F26+L27 -> 0.03 | H26: =G26+L27 -> 0.035 | I26: =H26+L27 -> 0.04 | L26: 0.005
B27: =B28+L27 -> 0.11411305 | C27: 98.981907 | D27: 102.85577 | E27: 107.14125 | F27: 111.90763 | G27: 117.24067 | H27: 123.24782 | I27: 130.06551 | L27: 0.005
B28: =B29+L27 -> 0.10911305 | C28: 104.16943 | D28: 108.51409 | E28: 113.3463 | F28: 118.75299 | G28: 124.8431 | H28: 131.75495 | I28: 139.66687
B29: =B30+L27 -> 0.10411305 | C29: 109.91159 | D29: 114.81083 | E29: 120.29254 | F29: 126.46714 | G29: 133.47487 | H29: 141.49655 | I29: 150.76941
A30: Cost Of Equity Ke | B30: =Ke!D38 -> 0.099113049 | C30: 116.30184 | D30: 121.85993 | E30: 128.12059 | F30: 135.22598 | G30: 143.35946 | H30: 152.76155 | I30: 163.75417
B31: =B30-L27 -> 0.094113049 | C31: 123.45582 | D31: 129.80412 | E31: 137.00899 | F31: 145.25634 | G31: 154.79007 | H31: 165.93659 | I31: 179.14297
B32: =B31-L27 -> 0.089113049 | C32: 131.51844 | D32: 138.82465 | E32: 147.188 | F32: 156.85581 | G32: 168.15911 | H32: 181.55124 | I32: 197.67016
B33: =B32-L27 -> 0.084113049 | C33: 140.67369 | D33: 149.15522 | E33: 158.95964 | F33: 170.42266 | G33: 184.00402 | H33: 200.35071 | I33: 220.40303
A36: Model 12 Month Price Target with Sensitivity of Ke
C38: =C14 -> 46022 | D38: =D14 -> 46387 | E38: =E14 -> 46752 | F38: =F14 -> 47118 | G38: =G14 -> 47483
A39: Time period | C39: =MAX((C38-$G$4)/365,0) -> 0 | D39: =MAX((D38-$G$4)/365,0) -> 0.046575342 | E39: =MAX((E38-$G$4)/365,0) -> 1.0465753 | F39: =MAX((F38-$G$4)/365,0) -> 2.0493151 | G39: =MAX((G38-$G$4)/365,0) -> 3.0493151
A40: Nominal FCFE: | C40: 0 | D40: =D16*D39 -> 108.86274 | E40: =E16 -> 2579.8435 | F40: =F16 -> 2748.9918 | G40: =G16 -> 3134.4489
A41: PV FCFE: | C41: =(C40*C39)/((1+$B$3)^C39) -> 0 | D41: =D40/((1+$B$3)^D39) -> 108.38463 | E41: =E40/((1+$B$3)^E39) -> 2336.8963 | F41: =F40/((1+$B$3)^F39) -> 2264.9818 | G41: =G40/((1+$B$3)^G39) -> 2349.6874
A43: Terminal Value in 2030 | B43: =G40*(1+B19)/(B3-B19) -> 43350.128
A44: PV of Terminal Value | B44: =B43/(1+B3)^G39 -> 32496.702
A45: Total PV: | B45: =SUM(D41:H41)+B44 -> 39556.652
A46: Valuation per Share ($): | B46: =B45/I4 -> 140.65169
C47: Terminal Growth Rate
B48: =B46 -> 140.65169 | C48: =D48-$L$26 -> 0.01 | D48: =E48-$L$26 -> 0.015 | E48: =F48-$L$26 -> 0.02 | F48: 0.025 | G48: =F48+$L$26 -> 0.03 | H48: =G48+$L$26 -> 0.035 | I48: =H48+$L$26 -> 0.04
B49: =B50+$L$27 -> 0.11411305 | C49: 102.19482 | D49: 106.52243 | E49: 111.30987 | F49: 116.63454 | G49: 122.59224 | H49: 129.30301 | I49: 136.91926
...

Sheet ZDFhZjliYjItMDQxYy00MW

Sheet Ke
A1: #VALUE! | D1: ECL | G1: Price = E*(1+g)/(ke-g)
A2: Cost of Equity | G2: P/E = (1+g)/(ke-g)
A3: (Blue = input, Black = calculation) | G3: ke = (1+g)/(P/E) + g
C4: Historic Beta | D4: 1.08
A5: S&P 500 data | F5: Source | G5: Reference
B6: S&P500 Forward P/E | D6: 22.05 | F6: WSJ | G6: 1-Year Forward P/E for S&P
B7: Projected EPS growth rate (g S&P) | D7: 0.1111 | F7: CapIQ/Bloomberg | G7: 5-Year Projected Earnings Growth Rate for S&P
B8: Risk-free rate (Rf) | D8: 0.0396 | F8: WSJ (5/8) | G8: 10 yr T-Note
B9: Implied required return on equity (Rs&p500) | D9: =((1+D7)/D6)+D7 -> 0.16149002 | G9: { (1+ gs&p500 ) / (P/Es&p500) } + gs&p500
B10: Implied equity risk premium (Rm) | D10: =(D8-D9)*-1 -> 0.12189002 | G10: Rs&p500-Rm
A13: Beta
A14: Fedex data
B15: Current Price (P) | D15: 280.11 | F15: WorkSpace
B16: Forward EPS (E) | D16: 7.53 | F16: WorkSpace | H16: 33.06
B17: P/E ratio | D17: 37.48 | F17: WorkSpace | G17: calc | J17: Book
B18: Projected EPS growth rate (g) | D18: ='Comps no formula'!Q19 -> 0.12345 | F18: WorkSpace + Calculation | G18: Took the average | I18: Market Cap | J18: D/E Ratio | K18: Tax Rate | L18: bU = bL / (1+ ((1-t)D/E)) | M18: bL = bu (1+ ((1-t)D/E))
B19: Implied required return on equity (Re) | D19: =((1+D18)/(D17))+D18 -> 0.15342465 | G19: { (1+g) / (P/E) } +g | I19: CLX | J19: 5.2365145 | K19: 0.24 | L19: =E23/(1+((1-K19)*J19)) -> 0.10442289 | M19: =L19*(1+((1-$K$26)*$J$26)) -> 0.17596514
B20: Forward (Bf) | D20: =(D19-D8)/D10 -> 0.93383077 | G20: (Re-Rf)/Rm | I20: CHD | J20: 0.5055494 | K20: 0.23 | L20: =E24/(1+((1-K20)*J20)) -> 0.29511837 | M20: =L20*(1+((1-$K$26)*$J$26)) -> 0.49730999
I21: DD | J21: 0.3013912 | K21: 0.23 | L21: =E25/(1+((1-K21)*J21)) -> 0.88468911 | M21: =L21*(1+((1-$K$26)*$J$26)) -> 1.4908077
A22: Comparable Beta | D22: Relevered | E22: Market Beta | I22: SHW | J22: 2.4875839 | K22: 0.222 | L22: =E26/(1+((1-K22)*J22)) -> 0.41221797 | M22: =L22*(1+((1-$K$26)*$J$26)) -> 0.6946369
B23: CLX | D23: =M19 -> 0.17596514 | E23: 0.52 | F23: Workspace
B24: CHD | D24: =M20 -> 0.49730999 | E24: 0.41 | F24: Workspace
B25: DD | D25: =M21 -> 1.4908077 | E25: 1.09 | F25: Workspace | J25: D/E Ratio | K25: Tax Rate | L25: Unlevered | M25: Relevered
B26: SHW | D26: =M22 -> 0.6946369 | E26: 1.21 | F26: Workspace | I26: ECL | J26: 0.860704 | K26: 0.204 | L26: =D30/(1+((1-K26)*J26)) -> 0.64090377 | M26: =L26*(1+((1-K26)*J26)) -> 1.08
B27: Mean | D27: =AVERAGE(D23:D26) -> 0.71467992 | E27: =AVERAGE(E23:E26) -> 0.8075
A29: Historical Beta
B30: Historic (Bh) - 5-year monthly | D30: =D4 -> 1.08 | F30: WorkSpace | G30: Five-year monthly beta
A32: Cost of Equity:
B33: Historic equity risk premium | D33: 0.065 | E33: Weight | G33: Based on long-term, historic, average risk premium (see class slides, source: Damodaran)
B34: Using Forward Beta | D34: =$D$8+D20*$D$33 -> 0.100299 | E34: 0.5 | G34: Rf+Rm*Bf
B35: Using Comparable Beta | D35: =$D$8+D27*$D$33 -> 0.086054195 | E35: 0.25
B36: Using Historic Beta | D36: =$D$8+D30*$D$33 -> 0.1098 | E36: 0.25 | G36: Rf+Rm*Bh
B38: Weighted COE | D38: =SUMPRODUCT(D34:D36,E34:E36) -> 0.099113049
B40: Market COE (beta = 1) | D40: =D33+D8 -> 0.1046 | G40: Assumes beta of 1.0

Sheet Revenue
A4: Segment | B4: 2020 | C4: 2021 | D4: 2022 | E4: 2023 | F4: 2024 | G4: 2025 | H4: 2026 | I4: 2027 | J4: 2028 | K4: 2029
A5: Global Industrial | N5: Industrial water treatment, AI data center cooling, sustainability
A6: Revenue | B6: =B49 -> 6205.78 | C6: =C49 -> 6237.8 | D6: =D49 -> 7199 | E6: =E49 -> 7626.5 | F6: =F49 -> 7777.2 | G6: =G49 -> 8062.243 | H6: =H49 -> 8357.9865 | I6: =I49 -> 8636.2583 | ... K6: =K49 -> 9222.5442
A8: Global Institutional & Specialty | N8: Hospitality rebound, digital dishwashing (DishIQ), food safety
A9: Revenue | B9: =B70 -> 3553.2 | C9: =C70 -> 4179.0161 | D9: =D70 -> 4432.1 | E9: =E70 -> 4999.2 | F9: =F70 -> 5382.6 | G9: =G70 -> 5649.228 | H9: =H70 -> 5929.1352 | I9: =I70 -> 6222.9866 | ... K9: =K70 -> 6855.3511
A11: Global Healthcare & Life Sciences | N11: Biopharma purification, infection prevention
A12: Revenue | B12: =B88 -> 1181.9 | C12: =C88 -> 1181.6 | D12: =D88 -> 1510.5 | E12: =E88 -> 1586 | F12: =F88 -> 1418.8 | G12: =G88 -> 1489.0625 | H12: =H88 -> 1562.8865 | I12: =I88 -> 1631.8982 | ... K12: =K88 -> 1779.4138 | N12: The segment’s 2024 drop was likely a one-off portfolio optimization.
A14: Global Pest Elimination / Other | N14: Predictive pest tech, commercial footprint expansion
A15: Revenue | B15: =B106 -> 1084.3 | C15: =C106 -> 1218.6 | D15: =D106 -> 1326.6 | E15: =E106 -> 1066 | F15: =F106 -> 1162.8 | G15: =G106 -> 1218.951 | H15: =H106 -> 1277.8364 | I15: =I106 -> 1339.5902 | ... K15: =K106 -> 1472.2738
A17: Corporate (ChampionX and other) | N17: Non-core
A18: Revenue | B18: =B124 -> 100 | C18: =C124 -> 139.2 | D18: =D124 -> 123.8 | E18: =E124 -> 89.1 | F18: =F124 -> 0 | G18: =G124 -> 0 | H18: =H124 -> 0 | I18: =I124 -> 0 | ... K18: =K124 -> 0 | N18: Sunset of ChampionX contract by 2024
A20: Total Net Sales
A21: Grand Total Net Sales | B21: =SUM(B6+B9+B12+B15+B18) -> 12125.18 | C21: =SUM(C6+C9+C12+C15+C18) -> 12956.216 | D21: =SUM(D6+D9+D12+D15+D18) -> 14592 | E21: =SUM(E6+E9+E12+E15+E18) -> 15366.8 | F21: =SUM(F6+F9+F12+F15+F18) -> 15741.4 | G21: =SUM(G6+G9+G12+G15+G18) -> 16419.485 | H21: =SUM(H6+H9+H12+H15+H18) -> 17127.844 | I21: =SUM(I6+I9+I12+I15+I18) -> 17830.733 | ... K21: =SUM(K6+K9+K12+K15+K18) -> 19329.583
C22: =(C21-B21)/B21 -> 0.068538046 | D22: =(D21-C21)/C21 -> 0.12625476 | E22: =(E21-D21)/D21 -> 0.053097588 | F22: =(F21-E21)/E21 -> 0.024377229 | G22: =(G21-F21)/F21 -> 0.043076505 | H22: =(H21-G21)/G21 -> 0.043141427 | I22: =(I21-H21)/H21 -> 0.041037787 | J22: =(J21-I21)/I21 -> 0.041134149 | K22: =(K21-J21)/J21 -> 0.041229793
A23: Total Product & Equipment | B23: 9466.67 | C23: 10153.3 | D23: 11446.2 | E23: 12316.8 | F23: 12473.6 | G23: =G21*0.8 -> 13135.588 | H23: =H21*0.8 -> 13702.276 | I23: =I21*0.8 -> 14264.587 | J23: =J21*0.8 -> 14851.348 | K23: =K21*0.8 -> 15463.666
A24: Total Service & Lease | B24: 2323.6 | C24: 2579.8 | D24: 2741.6 | E24: 3003.4 | F24: 3267.8 | G24: =G21*0.2 -> 3283.8969 | H24: =H21*0.2 -> 3425.5689 | I24: =I21*0.2 -> 3566.1467 | J24: =J21*0.2 -> 3712.8371 | K24: =K21*0.2 -> 3865.9166
A27: 🏭 Global Industrial
A28: Region | B28: 2020 | C28: 2021 | D28: 2022 | E28: 2023 | F28: 2024 | G28: 2025 | H28: 2026 | I28: 2027 | J28: 2028 | K28: 2029
A29: United States | B29: =2564.3*'change in segment '!I7 -> 2717.036 | C29: 2603 | D29: 3129.2 | E29: 3232.5 | F29: 3320.7 | G29: =F29*(1+G30) -> 3453.528 | H29: =G29*(1+H30) -> 3591.6691 | I29: =H29*(1+I30) -> 3735.3359 | J29: =I29*(1+J30) -> 3884.7493 | K29: =J29*(1+K30) -> 4040.1393
A30: YoY growth | C30: =(C29-B29)/B29 -> -0.041970718 | D30: =(D29-C29)/C29 -> 0.20215136 | E30: =(E29-D29)/D29 -> 0.033011632 | F30: =(F29-E29)/E29 -> 0.027285383 | G30: =+CHOOSE(Cover!$I$11,G31,G32,G33) -> 0.04 | H30: =+CHOOSE(Cover!$I$11,H31,H32,H33) -> 0.04 | I30: =+CHOOSE(Cover!$I$11,I31,I32,I33) -> 0.04 | J30: =+CHOOSE(Cover!$I$11,J31,J32,J33) -> 0.04 | K30: =+CHOOSE(Cover!$I$11,K31,K32,K33) -> 0.04 | N30: Supported by steady industrial output (~1–2%) and surging AI/data-center & sustainability investment (~20–25% CAGR) driving higher-margin water and energy-efficiency demand.
A31: bull | G31: 0.06 | H31: 0.06 | I31: 0.06 | J31: 0.06 | K31: 0.06
A32: base | G32: 0.04 | H32: 0.04 | I32: 0.04 | J32: 0.04 | K32: 0.04
A33: bear | G33: 0.03 | H33: 0.03 | I33: 0.025 | J33: 0.025 | K33: 0.025
A34: Europe | B34: =1262.6*'change in segment '!I9 -> 1322.5409 | C34: 1367.1 | D34: 1433.9 | E34: 1573 | F34: 1593.7 | G34: =F34*(1+G35) -> 1641.511 | H34: =G34*(1+H35) -> 1690.7563 | I34: =H34*(1+I35) -> 1733.0252 | J34: =I34*(1+J35) -> 1776.3509 | K34: =J34*(1+K35) -> 1820.7596
A35: YoY growth | C35: =(C34-B34)/B34 -> 0.033692075 | D35: =(D34-C34)/C34 -> 0.048862556 | E35: =(E34-D34)/D34 -> 0.09700816 | F35: =(F34-E34)/E34 -> 0.013159568 | G35: =+CHOOSE(Cover!$I$16,G36,G37,G38) -> 0.03 | H35: =+CHOOSE(Cover!$I$16,H36,H37,H38) -> 0.03 | I35: =+CHOOSE(Cover!$I$16,I36,I37,I38) -> 0.025 | J35: =+CHOOSE(Cover!$I$16,J36,J37,J38) -> 0.025 | K35: =+CHOOSE(Cover!$I$16,K36,K37,K38) -> 0.025 | N35: Modest industrial production (~1–2%) growth, lifted slightly by EU Green Deal water & sustainability infrastructure investments.
A36: bull | G36: 0.04 | H36: 0.04 | I36: 0.03 | J36: 0.03 | K36: 0.03
A37: base | G37: 0.03 | H37: 0.03 | I37: 0.025 | J37: 0.025 | K37: 0.025
A38: bear | G38: 0.02 | H38: 0.02 | I38: 0.015 | J38: 0.015 | K38: 0.015
A39: Asia Pacific | B39: =747.2*'change in segment '!I11 -> 802.23325 | C39: 802.5 | D39: 888.8 | E39: 947.4 | F39: 948.9 | G39: =F39*(1+G40) -> 986.856 | H39: =G39*(1+H40) -> 1026.3302 | I39: =H39*(1+I40) -> 1062.2518 | J39: =I39*(1+J40) -> 1099.4306 | K39: =J39*(1+K40) -> 1137.9107
A40: YoY growth | C40: =(C39-B39)/B39 -> 0.00033250563 | D40: =(D39-C39)/C39 -> 0.10753894 | E40: =(E39-D39)/D39 -> 0.065931593 | F40: =(F39-E39)/E39 -> 0.0015832806 | G40: 0.04 | H40: 0.04 | I40: 0.035 | J40: 0.035 | K40: 0.035 | N40: Industrial production and GDP in the region are modest (~4–4.5%) but are uplifted by high-growth tailwinds from data-center build-out (~13–21% CAGR) and water treatment/infrastructure (~6%+ CAGR).
A41: Latin America | B41: =491.7*'change in segment '!I13 -> 517.18512 | C41: 551.5 | D41: 656.2 | E41: 772.5 | F41: 810.5 | G41: =F41*(1+G42) -> 842.92 | H41: =G41*(1+H42) -> 876.6368 | I41: =H41*(1+I42) -> 907.31909 | J41: =I41*(1+J42) -> 939.07526 | K41: =J41*(1+K42) -> 971.94289
A42: YoY growth | C42: =(C41-B41)/B41 -> 0.06634932 | D42: =(D41-C41)/C41 -> 0.18984587 | E42: =(E41-D41)/D41 -> 0.17723255 | F42: =(F41-E41)/E41 -> 0.049190939 | G42: 0.04 | H42: 0.04 | I42: 0.035 | J42: 0.035 | K42: 0.035 | N42: Regional GDP around 2.2–2.3% and industrial water/wastewater markets expanding ~5–6% CAGR, yielding mid-single-digit potential.
A43: Greater China | B43: =333*'change in segment '!I17 -> 363.4609 | C43: 394.9 | D43: 435.8 | E43: 407 | F43: 400.4 | G43: =F43*(1+G44) -> 408.408 | H43: =G43*(1+H44) -> 416.57616 | I43: =H43*(1+I44) -> 420.74192 | J43: =I43*(1+J44) -> 424.94934 | K43: =J43*(1+K44) -> 429.19883
A44: YoY growth | C44: =(C43-B43)/B43 -> 0.086499268 | D44: =(D43-C43)/C43 -> 0.10357052 | E44: =(E43-D43)/D43 -> -0.06608536 | F44: =(F43-E43)/E43 -> -0.016216216 | G44: 0.02 | H44: 0.02 | I44: 0.01 | J44: 0.01 | K44: 0.01 | N44: Slowing macro (~4.5% GDP) offset by industrial water-treatment (~7% CAGR) and data-center build-outs (~8–9% CAGR) sustaining mid-single-digit Industrial growth.
A45: India, Middle East & Africa | B45: =314.1*'change in segment '!I15 -> 326.53965 | C45: 344.4 | D45: 459.3 | E45: 491.8 | F45: 493 | G45: =F45*(1+G46) -> 512.72 | H45: =G45*(1+H46) -> 533.2288 | I45: =H45*(1+I46) -> 549.22566 | J45: =I45*(1+J46) -> 565.70243 | K45: =J45*(1+K46) -> 582.67351
A46: YoY growth | C46: =(C45-B45)/B45 -> 0.054695803 | D46: =(D45-C45)/C45 -> 0.33362369 | E46: =(E45-D45)/D45 -> 0.070759852 | F46: =(F45-E45)/E45 -> 0.0024400163 | G46: 0.04 | H46: 0.04 | I46: 0.03 | J46: 0.03 | K46: 0.03 | N46: High-growth mix — India GDP 6.6%, MENA GDP ~3%, combined with regional water infrastructure (~4% CAGR) and digital/data-center CAPEX (~12–16% CAGR).
A47: Canada | B47: =157.9*'change in segment '!I19 -> 156.78423 | C47: 174.4 | D47: 195.8 | E47: 202.3 | F47: 210 | G47: =F47*(1+G48) -> 216.3 | H47: =G47*(1+H48) -> 222.789 | I47: =H47*(1+I48) -> 228.35872 | J47: =I47*(1+J48) -> 234.06769 | K47: =J47*(1+K48) -> 239.91939
A48: YoY growth | C48: =(C47-B47)/B47 -> 0.11235674 | D48: =(D47-C47)/C47 -> 0.12270642 | E48: =(E47-D47)/D47 -> 0.03319714 | F48: =(F47-E47)/E47 -> 0.038062284 | G48: 0.03 | H48: 0.03 | I48: 0.025 | J48: 0.025 | K48: 0.025 | N48: Stable economy (GDP ~1.5%) but boosted by data-center (~14% CAGR) and industrial water (~4–6% CAGR) growth, keeping revenue above national output.
A49: Total | B49: =B47+B45+B43+B41+B39+B34+B29 -> 6205.78 | C49: =C47+C45+C43+C41+C39+C34+C29 -> 6237.8 | D49: =D47+D45+D43+D41+D39+D34+D29 -> 7199 | E49: =E47+E45+E43+E41+E39+E34+E29 -> 7626.5 | F49: =F47+F45+F43+F41+F39+F34+F29 -> 7777.2 | G49: =G47+G45+G43+G41+G39+G34+G29 -> 8062.243 | H49: =H47+H45+H43+H41+H39+H34+H29 -> 8357.9865 | I49: =I47+I45+I43+I41+I39+I34+I29 -> 8636.2583 | ... K49: =K47+K45+K43+K41+K39+K34+K29 -> 9222.5442
A51: 🏨 Global Institutional & Specialty
...

Sheet change in segment 
B3: changs in reportable segment
B4: 🏭 Global Industrial
C5: 2022 | D5: 2022 | F5: 2023 | G5: 2023 | I5: Avg percentage change
B7: United States | C7: 3129.2 | D7: 2945.1 | E7: =C7/D7 -> 1.0625106 | F7: 3232.5 | G7: 3059.3 | H7: =F7/G7 -> 1.0566143 | I7: =AVERAGE(E7,H7) -> 1.0595624
D8: =C7-D7 -> 184.1 | G8: =F7-G7 -> 173.2
B9: Europe | C9: 1433.9 | D9: 1373.6 | E9: =C9/D9 -> 1.0438992 | F9: 1573 | G9: 1496.6 | H9: =F9/G9 -> 1.051049 | I9: =AVERAGE(E9,H9) -> 1.0474741
D10: =C9-D9 -> 60.3 | G10: =F9-G9 -> 76.4
B11: Asia Pacific | C11: 888.8 | D11: 830.1 | E11: =C11/D11 -> 1.0707144 | F11: 947.4 | G11: 880 | H11: =F11/G11 -> 1.0765909 | I11: =AVERAGE(E11,H11) -> 1.0736526
D12: =C11-D11 -> 58.7 | G12: =F11-G11 -> 67.4
B13: Latin America | C13: 656.2 | D13: 621.7 | E13: =C13/D13 -> 1.055493 | F13: 772.5 | G13: 737 | H13: =F13/G13 -> 1.0481682 | I13: =AVERAGE(E13,H13) -> 1.0518306
D14: =C13-D13 -> 34.5 | G14: =F13-G13 -> 35.5
B15: India, Middle East & Africa | C15: 435.8 | D15: 419.3 | E15: =C15/D15 -> 1.0393513 | F15: 407 | G15: 391.4 | H15: =F15/G15 -> 1.0398569 | I15: =AVERAGE(E15,H15) -> 1.0396041
D16: =C15-D15 -> 16.5 | G16: =F15-G15 -> 15.6
B17: Greater China | C17: 459.3 | D17: 419.4 | E17: =C17/D17 -> 1.0951359 | F17: 491.8 | G17: 452.1 | H17: =F17/G17 -> 1.0878124 | I17: =AVERAGE(E17,H17) -> 1.0914742
D18: =C17-D17 -> 39.9 | G18: =F17-G17 -> 39.7
B19: Canada | C19: 195.8 | D19: 195.8 | E19: =C19/D19 -> 1 | F19: 202.3 | G19: 205.2 | H19: =F19/G19 -> 0.98586745 | I19: =AVERAGE(E19,H19) -> 0.99293372
D20: =C19-D19 -> 0
B21: Total | C21: =C9+C11+C13+C15+C17+C19+C7 -> 7199 | D21: =D9+D11+D13+D15+D17+D19+D7 -> 6805 | E21: =C21/D21 -> 1.0578986 | F21: =F9+F11+F13+F15+F17+F19+F7 -> 7626.5 | G21: =G9+G11+G13+G15+G17+G19+G7 -> 7221.6 | H21: =F21/G21 -> 1.0560679
B24: 🪳 Global Pest Elimination / Other
C25: 2022 | D25: 2022 | E25: % change | F25: 2023 | G25: 2023 | H25: %change | I25: avg % change
B26: United States | C26: 650.3 | D26: 816 | E26: =C26/D26 -> 0.79693627 | F26: 733.6 | G26: 898.6 | H26: =F26/G26 -> 0.81638104 | I26: =AVERAGE(E26,H26) -> 0.80665866
D27: =C26-D26 -> -165.7 | G27: =F26-G26 -> -165
B28: Europe | C28: 154.7 | D28: 272.7 | E28: =C28/D28 -> 0.56729006 | F28: 171 | G28: 301.7 | H28: =F28/G28 -> 0.5667882 | I28: =AVERAGE(E28,H28) -> 0.56703913
D29: =C28-D28 -> -118 | G29: =F28-G28 -> -130.7
B30: Asia Pacific | C30: 27.9 | D30: 76.1 | E30: =C30/D30 -> 0.36662286 | F30: 28.7 | G30: 85.9 | H30: =F30/G30 -> 0.33410943 | I30: =AVERAGE(E30,H30) -> 0.35036615
D31: =C30-D30 -> -48.2 | G31: =F30-G30 -> -57.2
B32: Latin America | C32: 51.8 | D32: 51.9 | E32: =C32/D32 -> 0.99807322 | F32: 57.5 | G32: 57.6 | H32: =F32/G32 -> 0.99826389 | I32: =AVERAGE(E32,H32) -> 0.99816855
D33: =C32-D32 -> -0.1 | G33: =F32-G32 -> -0.1
B34: India, Middle East & Africa | C34: 8.1 | D34: 10.3 | E34: =C34/D34 -> 0.78640777 | F34: 57.4 | G34: 69.2 | H34: =F34/G34 -> 0.82947977 | I34: =AVERAGE(E34,H34) -> 0.80794377
D35: =C34-D34 -> -2.2 | G35: =F34-G34 -> -11.8
B36: Greater China | C36: 56.8 | D36: 68.6 | E36: =C36/D36 -> 0.82798834 | F36: 6.9 | G36: 9 | H36: =F36/G36 -> 0.76666667 | I36: =AVERAGE(E36,H36) -> 0.7973275
D37: =C36-D36 -> -11.8 | G37: =F36-G36 -> -2.1
B38: Canada | C38: 9.4 | D38: 20.8 | E38: =C38/D38 -> 0.45192308 | F38: 10.9 | G38: 22.2 | H38: =F38/G38 -> 0.49099099 | I38: =AVERAGE(E38,H38) -> 0.47145703
D39: =C38-D38 -> -11.4
B40: Total | C40: =C26+C28+C30+C32+C34+C36+C38 -> 959 | D40: =D26+D28+D30+D32+D34+D36+D38 -> 1316.4 | E40: =C40/D40 -> 0.72850198 | F40: =F26+F28+F30+F32+F34+F36+F38 -> 1066 | G40: =G26+G28+G30+G32+G34+G36+G38 -> 1444.2 | H40: =F40/G40 -> 0.73812491

Sheet Cost of sales
A3: Segment | B3: 2020 | C3: 2021 | D3: 2022 | E3: 2023 | F3: 2024 | G3: 2025 | H3: 2026 | I3: 2027 | J3: 2028 | K3: 2029 | L3: 2029
A4: Global Industrial
A5: Revenue | B5: 5870.8 | C5: 6237.8 | D5: 6805 | E5: 7626.5 | F5: 7777.2 | G5: 8095.45 | H5: 8427.3891 | I5: 8726.7424 | J5: 9037.5581 | K5: 9360.296
A6: Op.income | B6: 1079.1 | C6: 985.7 | D6: 977
A7: Op.margin | B7: 0.105 | C7: 0.132 | D7: 0.119 | E7: 0.14 | F7: 0.166 | G7: =AVERAGE(D7:F7) -> 0.14166667 | H7: =AVERAGE(E7:G7) -> 0.14922222 | I7: =AVERAGE(F7:H7) -> 0.1522963 | J7: =AVERAGE(G7:I7) -> 0.1477284 | K7: =AVERAGE(H7:J7) -> 0.14974897 | M7: Numbers rounded from Ecolab’s Segment Results table in the Form 10-K; “Operating income ÷ Net sales.”
A8: SG&A | B8: ='Income statement'!$B$11/'Income statement'!$B$7 -> 0.28066363 | C8: ='Income statement'!$C$11/'Income statement'!$C$7 -> 0.26828502 | D8: ='Income statement'!$D$11/'Income statement'!$D$7 -> 0.25753112 | E8: ='Income statement'!$E$11/'Income statement'!$E$7 -> 0.26511403 | F8: ='Income statement'!$F$11/'Income statement'!$F$7 -> 0.26860381 | G8: 0.26 | H8: 0.26 | I8: 0.26 | J8: 0.26 | K8: 0.26
A9: cost of sales | B9: =B5*(1-B8-B7) -> 3606.6459 | C9: =C5*(1-C8-C7) -> 3740.9021 | D9: =D5*(1-D8-D7) -> 4242.7057 | E9: 4769.7 | F9: 4691.2 | G9: =G5*(1-G8-G7) -> 4843.7776 | H9: =H5*(1-H8-H7) -> 4978.7142 | I9: =I5*(1-I8-I7) -> 5128.7388 | J9: =J5*(1-J8-J7) -> 5352.689 | K9: =K5*(1-K8-K7) -> 5524.9243 | M9: cos=revenue-sga(26%)-operating margin
A10: Global Institutional & Specialty
A11: Revenue | B11: 3553.2 | C11: 3955.9 | D11: 4421.9 | E11: 4999.2 | F11: 5382.6 | G11: 5686.363 | H11: 6007.49 | I11: 6346.9841 | J11: 6705.9064 | K11: 7085.3802
A12: Op.income | B12: 316.3 | C12: 545.7 | D12: 634.5
A13: Op.margin | B13: =316.3/B11 -> 0.08901835 | C13: 0.102 | D13: 0.095 | E13: 0.12 | F13: 0.138 | G13: =AVERAGE(D13:F13) -> 0.11766667 | H13: =AVERAGE(E13:G13) -> 0.12522222 | I13: =AVERAGE(F13:H13) -> 0.12696296 | J13: =AVERAGE(G13:I13) -> 0.12328395 | K13: =AVERAGE(H13:J13) -> 0.12515638 | M13: Numbers rounded from Ecolab’s Segment Results table in the Form 10-K; “Operating income ÷ Net sales.”
A14: SG&A | B14: ='Income statement'!$B$11/'Income statement'!$B$7 -> 0.28066363 | C14: ='Income statement'!$C$11/'Income statement'!$C$7 -> 0.26828502 | D14: ='Income statement'!$D$11/'Income statement'!$D$7 -> 0.25753112 | E14: ='Income statement'!$E$11/'Income statement'!$E$7 -> 0.26511403 | F14: ='Income statement'!$F$11/'Income statement'!$F$7 -> 0.26860381 | G14: 0.26 | H14: 0.26 | I14: 0.26 | J14: 0.26 | K14: 0.26
A15: cost of sales | B15: =B11*(1-B14-B13) -> 2239.646 | C15: =C11*(1-C14-C13) -> 2491.0895 | D15: =D11*(1-D14-D13) -> 2863.0426 | E15: 2727.3 | F15: 2727 | G15: =G11*(1-G14-G13) -> 3538.8132 | H15: =H11*(1-H14-H13) -> 3693.2714 | I15: =I11*(1-I14-I13) -> 3890.9363 | J15: =J11*(1-J14-J13) -> 4135.6401 | K15: =K11*(1-K14-K13) -> 4356.4008 | M15: cos=revenue-sga(26%)-operating margin
A16: Global Healthcare & Life Sciences
A17: Revenue | B17: 1181.9 | C17: 1181.6 | D17: 1510.5 | E17: 1586 | F17: 1418.8 | G17: 1489.0625 | H17: 1562.8865 | I17: 1631.8982 | J17: 1704.0257 | K17: 1779.4138
A18: Op.income | B18: 207.6 | C18: 152.3 | D18: 205
A19: Op.margin | B19: 0.062 | C19: 0.07 | D19: 0.07 | E19: 0.085 | F19: 0.098 | G19: =AVERAGE(D19:F19) -> 0.084333333 | H19: =AVERAGE(E19:G19) -> 0.089111111 | I19: =AVERAGE(F19:H19) -> 0.090481481 | J19: =AVERAGE(G19:I19) -> 0.087975309 | K19: =AVERAGE(H19:J19) -> 0.0891893 | M19: Numbers rounded from Ecolab’s Segment Results table in the Form 10-K; “Operating income ÷ Net sales.”
A20: SG&A | B20: ='Income statement'!$B$11/'Income statement'!$B$7 -> 0.28066363 | C20: ='Income statement'!$C$11/'Income statement'!$C$7 -> 0.26828502 | D20: ='Income statement'!$D$11/'Income statement'!$D$7 -> 0.25753112 | E20: ='Income statement'!$E$11/'Income statement'!$E$7 -> 0.26511403 | F20: ='Income statement'!$F$11/'Income statement'!$F$7 -> 0.26860381 | G20: 0.26 | H20: 0.26 | I20: 0.26 | J20: 0.26 | K20: 0.26
A21: cost of sales | B21: =B17*(1-B20-B19) -> 776.90585 | C21: =C17*(1-C20-C19) -> 781.88242 | D21: =D17*(1-D20-D19) -> 1015.7642 | E21: 1026.9 | F21: 895 | G21: =G17*(1-G20-G19) -> 976.32865 | H21: =H17*(1-H20-H19) -> 1017.2655 | I21: =I17*(1-I20-I19) -> 1059.9481 | J21: =J17*(1-J20-J19) -> 1111.0669 | K21: =K17*(1-K20-K19) -> 1158.0615 | M21: cos=revenue-sga(26%)-operating margin
A22: Global Pest Elimination / Other
A23: Revenue | B23: 1084.3 | C23: 1218.6 | D23: 1326.6 | E23: 1066 | F23: 1162.8 | G23: 1218.951 | H23: 1277.8364 | I23: 1339.5902 | J23: 1404.3535 | K23: 1472.2738
A24: Op.income | B24: 130.6 | C24: 184 | D24: 212
A25: Op.margin | B25: 0.115 | C25: 0.118 | D25: 0.118 | E25: 0.126 | F25: 0.13 | G25: =AVERAGE(D25:F25) -> 0.12466667 | H25: =AVERAGE(E25:G25) -> 0.12688889 | I25: =AVERAGE(F25:H25) -> 0.12718519 | J25: =AVERAGE(G25:I25) -> 0.12624691 | K25: =AVERAGE(H25:J25) -> 0.12677366 | M25: Numbers rounded from Ecolab’s Segment Results table in the Form 10-K; “Operating income ÷ Net sales.”
A26: SG&A | B26: ='Income statement'!$B$11/'Income statement'!$B$7 -> 0.28066363 | C26: ='Income statement'!$C$11/'Income statement'!$C$7 -> 0.26828502 | D26: ='Income statement'!$D$11/'Income statement'!$D$7 -> 0.25753112 | E26: ='Income statement'!$E$11/'Income statement'!$E$7 -> 0.26511403 | F26: ='Income statement'!$F$11/'Income statement'!$F$7 -> 0.26860381 | G26: 0.26 | H26: 0.26 | I26: 0.26 | J26: 0.26 | K26: 0.26
A27: cost of sales | B27: =B23*(1-B26-B25) -> 655.28192 | C27: =C23*(1-C26-C25) -> 747.87307 | D27: =D23*(1-D26-D25) -> 828.42042 | E27: 595 | F27: 655 | G27: =G23*(1-G26-G25) -> 750.06118 | H27: =H23*(1-H26-H25) -> 783.45567 | I27: =I23*(1-I26-I25) -> 820.92075 | J27: =J23*(1-J26-J25) -> 861.92628 | K27: =K23*(1-K26-K25) -> 902.83705 | M27: cos=revenue-sga(26%)-operating margin
A28: Corporate (ChampionX and other)
A29: Revenue | B29: 100 | C29: 139.2 | D29: 123.8 | E29: 89.1 | F29: -42.5 | G29: 42.2 | H29: -42.2 | I29: 42.2 | J29: -42.2 | K29: 42.2
B30: -347.7 | C30: -316.6 | D30: -416.7 | E30: 63.3 | F30: 5.4
M32: cos=revenue-sga(26%)-operating margin
A33: Total Net Sales
A34: Grand Total Net Sales | B34: =B5+B11+B17+B23+B29 -> 11790.2 | C34: =C5+C11+C17+C23+C29 -> 12733.1 | D34: =D5+D11+D17+D23+D29 -> 14187.8 | E34: =E5+E11+E17+E23+E29 -> 15366.8 | F34: =F5+F11+F17+F23+F29 -> 15698.9 | G34: =G5+G11+G17+G23+G29 -> 16532.027 | H34: =H5+H11+H17+H23+H29 -> 17233.402 | I34: =I5+I11+I17+I23+I29 -> 18087.415 | ... K34: =K5+K11+K17+K23+K29 -> 19739.564
B37: =B9+B15+B21+B27 -> 7278.4797 | C37: =C9+C15+C21+C27 -> 7761.7471 | D37: =D9+D15+D21+D27 -> 8949.9331 | E37: =E9+E15+E21+E27 -> 9118.9 | F37: =F9+F15+F21+F27 -> 8968.2 | G37: =G9+G15+G21+G27 -> 10108.981 | H37: =H9+H15+H21+H27 -> 10472.707 | I37: =I9+I15+I21+I27 -> 10900.544 | ... K37: =K9+K15+K21+K27 -> 11942.224
B38: 9.8 | C38: 47.5 | D38: -50.1

Sheet COGS
A3: Segment / Line Item | B3: 2022 | C3: 2023 | D3: 2024 | E3: 2025 | F3: 2026 | G3: 2027 | H3: 2028 | I3: 2029
A4: 🏭 Global Industrial
A5: Net Sales | B5: 7172.6 | C5: 7640.5 | D5: 7857.2 | E5: =Revenue!G6 -> 8062.243 | F5: =Revenue!H6 -> 8357.9865 | G5: =Revenue!I6 -> 8636.2583 | H5: =Revenue!J6 -> 8924.3255 | I5: =Revenue!K6 -> 9222.5442
A6: Cost of Sales (COS) | B6: 4692.1 | C6: 4769.7 | D6: 4691.2 | E6: =E5*E7 -> 4837.3458 | F6: =F5*F7 -> 5014.7919 | G6: =G5*G7 -> 5181.755 | H6: =H5*H7 -> 5354.5953 | I6: =I5*I7 -> 5533.5265
B7: =B6/B5 -> 0.65417004 | C7: =C6/C5 -> 0.62426543 | D7: =D6/D5 -> 0.59705748 | E7: =+CHOOSE(Cover!$I$13,E8,E9,E10) -> 0.6 | F7: =+CHOOSE(Cover!$I$13,F8,F9,F10) -> 0.6 | G7: =+CHOOSE(Cover!$I$13,G8,G9,G10) -> 0.6 | H7: =+CHOOSE(Cover!$I$13,H8,H9,H10) -> 0.6 | I7: =+CHOOSE(Cover!$I$13,I8,I9,I10) -> 0.6 | L7: COS (% of sales): Held ~60% as 2024 price/cost tailwinds persist but are tempered by reinvestment, consistent with the company’s margin expansion drivers.
A8: bull | E8: 0.58 | F8: 0.58 | G8: 0.58 | H8: 0.58 | I8: 0.58
A9: base | E9: 0.6 | F9: 0.6 | G9: 0.6 | H9: 0.6 | I9: 0.6
A10: bear | E10: 0.62 | F10: 0.62 | G10: 0.62 | H10: 0.62 | I10: 0.62
A11: SG&A | B11: 1531.6 | C11: 1748.8 | D11: 1865.4 | E11: =E12*E5 -> 1934.9383 | F11: =F12*F5 -> 2005.9167 | G11: =G12*G5 -> 2072.702 | H11: =H12*H5 -> 2141.8381 | I11: =I12*I5 -> 2213.4106
B12: =B11/B5 -> 0.21353484 | C12: =C11/C5 -> 0.22888554 | D12: =D11/D5 -> 0.23741282 | E12: 0.24 | F12: 0.24 | G12: 0.24 | H12: 0.24 | I12: 0.24 | L12: SG&A (% of sales): ~24% (steady) to reflect ongoing growth investments vs. productivity (company SG&A ratio sat ~26.9% in 2024).
A13: Special (gains) & charges | B13: – | C13: – | D13: – | L13: Specials: None at the segment level because ECL does not allocate specials to reportable segments.
A14: 🏨 Global Institutional & Specialty
A15: Net Sales | B15: 4433.2 | C15: 5014.6 | D15: 5413.9 | E15: =Revenue!G9 -> 5649.228 | F15: =Revenue!H9 -> 5929.1352 | G15: =Revenue!I9 -> 6222.9866 | H15: =Revenue!J9 -> 6531.4807 | I15: =Revenue!K9 -> 6855.3511
A16: Cost of Sales (COS) | B16: 2491.3 | C16: 2727.3 | D16: 2727.5 | E16: =E15*E17 -> 2824.614 | F16: =F15*F17 -> 2964.5676 | G16: =G15*G17 -> 3111.4933 | H16: =H15*H17 -> 3265.7403 | I16: =I15*I17 -> 3427.6755
B17: =B16/B15 -> 0.56196427 | C17: =C16/C15 -> 0.54387189 | D17: =D16/D15 -> 0.50379578 | E17: =+CHOOSE(Cover!$I$14,E18,E19,E20) -> 0.5 | F17: =+CHOOSE(Cover!$I$14,F18,F19,F20) -> 0.5 | G17: =+CHOOSE(Cover!$I$14,G18,G19,G20) -> 0.5 | H17: =+CHOOSE(Cover!$I$14,H18,H19,H20) -> 0.5 | I17: =+CHOOSE(Cover!$I$14,I18,I19,I20) -> 0.5 | L17: Moves toward 50% as 2024 margin drivers (value pricing, lower delivered costs) carry forward.
A18: bull | E18: 0.48 | F18: 0.48 | G18: 0.48 | H18: 0.48 | I18: 0.48
A19: base | E19: 0.5 | F19: 0.5 | G19: 0.5 | H19: 0.5 | I19: 0.5
A20: bear | E20: 0.52 | F20: 0.52 | G20: 0.52 | H20: 0.52 | I20: 0.52
A21: SG&A | B21: 1310 | C21: 1445.5 | D21: 1503.7 | E21: =E22*E15 -> 1581.7838 | F21: =F22*F15 -> 1660.1579 | G21: =G22*G15 -> 1742.4362 | H21: =H22*H15 -> 1828.8146 | I21: =I22*I15 -> 1919.4983
B22: =B21/B15 -> 0.29549761 | C22: =C21/C15 -> 0.28825829 | D22: =D21/D15 -> 0.27774802 | E22: 0.28 | F22: 0.28 | G22: 0.28 | H22: 0.28 | I22: 0.28 | L22: ~28% (flat) reflecting scale benefits offset by continued commercial investment.
A23: Special (gains) & charges | B23: – | C23: – | D23: – | L23: Not allocated to segments.
A24: 🧬 Global Healthcare & Life Sciences
A25: Net Sales | B25: 1534.3 | C25: 1607.5 | D25: 1434.1 | E25: =Revenue!G12 -> 1489.0625 | F25: =Revenue!H12 -> 1562.8865 | G25: =Revenue!I12 -> 1631.8982 | H25: =Revenue!J12 -> 1704.0257 | I25: =Revenue!K12 -> 1779.4138
A26: Cost of Sales (COS) | B26: 956.2 | C26: 1026.9 | D26: 895.1 | E26: =E25*E27 -> 923.21875 | F26: =F25*F27 -> 968.98963 | G26: =G25*G27 -> 1011.7769 | H26: =H25*H27 -> 1056.496 | I26: =I25*I27 -> 1103.2366
B27: =B26/B25 -> 0.6232158 | C27: =C26/C25 -> 0.63881804 | D27: =D26/D25 -> 0.62415452 | E27: 0.62 | F27: 0.62 | G27: 0.62 | H27: 0.62 | I27: 0.62 | L27: Kept ~62% as mix/volume headwinds offset pricing—consistent with MD&A noting pricing gains partly offset by lower volumes.
A28: SG&A | B28: 384.7 | C28: 419.8 | D28: 391.8 | E28: =E29*E25 -> 387.15625 | F28: =F29*F25 -> 406.35049 | G28: =G29*G25 -> 424.29353 | H28: =H29*H25 -> 443.04669 | I28: =I29*I25 -> 462.64759
B29: =B28/B25 -> 0.25073323 | C29: =C28/C25 -> 0.26115086 | D29: =D28/D25 -> 0.27320271 | E29: 0.26 | F29: 0.26 | G29: 0.26 | H29: 0.26 | I29: 0.26 | L29: ~26–27% (steady) to reflect ongoing reinvestment while scaling Life Sciences.
A30: Special (gains) & charges | B30: – | C30: – | D30: – | L30: Not allocated to segments.
A31: 🪳 Global Pest Elimination
A32: Net Sales | B32: 963.5 | C32: 1070.2 | D32: 1167.8 | E32: ='Cost of sales'!G23 -> 1218.951 | F32: ='Cost of sales'!H23 -> 1277.8364 | G32: ='Cost of sales'!I23 -> 1339.5902 | H32: ='Cost of sales'!J23 -> 1404.3535 | I32: ='Cost of sales'!K23 -> 1472.2738
A33: Cost of Sales (COS) | B33: 537.8 | C33: 595 | D33: 655 | E33: =E32*E34 -> 683.68976 | F33: =F32*F34 -> 716.7176 | G33: =G32*G34 -> 751.35435 | H33: =H32*H34 -> 787.67899 | I33: =I32*I34 -> 825.77438
B34: =B33/B32 -> 0.55817333 | C34: =C33/C32 -> 0.55597085 | D34: =D33/D32 -> 0.56088371 | E34: =D34 -> 0.56088371 | F34: =E34 -> 0.56088371 | G34: =F34 -> 0.56088371 | H34: =G34 -> 0.56088371 | I34: =H34 -> 0.56088371 | L34: ~56% (service-heavy model; stable).
A35: SG&A | B35: 228.4 | C35: 264.8 | D35: 292.4 | E35: =E36*E32 -> 304.73775 | F35: =F36*F32 -> 319.45909 | G35: =G36*G32 -> 334.89756 | H35: =H36*H32 -> 351.08837 | I35: =I36*I32 -> 368.06844
B36: =B35/B32 -> 0.23705241 | C36: =C35/C32 -> 0.24743039 | D36: =D35/D32 -> 0.25038534 | E36: 0.25 | F36: 0.25 | G36: 0.25 | H36: 0.25 | I36: 0.25 | L36: ~25% (stable) as digital tools scale field productivity.
A37: Special (gains) & charges | B37: – | C37: – | D37: – | L37: Not allocated to segments.
A38: 🏢 Corporate / Other
A39: Net Sales | B39: 89.2 | C39: 42.7 | D39: -5.4 | E39: 0 | F39: 0 | G39: 0 | H39: 0 | I39: 0 | L39: Modeled to zero as transitional ChampionX product sales in Corporate wind down.
A40: Cost of Sales (COS) | B40: 159 | C40: 63.3 | D40: 199.3 | E40: 0 | F40: 0 | G40: 0 | H40: 0 | I40: 0 | L40: Modeled to zero as transitional ChampionX product sales in Corporate wind down.
A41: SG&A | B41: 204 | C41: 200.8 | D41: 188.9 | E41: 200 | F41: 200 | G41: 200 | H41: 200 | I41: 200 | L41: Flat ~$200mm proxy for HQ, shared services and unallocated amortization (Corporate includes Nalco/Purolite intangible amortization and specials).
A42: Special (gains) & charges | B42: 140.5 | C42: 111.4 | D42: -188.9 | E42: 100 | F42: 100 | G42: 100 | H42: 100 | I42: 100 | L42: Normalized at $100mm per year to reflect recurring restructuring/integration activity, informed by recent history and the multi-year One Ecolab program through 2027.
...

Sheet Temporary
A3: Segment | B3: 2020 | C3: 2021 | D3: 2022 | E3: 2023 | F3: 2024 | G3: 2025 | H3: 2026 | I3: 2027 | J3: 2028 | K3: 2029
A4: Global Industrial | N4: Industrial water treatment, AI data center cooling, sustainability
A5: Product & Equipment Sales | B5: 5052.3 | C5: 5372 | D5: 6303.9 | E5: 6710.8 | F5: 6810.8 | G5: =F5*(1+G6) -> 7355.664 | H5: =G5*(1+H6) -> 7944.1171 | I5: =H5*(1+I6) -> 8579.6465 | J5: =I5*(1+J6) -> 9266.0182 | K5: =J5*(1+K6) -> 10007.3
C6: =(C5-B5)/B5 -> 0.063278111 | D6: =(D5-C5)/C5 -> 0.17347357 | E6: =(E5-D5)/D5 -> 0.064547344 | F6: =(F5-E5)/E5 -> 0.014901353 | G6: =8% -> 0.08 | H6: =8% -> 0.08 | I6: =8% -> 0.08 | J6: =8% -> 0.08 | K6: =8% -> 0.08
A7: Service & Lease Sales | B7: 818.5 | C7: 865.8 | D7: 893.2 | E7: 915.7 | F7: 966.4 | G7: =F7*(1+G8) -> 1007.4704 | H7: =G7*(1+H8) -> 1050.2863 | I7: =H7*(1+I8) -> 1094.9217 | J7: =I7*(1+J8) -> 1141.4541 | K7: =J7*(1+K8) -> 1189.9641
C8: =(C7-B7)/B7 -> 0.057788638 | D8: =(D7-C7)/C7 -> 0.031647032 | E8: =(E7-D7)/D7 -> 0.025190327 | F8: =(F7-E7)/E7 -> 0.055367478 | G8: =AVERAGE(C8:F8) -> 0.042498369 | H8: 0.042498369 | I8: 0.042498369 | J8: 0.042498369 | K8: 0.042498369
A9: Global Institutional & Specialty | N9: Hospitality rebound, digital dishwashing (DishIQ), food safety
A10: Product & Equipment Sales | B10: 2968.7 | C10: 3265.5 | D10: 3655.1 | E10: 4087.3 | F10: 4362.2 | G10: =F10*(1+G11) -> 4803.6407 | H10: =G10*(1+H11) -> 5289.7537 | I10: =H10*(1+I11) -> 5712.934 | J10: =I10*(1+J11) -> 6169.9687 | K10: =J10*(1+K11) -> 6663.5662
C11: =(C10-B10)/B10 -> 0.099976421 | D11: =(D10-C10)/C10 -> 0.11930792 | E11: =(E10-D10)/D10 -> 0.11824574 | F11: =(F10-E10)/E10 -> 0.067257113 | G11: =AVERAGE(C11:F11) -> 0.1011968 | H11: 0.1011968 | I11: 0.08 | J11: 0.08 | K11: 0.08
A12: Service & Lease Sales | B12: 584.5 | C12: 690.4 | D12: 777 | E12: 911.9 | F12: 1020.4 | G12: =F12*(1+G13) -> 1173.2595 | H12: =G12*(1+H13) -> 1337.5158 | I12: =H12*(1+I13) -> 1511.3928 | J12: =I12*(1+J13) -> 1692.76 | K12: =J12*(1+K13) -> 1878.9636
C13: =(C12-B12)/B12 -> 0.1811805 | D13: =(D12-C12)/C12 -> 0.12543453 | E13: =(E12-D12)/D12 -> 0.17361647 | F13: =(F12-E12)/E12 -> 0.11898234 | G13: =AVERAGE(C13:F13) -> 0.14980346 | H13: 0.14 | I13: 0.13 | J13: 0.12 | K13: 0.11
A14: Global Healthcare & Life Sciences | N14: Biopharma purification, infection prevention
A15: Product & Equipment Sales | B15: 1071.4 | C15: 1068.9 | D15: 1398.1 | E15: 1476.2 | F15: 1300.6 | G15: =F15*(1+G16) -> 1365.63 | H15: =G15*(1+H16) -> 1433.9115 | I15: =H15*(1+I16) -> 1505.6071 | J15: =I15*(1+J16) -> 1580.8874 | K15: =J15*(1+K16) -> 1659.9318 | N15: The segment’s 2024 drop was likely a one-off portfolio optimization.
C16: =(C15-B15)/B15 -> -0.0023333956 | D16: =(D15-C15)/C15 -> 0.30798017 | E16: =(E15-D15)/D15 -> 0.055861526 | F16: =(F15-E15)/E15 -> -0.11895407 | G16: 0.05 | H16: 0.05 | I16: 0.05 | J16: 0.05 | K16: 0.05
A17: Service & Lease Sales | B17: 110.5 | C17: 112.7 | D17: 112.4 | E17: 109.8 | F17: 118.2 | G17: =F17*(1+G18) -> 120.28678 | H17: =G17*(1+H18) -> 122.4104 | I17: =H17*(1+I18) -> 124.57152 | J17: =I17*(1+J18) -> 126.77078 | K17: =J17*(1+K18) -> 129.00888
C18: =(C17-B17)/B17 -> 0.019909502 | D18: =(D17-C17)/C17 -> -0.0026619343 | E18: =(E17-D17)/D17 -> -0.023131673 | F18: =(F17-E17)/E17 -> 0.076502732 | G18: =AVERAGE(C18:F18) -> 0.017654657 | H18: 0.017654657 | I18: 0.017654657 | J18: 0.017654657 | K18: 0.017654657
A19: Global Pest Elimination / Other | N19: Predictive pest tech, commercial footprint expansion
A20: Product & Equipment Sales | B20: 274.5 | C20: 308.9
A21: Service & Lease Sales | B21: 809.8 | C21: 909.7 | D21: 959 | E21: 1066 | F21: 1162.8 | G21: =F21*(1+G22) -> 1273.2482 | H21: =G21*(1+H22) -> 1394.1873 | I21: =H21*(1+I22) -> 1526.6138 | J21: =I21*(1+J22) -> 1671.6187 | K21: =J21*(1+K22) -> 1830.3969
C22: =(C21-B21)/B21 -> 0.12336379 | D22: =(D21-C21)/C21 -> 0.05419369 | E22: =(E21-D21)/D21 -> 0.11157456 | F22: =(F21-E21)/E21 -> 0.090806754 | G22: =AVERAGE(C22:F22) -> 0.094984699 | H22: 0.094984699 | I22: 0.094984699 | J22: 0.094984699 | K22: 0.094984699
A23: Corporate (ChampionX and other) | N23: Non-core
A24: Product & Equipment Sales | B24: 99.77 | C24: 138 | D24: 89.1 | E24: 42.5 | F24: 0 | G24: 0 | H24: 0 | I24: 0 | J24: 0 | K24: 0 | N24: Sunset of ChampionX contract by 2024
C25: =(C24-B24)/B24 -> 0.38318132 | D25: =(D24-C24)/C24 -> -0.35434783 | E25: =(E24-D24)/D24 -> -0.52300786 | F25: =(F24-E24)/E24 -> -1
A26: Service & Lease Sales | B26: 0.3 | C26: 1.2 | D26: – | E26: – | F26: –
A27: Total Net Sales
A28: Total Product & Equipment | B28: =B5+B10+B15+B20+B24 -> 9466.67 | C28: =C5+C10+C15+C20+C24 -> 10153.3 | D28: =D5+D10+D15+D24 -> 11446.2 | E28: =E5+E10+E15+E24 -> 12316.8 | F28: =F5+F10+F15+F24 -> 12473.6 | G28: =G5+G10+G15+G24 -> 13524.935 | H28: =H5+H10+H15+H24 -> 14667.782 | I28: =I5+I10+I15+I24 -> 15798.188 | J28: =J5+J10+J15+J24 -> 17016.874 | K28: =K5+K10+K15+K24 -> 18330.798
B29: =B28/B32 -> 0.80292224 | C29: =C28/C32 -> 0.79739419 | D29: =D28/D32 -> 0.80676356 | E29: =E28/E32 -> 0.80395817 | F29: =F28/F32 -> 0.79240728 | G29: =G28/G32 -> 0.79096888 | H29: =H28/H32 -> 0.78977162 | I29: =I28/I32 -> 0.78771609 | ... K29: =K28/K32 -> 0.78473799
A30: Total Service & Lease | B30: =B7+B12+B17+B21+B26 -> 2323.6 | C30: =C7+C12+C17+C21+C26 -> 2579.8 | D30: =D7+D12+D17+D21 -> 2741.6 | E30: =E7+E12+E17+E21 -> 3003.4 | F30: =F7+F12+F17+F21 -> 3267.8 | G30: =G7+G12+G17+G21 -> 3574.2649 | H30: =H7+H12+H17+H21 -> 3904.3998 | I30: =I7+I12+I17+I21 -> 4257.4998 | J30: =J7+J12+J17+J21 -> 4632.6036 | K30: =K7+K12+K17+K21 -> 5028.3334
B31: =B30/B32 -> 0.19707776 | C31: =C30/C32 -> 0.20260581 | D31: =D30/D32 -> 0.19323644 | E31: =E30/E32 -> 0.19604183 | F31: =F30/F32 -> 0.20759272 | G31: =G30/G32 -> 0.20903112 | H31: =H30/H32 -> 0.21022838 | I31: =I30/I32 -> 0.21228391 | ... K31: =K30/K32 -> 0.21526201
A32: Grand Total Net Sales | B32: =B28+B30 -> 11790.27 | C32: =C28+C30 -> 12733.1 | D32: =D28+D30 -> 14187.8 | E32: =E28+E30 -> 15320.2 | F32: =F28+F30 -> 15741.4 | G32: =G28+G30 -> 17099.2 | H32: =H28+H30 -> 18572.182 | I32: =I28+I30 -> 20055.687 | ... K32: =K28+K30 -> 23359.131

Sheet Income statement
A3: CONSOLIDATED STATEMENTS OF INCOME
B4: 2020 | C4: 2021 | D4: 2022 | E4: 2023 | F4: 2024 | G4: 2025 | H4: 2026 | I4: 2027 | J4: 2028 | K4: 2029
A5: Product and equipment sales | B5: =Revenue!B23 -> 9466.67 | C5: =Revenue!C23 -> 10153.3 | D5: =Revenue!D23 -> 11446.2 | E5: =Revenue!E23 -> 12316.8 | F5: =Revenue!F23 -> 12473.6 | G5: =Revenue!G23 -> 13135.588 | H5: =Revenue!H23 -> 13702.276 | I5: =Revenue!I23 -> 14264.587 | ... K5: =Revenue!K23 -> 15463.666
A6: Service and lease sales | B6: =Revenue!B24 -> 2323.6 | C6: =Revenue!C24 -> 2579.8 | D6: =Revenue!D24 -> 2741.6 | E6: =Revenue!E24 -> 3003.4 | F6: =Revenue!F24 -> 3267.8 | G6: =Revenue!G24 -> 3283.8969 | H6: =Revenue!H24 -> 3425.5689 | I6: =Revenue!I24 -> 3566.1467 | ... K6: =Revenue!K24 -> 3865.9166
A7: Net sales | B7: =B5+B6 -> 11790.27 | C7: =C5+C6 -> 12733.1 | D7: =D5+D6 -> 14187.8 | E7: =E5+E6 -> 15320.2 | F7: =Revenue!F21 -> 15741.4 | G7: =Revenue!G21 -> 16419.485 | H7: =Revenue!H21 -> 17127.844 | I7: =Revenue!I21 -> 17830.733 | J7: =Revenue!J21 -> 18564.185 | K7: =Revenue!K21 -> 19329.583
A8: Product and equipment cost of sales | B8: 5481.3 | C8: 6100.9 | D8: 7212.8 | E8: 7389.2 | F8: 6990
A9: Service and lease cost of sales | B9: 1424.5 | C9: 1514.9 | D9: 1618.2 | E9: 1765.7 | F9: 1909.7
A10: Cost of sales | B10: =B8+B9 -> 6905.8 | C10: =C8+C9 -> 7615.8 | D10: =D8+D9 -> 8831 | E10: =E8+E9 -> 9154.9 | F10: =F8+F9 -> 8899.7 | G10: =COGS!E45 -> 9268.8683 | H10: =COGS!F45 -> 9665.0667 | I10: =COGS!G45 -> 10056.38 | J10: =COGS!H45 -> 10464.511 | K10: =COGS!I45 -> 10890.213
A11: Selling, general and administrative expenses | B11: 3309.1 | C11: 3416.1 | D11: 3653.8 | E11: 4061.6 | F11: 4228.2 | G11: =COGS!E47 -> 4408.6162 | H11: =COGS!F47 -> 4591.8842 | I11: =COGS!G47 -> 4774.3293 | J11: =COGS!H47 -> 4964.7878 | K11: =COGS!I47 -> 5163.625
A12: Special (gains) and charges | B12: 179.6 | C12: 102.6 | D12: 140.5 | E12: 111.4 | F12: -188.9 | G12: =COGS!E49 -> 100 | H12: =COGS!F49 -> 100 | I12: =COGS!G49 -> 100 | J12: =COGS!H49 -> 100 | K12: =COGS!I49 -> 100
A13: Operating income | B13: =B7-B10-B11-B12 -> 1395.77 | C13: =C7-C10-C11-C12 -> 1598.6 | D13: =D7-D10-D11-D12 -> 1562.5 | E13: =E7-E10-E11-E12 -> 1992.3 | F13: =F7-F10-F11-F12 -> 2802.4 | G13: =G7-G10-G11-G12 -> 2642 | H13: =H7-H10-H11-H12 -> 2770.8936 | I13: =I7-I10-I11-I12 -> 2900.0245 | ... K13: =K7-K10-K11-K12 -> 3175.7449
A14: Other (income) expense | B14: -55.9 | C14: -33.9 | D14: -24.5 | E14: -59.9 | F14: -51.3 | G14: -50 | H14: -50 | I14: -50 | J14: -50 | K14: -50
A15: Interest expense, net | B15: 290.2 | C15: 218.3 | D15: 243.6 | E15: 296.7 | F15: 282.5 | G15: =Schedules!C51 -> 267.976 | H15: =Schedules!D51 -> 288.2 | I15: =Schedules!E51 -> 302.58 | J15: =Schedules!F51 -> 322.56 | K15: =Schedules!G51 -> 340.41
A16: Income before income taxes | B16: =B13-B14-B15 -> 1161.47 | C16: =C13-C14-C15 -> 1414.2 | D16: =D13-D14-D15 -> 1343.4 | E16: =E13-E14-E15 -> 1755.5 | F16: =F13-F14-F15 -> 2571.2 | G16: =G13-G14-G15 -> 2424.024 | H16: =H13-H14-H15 -> 2532.6936 | I16: =I13-I14-I15 -> 2647.4445 | ... K16: =K13-K14-K15 -> 2885.3349
A17: Provision for income taxes | B17: 176.6 | C17: 270.2 | D17: 234.5 | E17: 362.5 | F17: 439.3 | G17: =G16*G44 -> 472.68469 | H17: =H16*H44 -> 468.86428 | I17: =I16*I44 -> 490.10751 | J17: =J16*J44 -> 511.37511 | K17: =K16*K44 -> 534.14692
A18: Net income including noncontrolling interest | B18: =B16-B17 -> 984.87 | C18: =C16-C17 -> 1144 | D18: =D16-D17 -> 1108.9 | E18: =E16-E17 -> 1393 | F18: =F16-F17 -> 2131.9 | G18: =G16-G17 -> 1951.3393 | H18: =H16-H17 -> 2063.8293 | I18: =I16-I17 -> 2157.337 | ... K18: =K16-K17 -> 2351.188
A19: Net income attributable to noncontrolling interest | B19: 17.4 | C19: 14.1 | D19: 17.2 | E19: 20.7 | F19: 19.5 | G19: 20 | H19: 20 | I19: 20 | J19: 20 | K19: 20
A20: Net income attributable to Ecolab | B20: =B18-B19 -> 967.47 | C20: =C18-C19 -> 1129.9 | D20: =D18-D19 -> 1091.7 | E20: =E18-E19 -> 1372.3 | F20: =F18-F19 -> 2112.4 | G20: =G18-G19 -> 1931.3393 | H20: =H18-H19 -> 2043.8293 | I20: =I18-I19 -> 2137.337 | ... K20: =K18-K19 -> 2331.188
A21: Net loss from discontinued operations, net of tax | B21: -2172.5 | C21: 0 | D21: 0 | E21: 0 | F21: 0 | G21: 0 | H21: 0 | I21: 0 | J21: 0 | K21: 0
A22: Net income (loss) attributable to Ecolab (total) | B22: =B20+B21 -> -1205.03 | C22: =C20+C21 -> 1129.9 | D22: =D20+D21 -> 1091.7 | E22: =E20+E21 -> 1372.3 | F22: =F20+F21 -> 2112.4 | G22: =G20+G21 -> 1931.3393 | H22: =H20+H21 -> 2043.8293 | I22: =I20+I21 -> 2137.337 | ... K22: =K20+K21 -> 2331.188
A30: Assumptions
B31: 2020 | C31: 2021 | D31: 2022 | E31: 2023 | F31: 2024 | G31: 2025 | H31: 2026 | I31: 2027 | J31: 2028 | K31: 2029
A32: Product and equipment sales | O32: Revenue model
A33: Service and lease sales
A34: Net sales
A35: Product and equipment cost of sales
A36: Service and lease cost of sales
A37: Cost of sales | O37: COGS sheet
A38: Selling, general and administrative expenses
A39: Special (gains) and charges | O39: Normalized to ~$100mm/yr post-2024 to reflect ongoing restructuring/integration under the “One Ecolab” program (company disclosed expected restructuring/special charges cadence).
A40: Operating income | B40: =B13/B7 -> 0.11838321 | C40: =C13/C7 -> 0.1255468 | D40: =D13/D7 -> 0.11012983 | E40: =E13/E7 -> 0.13004399 | F40: =F13/F7 -> 0.17802737 | G40: =G13/G7 -> 0.16090639 | H40: =H13/H7 -> 0.16177714 | I40: =I13/I7 -> 0.16264191 | ... K40: =K13/K7 -> 0.16429454
A41: Other (income) expense | O41: Modeled at ~$(50)mm) (credit) as a clean, non-discrete run-rate around recent levels (Q4 note on pension/other).
A42: Interest expense, net | O42: Near-term step down from 2024 levels (benefit from rates) then slight upward normalization with refinancing/average debt costs.
A43: Income before income taxes
A44: Provision for income taxes | B44: =B17/B16 -> 0.1520487 | C44: =C17/C16 -> 0.19106208 | D44: =D17/D16 -> 0.17455709 | E44: =E17/E16 -> 0.20649388 | F44: =F17/F16 -> 0.17085408 | G44: 0.195 | H44: 0.18512475 | I44: 0.18512475 | J44: 0.18512475 | K44: 0.18512475 | O44: Forward ETR set ~19% anchored to Ecolab’s 2024 effective rate (~17%) and ~19% adjusted tax-rate range cited in company materials.
A45: Net income including noncontrolling interest
A46: Net income attributable to noncontrolling interest | O46: Flat ~$20mm consistent with the small, stable historical contribution of NCI.
A47: Net income attributable to Ecolab
A48: Net loss from discontinued operations, net of tax | O48: None assumed after 2020; no additional divestitures modeled beyond the 2024 surgical solutions sale already reflected in history.
A49: Net income (loss) attributable to Ecolab (total)
...

Sheet Cash flow  2
B1: 2025 | C1: 2026 | D1: 2027 | E1: 2028 | F1: 2029
A2: Net income | B2: =+'Income statement'!G20 -> 1931.3393 | C2: =+'Income statement'!H20 -> 2043.8293 | D2: =+'Income statement'!I20 -> 2137.337 | E2: =+'Income statement'!J20 -> 2230.9519 | F2: =+'Income statement'!K20 -> 2331.188
A4: ASSETS
A5: Current assets
A6: Cash and cash equivalents
A7: Accounts receivable, net | B7: =+'Balance sheet'!F7-'Balance sheet'!G7 -> -104.00268 | C7: =+'Balance sheet'!G7-'Balance sheet'!H7 -> -81.161412 | D7: =+'Balance sheet'!H7-'Balance sheet'!I7 -> -125.17198 | E7: =+'Balance sheet'!I7-'Balance sheet'!J7 -> -130.61475 | F7: =+'Balance sheet'!J7-'Balance sheet'!K7 -> -136.30367
A8: Inventories | B8: =+'Balance sheet'!F8-'Balance sheet'!G8 -> -79.911385 | C8: =+'Balance sheet'!G8-'Balance sheet'!H8 -> -66.033064 | D8: =+'Balance sheet'!H8-'Balance sheet'!I8 -> -65.218802 | E8: =+'Balance sheet'!I8-'Balance sheet'!J8 -> -68.021846 | F8: =+'Balance sheet'!J8-'Balance sheet'!K8 -> -70.950407
A9: Other current assets | B9: =+'Balance sheet'!F9-'Balance sheet'!G9 -> -1.861616 | C9: =+'Balance sheet'!G9-'Balance sheet'!H9 -> -18.326802 | D9: =+'Balance sheet'!H9-'Balance sheet'!I9 -> -18.244515 | E9: =+'Balance sheet'!I9-'Balance sheet'!J9 -> -19.045844 | F9: =+'Balance sheet'!J9-'Balance sheet'!K9 -> -19.883719
A10: Total current assets
A11: Property, plant and equipment, net | B11: =+'Balance sheet'!F11-'Balance sheet'!G11 -> -280.07703 | C11: =+'Balance sheet'!G11-'Balance sheet'!H11 -> -269.95096 | D11: =+'Balance sheet'!H11-'Balance sheet'!I11 -> -261.39935 | E11: =+'Balance sheet'!I11-'Balance sheet'!J11 -> -256.28841 | F11: =+'Balance sheet'!J11-'Balance sheet'!K11 -> -254.05457
A12: Goodwill | B12: =+'Balance sheet'!F12-'Balance sheet'!G12 -> 0 | C12: =+'Balance sheet'!G12-'Balance sheet'!H12 -> 0 | D12: =+'Balance sheet'!H12-'Balance sheet'!I12 -> 0 | E12: =+'Balance sheet'!I12-'Balance sheet'!J12 -> 0 | F12: =+'Balance sheet'!J12-'Balance sheet'!K12 -> 0
A13: Other intangible assets, net | B13: =+'Balance sheet'!F13-'Balance sheet'!G13 -> 293 | C13: =+'Balance sheet'!G13-'Balance sheet'!H13 -> 287 | D13: =+'Balance sheet'!H13-'Balance sheet'!I13 -> 165 | E13: =+'Balance sheet'!I13-'Balance sheet'!J13 -> 157 | F13: =+'Balance sheet'!J13-'Balance sheet'!K13 -> 149
A14: Operating lease assets | B14: =+'Balance sheet'!F14-'Balance sheet'!G14 -> -210.55021 | C14: =+'Balance sheet'!G14-'Balance sheet'!H14 -> -194.70402 | D14: =+'Balance sheet'!H14-'Balance sheet'!I14 -> -180.80034 | E14: =+'Balance sheet'!I14-'Balance sheet'!J14 -> -169.42388 | F14: =+'Balance sheet'!J14-'Balance sheet'!K14 -> -160.24709
A15: Other assets | B15: =+'Balance sheet'!F15-'Balance sheet'!G15 -> 19.112732 | C15: =+'Balance sheet'!G15-'Balance sheet'!H15 -> -25.676405 | D15: =+'Balance sheet'!H15-'Balance sheet'!I15 -> -15.812366 | E15: =+'Balance sheet'!I15-'Balance sheet'!J15 -> -32.719797 | F15: =+'Balance sheet'!J15-'Balance sheet'!K15 -> -46.571499
A16: Total assets
A18: LIABILITIES AND EQUITY
A19: Current liabilities
A20: Short-term debt | B20: =+'Balance sheet'!G20-'Balance sheet'!F20 -> -43.3 | C20: ='Balance sheet'!H20-'Balance sheet'!G20 -> 8 | D20: ='Balance sheet'!I20-'Balance sheet'!H20 -> 20 | E20: ='Balance sheet'!J20-'Balance sheet'!I20 -> 28 | F20: ='Balance sheet'!K20-'Balance sheet'!J20 -> 40
A21: Accounts payable | B21: =+'Balance sheet'!G21-'Balance sheet'!F21 -> -172.49315 | C21: =+'Balance sheet'!H21-'Balance sheet'!G21 -> 67.925395 | D21: =+'Balance sheet'!I21-'Balance sheet'!H21 -> 72.898813 | E21: =+'Balance sheet'!J21-'Balance sheet'!I21 -> 71.999889 | F21: =+'Balance sheet'!K21-'Balance sheet'!J21 -> 75.094377
A22: Compensation and benefits | B22: =+'Balance sheet'!G22-'Balance sheet'!F22 -> -22.021414 | C22: =+'Balance sheet'!H22-'Balance sheet'!G22 -> 6.3634624 | D22: =+'Balance sheet'!I22-'Balance sheet'!H22 -> 28.278998 | E22: =+'Balance sheet'!J22-'Balance sheet'!I22 -> 4.6971189 | F22: =+'Balance sheet'!K22-'Balance sheet'!J22 -> 29.825578
A23: Income taxes | B23: =+'Balance sheet'!G23-'Balance sheet'!F23 -> 68.817592 | C23: =+'Balance sheet'!H23-'Balance sheet'!G23 -> -1.5826654 | D23: =+'Balance sheet'!I23-'Balance sheet'!H23 -> 8.8003647 | E23: =+'Balance sheet'!J23-'Balance sheet'!I23 -> 8.8104618 | F23: =+'Balance sheet'!K23-'Balance sheet'!J23 -> 9.4336042
A24: Other current liabilities | B24: =+'Balance sheet'!G24-'Balance sheet'!F24 -> 12.87411 | C24: =+'Balance sheet'!H24-'Balance sheet'!G24 -> 41.468191 | D24: =+'Balance sheet'!I24-'Balance sheet'!H24 -> 64.307948 | E24: =+'Balance sheet'!J24-'Balance sheet'!I24 -> 67.104205 | F24: =+'Balance sheet'!K24-'Balance sheet'!J24 -> 70.026926
A25: Total current liabilities
A26: Long-term debt | B26: =+'Balance sheet'!G26-'Balance sheet'!F26 -> 205.8 | C26: =+'Balance sheet'!H26-'Balance sheet'!G26 -> 100 | D26: =+'Balance sheet'!I26-'Balance sheet'!H26 -> 250 | E26: =+'Balance sheet'!J26-'Balance sheet'!I26 -> 350 | F26: =+'Balance sheet'!K26-'Balance sheet'!J26 -> 500
A27: Pension and post-retirement benefits | B27: =+'Balance sheet'!G27-'Balance sheet'!F27 -> 0 | C27: =+'Balance sheet'!H27-'Balance sheet'!G27 -> 0 | D27: =+'Balance sheet'!I27-'Balance sheet'!H27 -> 0 | E27: =+'Balance sheet'!J27-'Balance sheet'!I27 -> 0 | F27: =+'Balance sheet'!K27-'Balance sheet'!J27 -> 0
A28: Deferred income taxes | B28: =+'Balance sheet'!G28-'Balance sheet'!F28 -> 569.81131 | C28: =+'Balance sheet'!H28-'Balance sheet'!G28 -> -95.226024 | D28: =+'Balance sheet'!I28-'Balance sheet'!H28 -> -33.701942 | E28: =+'Balance sheet'!J28-'Balance sheet'!I28 -> -38.797935 | F28: =+'Balance sheet'!K28-'Balance sheet'!J28 -> 49.621163
A29: Operating lease liabilities | B29: =+'Balance sheet'!G29-'Balance sheet'!F29 -> 135.67616 | C29: =+'Balance sheet'!H29-'Balance sheet'!G29 -> 141.94324 | D29: =+'Balance sheet'!I29-'Balance sheet'!H29 -> 128.62715 | E29: =+'Balance sheet'!J29-'Balance sheet'!I29 -> 134.97562 | F29: =+'Balance sheet'!K29-'Balance sheet'!J29 -> 141.80966
A30: Other liabilities | B30: =+'Balance sheet'!G30-'Balance sheet'!F30 -> 38.620451 | C30: =+'Balance sheet'!H30-'Balance sheet'!G30 -> 17.421924 | D30: =+'Balance sheet'!I30-'Balance sheet'!H30 -> 17.327893 | E30: =+'Balance sheet'!J30-'Balance sheet'!I30 -> 18.081349 | F30: =+'Balance sheet'!K30-'Balance sheet'!J30 -> 18.868882
A31: Total liabilities
A33: Equity
A34: Common stock ($1 par value) | B34: =+'Balance sheet'!G34-'Balance sheet'!F34 -> 2 | C34: =+'Balance sheet'!H34-'Balance sheet'!G34 -> 1.5 | D34: =+'Balance sheet'!I34-'Balance sheet'!H34 -> 1 | E34: =+'Balance sheet'!J34-'Balance sheet'!I34 -> 1 | F34: =+'Balance sheet'!K34-'Balance sheet'!J34 -> 1
A35: Additional paid-in capital | B35: =+'Balance sheet'!G35-'Balance sheet'!F35 -> 328.38969 | C35: =+'Balance sheet'!H35-'Balance sheet'!G35 -> 342.55689 | D35: =+'Balance sheet'!I35-'Balance sheet'!H35 -> 356.61467 | E35: =+'Balance sheet'!J35-'Balance sheet'!I35 -> 371.28371 | F35: =+'Balance sheet'!K35-'Balance sheet'!J35 -> 386.59166
A36: Retained earnings
A37: Accumulated other comprehensive loss | B37: =+'Balance sheet'!G37-'Balance sheet'!F37 -> 0 | C37: =+'Balance sheet'!H37-'Balance sheet'!G37 -> 32 | D37: =+'Balance sheet'!I37-'Balance sheet'!H37 -> 30 | E37: =+'Balance sheet'!J37-'Balance sheet'!I37 -> 20 | F37: =+'Balance sheet'!K37-'Balance sheet'!J37 -> 20
A38: Treasury stock | B38: =+'Balance sheet'!G38-'Balance sheet'!F38 -> -499.8 | C38: =+'Balance sheet'!H38-'Balance sheet'!G38 -> -500 | D38: =+'Balance sheet'!I38-'Balance sheet'!H38 -> -500 | E38: =+'Balance sheet'!J38-'Balance sheet'!I38 -> -500 | F38: =+'Balance sheet'!K38-'Balance sheet'!J38 -> -500
A39: Total Ecolab shareholders’ equity
A40: Noncontrolling interest | B40: =+'Balance sheet'!G40-'Balance sheet'!F40 -> 0 | C40: =+'Balance sheet'!H40-'Balance sheet'!G40 -> 0 | D40: =+'Balance sheet'!I40-'Balance sheet'!H40 -> 0 | E40: =+'Balance sheet'!J40-'Balance sheet'!I40 -> 0 | F40: =+'Balance sheet'!K40-'Balance sheet'!J40 -> 0
A41: Total equity
A42: Total liabilities and equity
A43: Dividends | B43: =Schedules!G7 -> 690.1 | C43: =Schedules!H7 -> 703.902 | D43: =Schedules!I7 -> 725.01906 | E43: =Schedules!J7 -> 739.51944 | F43: =Schedules!K7 -> 761.70502
...

Sheet Cash flow
B1: 2021 | C1: 2022 | D1: 2023 | E1: 2024 | F1: 2025 | G1: 2026 | H1: 2027 | I1: 2028 | J1: 2029
A2: Net income | B2: ='Income statement'!C20 -> 1129.9 | C2: ='Income statement'!D20 -> 1091.7 | D2: ='Income statement'!E20 -> 1372.3 | E2: ='Income statement'!F20 -> 2112.4 | F2: ='Income statement'!G20 -> 1931.3393 | G2: ='Income statement'!H20 -> 2043.8293 | H2: ='Income statement'!I20 -> 2137.337 | I2: ='Income statement'!J20 -> 2230.9519 | J2: ='Income statement'!K20 -> 2331.188
A3: ASSETS
A4: Current assets
A5: Cash and cash equivalents
A6: Accounts receivable, net | B6: ='Balance sheet'!B7-'Balance sheet'!C7 -> -204.6 | C6: ='Balance sheet'!C7-'Balance sheet'!D7 -> -219.7 | D6: ='Balance sheet'!D7-'Balance sheet'!E7 -> -136.1 | E6: ='Balance sheet'!E7-'Balance sheet'!F7 -> -30.8 | F6: ='Balance sheet'!F7-'Balance sheet'!G7 -> -104.00268 | G6: ='Balance sheet'!G7-'Balance sheet'!H7 -> -81.161412 | H6: ='Balance sheet'!H7-'Balance sheet'!I7 -> -125.17198 | I6: ='Balance sheet'!I7-'Balance sheet'!J7 -> -130.61475 | J6: ='Balance sheet'!J7-'Balance sheet'!K7 -> -136.30367
A7: Inventories | B7: ='Balance sheet'!B8-'Balance sheet'!C8 -> -206.6 | C7: ='Balance sheet'!C8-'Balance sheet'!D8 -> -301 | D7: ='Balance sheet'!D8-'Balance sheet'!E8 -> 295.6 | E7: ='Balance sheet'!E8-'Balance sheet'!F8 -> 32.3 | F7: ='Balance sheet'!F8-'Balance sheet'!G8 -> -79.911385 | G7: ='Balance sheet'!G8-'Balance sheet'!H8 -> -66.033064 | H7: ='Balance sheet'!H8-'Balance sheet'!I8 -> -65.218802 | I7: ='Balance sheet'!I8-'Balance sheet'!J8 -> -68.021846 | J7: ='Balance sheet'!J8-'Balance sheet'!K8 -> -70.950407
A8: Other current assets | B8: ='Balance sheet'!B9-'Balance sheet'!C9 -> -58.8 | C8: ='Balance sheet'!C9-'Balance sheet'!D9 -> -47.7 | D8: ='Balance sheet'!D9-'Balance sheet'!E9 -> 11.5 | E8: ='Balance sheet'!E9-'Balance sheet'!F9 -> -45.8 | F8: ='Balance sheet'!F9-'Balance sheet'!G9 -> -1.861616 | G8: ='Balance sheet'!G9-'Balance sheet'!H9 -> -18.326802 | H8: ='Balance sheet'!H9-'Balance sheet'!I9 -> -18.244515 | I8: ='Balance sheet'!I9-'Balance sheet'!J9 -> -19.045844 | J8: ='Balance sheet'!J9-'Balance sheet'!K9 -> -19.883719
A9: Total current assets
A10: Property, plant and equipment, net | B10: ='Balance sheet'!B11-'Balance sheet'!C11 -> -163.6 | C10: ='Balance sheet'!C11-'Balance sheet'!D11 -> -4.9 | D10: ='Balance sheet'!D11-'Balance sheet'!E11 -> -181.2 | E10: ='Balance sheet'!E11-'Balance sheet'!F11 -> -277.8 | F10: ='Balance sheet'!F11-'Balance sheet'!G11 -> -280.07703 | G10: ='Balance sheet'!G11-'Balance sheet'!H11 -> -269.95096 | H10: ='Balance sheet'!H11-'Balance sheet'!I11 -> -261.39935 | I10: ='Balance sheet'!I11-'Balance sheet'!J11 -> -256.28841 | J10: ='Balance sheet'!J11-'Balance sheet'!K11 -> -254.05457
A11: Goodwill | B11: ='Balance sheet'!B12-'Balance sheet'!C12 -> -2057 | C11: ='Balance sheet'!C12-'Balance sheet'!D12 -> 51.2 | D11: ='Balance sheet'!D12-'Balance sheet'!E12 -> -135.5 | E11: ='Balance sheet'!E12-'Balance sheet'!F12 -> 240.9 | F11: ='Balance sheet'!F12-'Balance sheet'!G12 -> 0 | G11: ='Balance sheet'!G12-'Balance sheet'!H12 -> 0 | H11: ='Balance sheet'!H12-'Balance sheet'!I12 -> 0 | I11: ='Balance sheet'!I12-'Balance sheet'!J12 -> 0 | J11: ='Balance sheet'!J12-'Balance sheet'!K12 -> 0
