Workbook
Name AcquisitionsToggle: #REF!
Name CaseTable: #REF!
Name CaseToggle: #REF!
Name Company_Name: #REF!
Name date: #REF!
Name DeferredTaxUseRatio: #REF!
Name EarningsTable: #REF!
Name GVKey: ""
Name Scenario: #REF!
Name SPSet: "current"
Name SPWS_WBID: "5B7D581C-6777-4964-9E9E-E04793492FA2"
Name Stock_Name: #REF!
Name Stock_Name: #REF!
Name Stock_Ticker: #REF!
Name Stock_Ticker: #REF!
Name Ticker: #REF!
Name UseDeferredTaxAsset: #REF!

Sheet Cover
H7: Scenario Switchboard
H9: Revenue & Operating Expenses
H10: Business Segment
D11: Valuation Date: | E11: =TODAY() -> 45959 | H11: US Ground -no of Packages | I11: 2
D12: Company Name: | E12: Fedex corporation | H12: US Ground - Revenue Per Package | I12: 2
D13: Sector: | E13: Industrials | H13: International Export - no of Packages | I13: 2
D14: Industry: | E14: Logistics | H14: International Export - Revenue per package | I14: 2
D15: Rating: | E15: =IF(E23>=Ke!D38,"BUY","SELL") -> BUY | H15: Salaries & Employee Benefits-cogs | I15: 2
H16: Purchased Transportation-cogs | I16: 2
D17: Current Price | E17: =Ke!D15 -> 249.31 | H17: Scenario Key
D18: Valuation Price | E18: =DCF!B8 -> 272.0515 | H18: Bull | I18: 1
D19: 12-month Valuation Price | E19: =DCF!B9 -> 289.87884 | H19: Base | I19: 2
D20: Valuation Appreciation | E20: =E18/E17-1 -> 0.091217743 | H20: Bear | I20: 3
D21: 12-mo Valuation Appreciation | E21: =E19/E17-1 -> 0.16272449
D22: Dividend Yield | E22: 0.0239
D23: Total Valuation Appreciation | E23: =E21+E22 -> 0.18662449

Sheet DCF
A1: #VALUE!
H2: Share count in Millions
A3: Cost of Equity | B3: =Ke!D38 -> 0.11990275 | G3: =TODAY() -> 45959 | H3: Today | I3: ='Balance sheet'!F169 -> 235.95546
A4: Number of Shares in thousands: | B4: =I3 -> 235.95546 | G4: =G3+365 -> 46324 | H4: One year | I4: ='Balance sheet'!G169 -> 229.19789
G5: =G4+366 -> 46690 | H5: Two year | I5: ='Balance sheet'!H169 -> 223.241
A6: Actual Price: | B6: 242.84 | C6: At close oct 22, 2025
G7: Price Appreciation
A8: Model Valuation: | B8: =B24 -> 272.0515 | G8: Price Appreciation | I8: =B8/$B$6-1 -> 0.12029112
A9: Model 12 Month Price Target: | B9: =B46 -> 289.87884 | G9: Price Appreciation (12 month) | I9: =B9/B6-1 -> 0.19370303
A12: Model Current Valuation with Sensitivity of Ke
C14: 46173 | D14: 46538 | E14: 46904 | F14: 47269 | G14: 47634
A15: Time period (years) | C15: =MAX((C14-$G$3)/365,0) -> 0.58630137 | D15: =MAX((D14-$G$3)/365,0) -> 1.5863014 | E15: =MAX((E14-$G$3)/365,0) -> 2.5890411 | F15: =MAX((F14-$G$3)/365,0) -> 3.5890411 | G15: =MAX((G14-$G$3)/365,0) -> 4.5890411
A16: Nominal FCFE: | C16: =('Derived cash flow'!C59) -> 4634.6456 | D16: ='Derived cash flow'!D59 -> 6720.3146 | E16: ='Derived cash flow'!E59 -> 6901.7995 | F16: ='Derived cash flow'!F59 -> 6955.6837 | G16: ='Derived cash flow'!G59 -> 6382.3736
A17: PV FCFE: | C17: =(C16*C15)/((1+$B$3)^C15) -> 2542.7459 | D17: =D16/((1+$B$3)^D15) -> 5615.3239 | E17: =E16/((1+$B$3)^E15) -> 5147.9283 | F17: =F16/((1+$B$3)^F15) -> 4632.6518 | G17: =G16/((1+$B$3)^G15) -> 3795.6988
A19: Terminal Growth Rate | B19: 0.028
A21: Terminal Value in 2029 | B21: =G16*(1+B19)/(B3-B19) -> 71391.55 | D21: <== Implied terminal value / net income (or P/E) multiple for terminal value
A22: PV of Terminal Value | B22: =B21/(1+B3)^(G15) -> 42457.687
A23: Total PV: | B23: =SUM(C17:G17)+B22 -> 64192.036
A24: Valuation per Share ($): | B24: =B23/B4 -> 272.0515
C25: Terminal Growth Rate
B26: =B24 -> 272.0515 | C26: =D26-L27 -> 0.013 | D26: =E26-L27 -> 0.018 | E26: =F26-L27 -> 0.023 | F26: 0.028 | G26: =F26+L27 -> 0.033 | H26: =G26+L27 -> 0.038 | I26: =H26+L27 -> 0.043 | L26: 0.005
B27: =B28+L27 -> 0.13490275 | C27: 214.68367 | D27: 220.70975 | E27: 227.27435 | F27: 234.45301 | G27: 242.33614 | H27: 251.03277 | I27: 260.6757 | L27: 0.005
B28: =B29+L27 -> 0.12990275 | C28: 223.78936 | D28: 230.45881 | E28: 237.75215 | F28: 245.76119 | G28: 254.59674 | H28: 264.39369 | I28: 275.31799
B29: =B30+L27 -> 0.12490275 | C29: 233.70567 | D29: 241.11602 | E29: 249.25357 | F29: 258.23089 | G29: 268.18503 | H29: 279.2846 | I29: 291.73939
A30: Cost Of Equity Ke | B30: =Ke!D38 -> 0.11990275 | C30: 244.54623 | D30: 252.81493 | E30: 261.93693 | F30: 272.0515 | G30: 283.32996 | H30: 295.98548 | I30: 310.28665
B31: =B30-L27 -> 0.11490275 | C31: 256.44696 | D31: 265.71664 | E31: 275.99496 | F31: 287.45602 | G31: 300.31642 | H31: 314.84912 | I31: 331.40298
B32: =B31-L27 -> 0.10990275 | C32: 269.57186 | D32: 280.01733 | E32: 291.66477 | F32: 304.73432 | G32: 319.50337 | H32: 336.32644 | I32: 355.66407
B33: =B32-L27 -> 0.10490275 | C33: 284.12057 | D33: 295.9583 | E33: 309.24136 | F33: 324.25168 | G33: 341.34959 | H33: 361.00313 | I33: 383.83158
A36: Model 12 Month Price Target with Sensitivity of Ke
C38: =C14 -> 46173 | D38: =D14 -> 46538 | E38: =E14 -> 46904 | F38: =F14 -> 47269 | G38: =G14 -> 47634
A39: Time period | C39: =MAX((C38-$G$4)/365,0) -> 0 | D39: =MAX((D38-$G$4)/365,0) -> 0.58630137 | E39: =MAX((E38-$G$4)/365,0) -> 1.5890411 | F39: =MAX((F38-$G$4)/365,0) -> 2.5890411 | G39: =MAX((G38-$G$4)/365,0) -> 3.5890411
A40: Nominal FCFE: | C40: 0 | D40: =D16*D39 -> 3940.1297 | E40: =E16 -> 6901.7995 | F40: =F16 -> 6955.6837 | G40: =G16 -> 6382.3736
A41: PV FCFE: | C41: =(C40*C39)/((1+$B$3)^C39) -> 0 | D41: =D40/((1+$B$3)^D39) -> 3687.0246 | E41: =E40/((1+$B$3)^E39) -> 5765.179 | F41: =F40/((1+$B$3)^F39) -> 5188.1195 | G41: =G40/((1+$B$3)^G39) -> 4250.8136
A43: Terminal Value in 2030 | B43: =G40*(1+B19)/(B3-B19) -> 71391.55
A44: PV of Terminal Value | B44: =B43/(1+B3)^G39 -> 47548.481
A45: Total PV: | B45: =SUM(D41:H41)+B44 -> 66439.618
A46: Valuation per Share ($): | B46: =B45/I4 -> 289.87884
C47: Terminal Growth Rate
B48: =B46 -> 289.87884 | C48: =D48-$L$26 -> 0.013 | D48: =E48-$L$26 -> 0.018 | E48: =F48-$L$26 -> 0.023 | F48: 0.028 | G48: =F48+$L$26 -> 0.033 | H48: =G48+$L$26 -> 0.038 | I48: =H48+$L$26 -> 0.043
B49: =B50+$L$27 -> 0.13490275 | C49: 227.07307 | D49: 234.11373 | E49: 241.78356 | F49: 250.17085 | G49: 259.38121 | H49: 269.54204 | I49: 280.80849
...

Sheet Ke
A1: #VALUE! | D1: FDX.O | G1: Price = E*(1+g)/(ke-g)
A2: Cost of Equity | G2: P/E = (1+g)/(ke-g)
A3: (Blue = input, Black = calculation) | G3: ke = (1+g)/(P/E) + g
C4: Historic Beta | D4: 1.31
A5: S&P 500 data | F5: Source | G5: Reference
B6: S&P500 Forward P/E | D6: 22.17 | F6: WSJ | G6: 1-Year Forward P/E for S&P
B7: Projected EPS growth rate (g S&P) | D7: 0.1111 | F7: CapIQ/Bloomberg | G7: 5-Year Projected Earnings Growth Rate for S&P
B8: Risk-free rate (Rf) | D8: 0.0407 | F8: WSJ (5/8) | G8: 10 yr T-Note
B9: Implied required return on equity (Rs&p500) | D9: =((1+D7)/D6)+D7 -> 0.16121728 | G9: { (1+ gs&p500 ) / (P/Es&p500) } + gs&p500
B10: Implied equity risk premium (Rm) | D10: =(D8-D9)*-1 -> 0.12051728 | G10: Rs&p500-Rm
A13: Beta
A14: Fedex data
B15: Current Price (P) | D15: 249.31 | F15: WorkSpace
B16: Forward EPS (E) | D16: 18.03 | F16: WorkSpace | H16: 33.06
B17: P/E ratio | D17: =D15/D16 -> 13.82751 | F17: WorkSpace | G17: calc | J17: Book
B18: Projected EPS growth rate (g) | D18: ='Comps NF'!Q19 -> 0.104125 | F18: WorkSpace + Calculation | G18: Took the average | I18: Market Cap | J18: D/E Ratio | K18: Tax Rate | L18: bU = bL / (1+ ((1-t)D/E)) | M18: bL = bu (1+ ((1-t)D/E))
B19: Implied required return on equity (Re) | D19: =((1+D18)/(D17))+D18 -> 0.18397488 | G19: { (1+g) / (P/E) } +g | I19: UPS | J19: 1.5708 | K19: 0.23 | L19: =E23/(1+((1-K19)*J19)) -> 0.48426895 | M19: =L19*(1+((1-$K$26)*$J$26)) -> 0.7601025
B20: Forward (Bf) | D20: =(D19-D8)/D10 -> 1.1888327 | G20: (Re-Rf)/Rm | I20: JBHT.O | J20: 0.4485 | K20: 0.246 | L20: =E24/(1+((1-K20)*J20)) -> 0.91916641 | M20: =L20*(1+((1-$K$26)*$J$26)) -> 1.4427121
I21: GXO | J21: 0.9136 | K21: 0.368 | L21: =E25/(1+((1-K21)*J21)) -> 1.0840657 | M21: =L21*(1+((1-$K$26)*$J$26)) -> 1.7015359
A22: Comparable Beta | D22: Relevered | E22: Market Beta | I22: CHRW | J22: 0.7718 | K22: 0.192 | L22: =E26/(1+((1-K22)*J22)) -> 0.53584152 | M22: =L22*(1+((1-$K$26)*$J$26)) -> 0.84105014
B23: UPS | D23: =M19 -> 0.7601025 | E23: 1.07 | F23: Workspace
B24: JB hunt transport | D24: =M20 -> 1.4427121 | E24: 1.23 | F24: Workspace
B25: GXO logistics | D25: =M21 -> 1.7015359 | E25: 1.71 | F25: Workspace | J25: D/E Ratio | K25: Tax Rate | L25: Unlevered | M25: Relevered
B26: CHRW | D26: =M22 -> 0.84105014 | E26: 0.87 | F26: Workspace | I26: FDX | J26: 0.7625 | K26: 0.253 | L26: =D30/(1+((1-K26)*J26)) -> 0.83461419 | M26: =L26*(1+((1-K26)*J26)) -> 1.31
B27: Mean | D27: =AVERAGE(D23:D26) -> 1.1863502 | E27: =AVERAGE(E23:E26) -> 1.22
A29: Historical Beta
B30: Historic (Bh) - 5-year monthly | D30: =D4 -> 1.31 | F30: WorkSpace | G30: Five-year monthly beta
A32: Cost of Equity:
B33: Historic equity risk premium | D33: 0.065 | E33: Weight | G33: Based on long-term, historic, average risk premium (see class slides, source: Damodaran)
B34: Using Forward Beta | D34: =$D$8+D20*$D$33 -> 0.11797413 | E34: 0.5 | G34: Rf+Rm*Bf
B35: Using Comparable Beta | D35: =$D$8+D27*$D$33 -> 0.11781276 | E35: 0.25
B36: Using Historic Beta | D36: =$D$8+D30*$D$33 -> 0.12585 | E36: 0.25 | G36: Rf+Rm*Bh
B38: Weighted COE | D38: =SUMPRODUCT(D34:D36,E34:E36) -> 0.11990275
B40: Market COE (beta = 1) | D40: =D33+D8 -> 0.1057 | G40: Assumes beta of 1.0

Sheet Revenue
A1: FEDEX CORPORATION | C1: 2021 | D1: 2022 | E1: 2023 | F1: 2024 | G1: 2025 | J1: 2026E | K1: 2027E | L1: 2028E | M1: 2029E | N1: 2030E
A2: REVENUE STATEMENT
A4: Federal Express | C4: =42078+30496 -> 72574 | D4: =45814+33232 -> 79046 | E4: 75884 | F4: 74663 | G4: 75304 | J4: =J30 -> 77338.698 | K4: =K30 -> 78695.627 | L4: =L30 -> 80336.673 | M4: =M30 -> 81896.234 | N4: =N30 -> 83495.33
A5: FedEx Frieght | C5: 7833 | D5: 9532 | E5: 10084 | F5: 9429 | G5: 8892 | J5: =J32 -> 8962.7005 | K5: =K32 -> 9156.043 | L5: =L32 -> 9432.6225 | M5: =M32 -> 9717.5566 | N5: =N32 -> 10011.098
A6: Other(Print &Office) | C6: =3520+32 -> 3552 | D6: =4681+253 -> 4934 | E6: 4187 | F6: 3601 | G6: 3730 | J6: =J34 -> 3484 | K6: =K34 -> 3588.6619 | L6: =L34 -> 3696.4679 | M6: =M34 -> 3807.5125 | N6: =N34 -> 3921.8929
A7: Total | C7: =SUM(C4:C6) -> 83959 | D7: =SUM(D4:D6) -> 93512 | E7: =SUM(E4:E6) -> 90155 | F7: =SUM(F4:F6) -> 87693 | G7: =SUM(G4:G6) -> 87926 | J7: =SUM(J4:J6) -> 89785.399 | K7: =SUM(K4:K6) -> 91440.332 | L7: =SUM(L4:L6) -> 93465.763 | M7: =SUM(M4:M6) -> 95421.303 | N7: =SUM(N4:N6) -> 97428.321
A10: Federal Express segment
A11: Package:
A12: US priority revenue | C12: =8116+1791 -> 9907 | D12: =9084+1971 -> 11055 | E12: 10896 | F12: 10543 | G12: 10520 | J12: =J48*J43/1000 -> 10653.831 | K12: =K48*K43/1000 -> 10705.502 | L12: =L48*L43/1000 -> 10866.084 | M12: =M48*M43/1000 -> 11139.366 | N12: =N48*N43/1000 -> 11419.521
A13: US deferred revenue | C13: 4984 | D13: 5330 | E13: 5126 | F13: 4926 | G13: 5007 | J13: =J52*J43/1000 -> 5176.5974 | K13: =K52*K43/1000 -> 5332.9307 | L13: =L52*L43/1000 -> 5493.9852 | M13: =M52*M43/1000 -> 5659.9035 | N13: =N52*N43/1000 -> 5830.8326
A14: US ground revenue | C14: 30496 | D14: 33232 | E14: 32352 | F14: 32981 | G14: 33887 | J14: =J56*260/1000 -> 35373.279 | K14: =K56*260/1000 -> 36084.282 | L14: =L56*260/1000 -> 36809.576 | M14: =M56*260/1000 -> 37177.672 | N14: =N56*260/1000 -> 37549.449
A15: Total US domestic package revenue | C15: =SUM(C12:C14) -> 45387 | D15: =SUM(D12:D14) -> 49617 | E15: =SUM(E12:E14) -> 48374 | F15: =SUM(F12:F14) -> 48450 | G15: =SUM(G12:G14) -> 49414 | J15: =SUM(J12:J14) -> 51203.707 | K15: =SUM(K12:K14) -> 52122.714 | L15: =SUM(L12:L14) -> 53169.646 | M15: =SUM(M12:M14) -> 53976.942 | N15: =SUM(N12:N14) -> 54799.803
A16: International Priority | C16: 10317 | D16: 12130 | E16: 10938 | F16: 9454 | G16: 8737
A17: International economy | C17: 2632 | D17: 2838 | E17: 3307 | F17: 4653 | G17: 5861
A18: Total international export package revenue | C18: =SUM(C16:C17) -> 12949 | D18: =SUM(D16:D17) -> 14968 | E18: =SUM(E16:E17) -> 14245 | F18: =SUM(F16:F17) -> 14107 | G18: =SUM(G16:G17) -> 14598 | J18: =J60*J43/1000 -> 14857.884 | K18: =K60*K43/1000 -> 15003.491 | L18: =L60*L43/1000 -> 15303.561 | M18: =M60*M43/1000 -> 15765.728 | N18: =N60*N43/1000 -> 16241.853 | Q18: Calcualted as total due to the 10k reporting method
A19: International domestic | C19: 4640 | D19: 4340 | E19: 4552 | F19: 4659 | G19: 4495 | J19: =J64*J43/1000 -> 4576.3048 | K19: =K64*K43/1000 -> 4625.3603 | L19: =L64*L43/1000 -> 4674.9416 | M19: =M64*M43/1000 -> 4725.0544 | N19: =N64*N43/1000 -> 4775.7044
A20: Total package revenue | C20: =C19+C18+C15 -> 62976 | D20: =D19+D18+D15 -> 68925 | E20: =E19+E18+E15 -> 67171 | F20: =F19+F18+F15 -> 67216 | G20: =G19+G18+G15 -> 68507 | J20: =J19+J18+J15 -> 70637.896 | K20: =K19+K18+K15 -> 71751.566 | L20: =L19+L18+L15 -> 73148.148 | M20: =M19+M18+M15 -> 74467.724 | N20: =N19+N18+N15 -> 75817.36
A22: Freight:
A23: U.S. | C23: 3325 | D23: 3041 | E23: 2883 | F23: 2391 | G23: 1536 | J23: =J68*J43/1000 -> 1185.6574 | K23: =K68*K43/1000 -> 1244.9402 | L23: =L68*L43/1000 -> 1307.9342 | M23: =M68*M43/1000 -> 1374.1157 | N23: =N68*N43/1000 -> 1443.6459
A24: International priority | C24: 3030 | D24: 3840 | E24: 3059 | F24: 2205 | G24: 2320
A25: International economy | C25: =1582+245 -> 1827 | D25: =1653+177 -> 1830 | E25: 1719 | F25: 1874 | G25: 1975 | J25: =J72*J43/1000 -> 4565.1453 | K25: =K72*K43/1000 -> 4749.1206 | L25: =L72*L43/1000 -> 4930.5906 | M25: =M72*M43/1000 -> 5104.3939 | N25: =N72*N43/1000 -> 5284.3238 | Q25: Calcualted as total due to the 10k reporting method
A26: Total freight revenue | C26: =SUM(C23:C25) -> 8182 | D26: =SUM(D23:D25) -> 8711 | E26: =SUM(E23:E25) -> 7661 | F26: =SUM(F23:F25) -> 6470 | G26: =SUM(G23:G25) -> 5831 | J26: =SUM(J23:J25) -> 5750.8027 | K26: =SUM(K23:K25) -> 5994.0609 | L26: =SUM(L23:L25) -> 6238.5248 | M26: =SUM(M23:M25) -> 6478.5096 | N26: =SUM(N23:N25) -> 6727.9697
A28: Other | C28: 1416 | D28: 1410 | E28: 1052 | F28: 977 | G28: 966 | J28: 950 | K28: 950 | L28: 950 | M28: 950 | N28: 950
A30: Federal Express | C30: =C28+C26+C20 -> 72574 | D30: =D28+D26+D20 -> 79046 | E30: =E28+E26+E20 -> 75884 | F30: =F28+F26+F20 -> 74663 | G30: =G28+G26+G20 -> 75304 | J30: =J28+J26+J20 -> 77338.698 | K30: =K28+K26+K20 -> 78695.627 | L30: =L28+L26+L20 -> 80336.673 | M30: =M28+M26+M20 -> 81896.234 | N30: =N28+N26+N20 -> 83495.33
J31: =(J30-G30)/G30 -> 0.027019792 | K31: =(K30-J30)/J30 -> 0.017545268 | L31: =(L30-K30)/K30 -> 0.020853079 | M31: =(M30-L30)/L30 -> 0.019412819 | N31: =(N30-M30)/M30 -> 0.019525879
A32: Fedex freight segment | C32: 7833 | D32: 9532 | E32: 10084 | F32: 9429 | G32: 8892 | J32: =(J79+J83)*J43/1000 -> 8962.7005 | K32: =(K79+K83)*K43/1000 -> 9156.043 | L32: =(L79+L83)*L43/1000 -> 9432.6225 | M32: =(M79+M83)*M43/1000 -> 9717.5566 | N32: =(N79+N83)*N43/1000 -> 10011.098
J33: =(J32-G32)/G32 -> 0.0079510195 | K33: =(K32-J32)/J32 -> 0.021571909 | L33: =(L32-K32)/K32 -> 0.030207312 | M33: =(M32-L32)/L32 -> 0.030207312 | N33: =(N32-M32)/M32 -> 0.030207312
A34: Other and eliminations | C34: =3520+32 -> 3552 | D34: =4681+253 -> 4934 | E34: 4187 | F34: 3601 | G34: 3730 | J34: =J88 -> 3484 | K34: =K88 -> 3588.6619 | L34: =L88 -> 3696.4679 | M34: =M88 -> 3807.5125 | N34: =N88 -> 3921.8929
J35: =(J34-G34)/G34 -> -0.065951743 | K35: =(K34-J34)/J34 -> 0.030040728 | L35: =(L34-K34)/K34 -> 0.030040728 | M35: =(M34-L34)/L34 -> 0.030040728 | N35: =(N34-M34)/M34 -> 0.030040728
A36: Total revenue | C36: =SUM(C30:C34) -> 83959 | D36: =SUM(D30:D34) -> 93512 | E36: =SUM(E30:E34) -> 90155 | F36: =SUM(F30:F34) -> 87693 | G36: =SUM(G30:G34) -> 87926 | J36: =J89 -> 89241.195 | K36: =K89 -> 90885.189 | L36: =L89 -> 92899.462 | M36: =M89 -> 94849.339 | N36: =N89 -> 96850.637
E39: Package statistics
A41: Average daily package volume(ADV) | B41: in thousands
A42: Revenue/package | B42: dollars
A43: BusinessDays | C43: 256 | D43: 257 | E43: 255 | F43: 256 | G43: 254 | H43: 254 | J43: 256 | K43: 256 | L43: 256 | M43: 256 | N43: 256 | P43: calendar-neutral hold; no structural change expected.
A45: Federal Express | C45: 2021 | D45: 2022 | E45: 2023 | F45: 2024 | G45: 2025 | H45: Q1 2026 | J45: 2026E | K45: 2027E | L45: 2028E | M45: 2029E | N45: 2030E
A46: U.S. Priority(ADV) | C46: 1932 | D46: 1927 | E46: 1724 | F46: 1649 | G46: 1609 | H46: 1654 | J46: =G46*(1+J97) -> 1592.91 | K46: =J46*(1+K97) -> 1576.9809 | L46: =K46*(1+L97) -> 1576.9809 | M46: =L46*(1+M97) -> 1592.7507 | N46: =M46*(1+N97) -> 1608.6782
A47: Revenue/package | C47: 20.1117 | D47: 22.4993 | E47: 24.78 | F47: 24.98 | G47: 25.74 | H47: 26.13 | J47: =G47*(1+J98) -> 26.1261 | K47: =J47*(1+K98) -> 26.517991 | L47: =K47*(1+L98) -> 26.915761 | M47: =L47*(1+M98) -> 27.319498 | N47: =M47*(1+N98) -> 27.72929
A48: Revenue | C48: =C46*C47 -> 38855.804 | D48: =D46*D47 -> 43356.151 | E48: =E46*E47 -> 42720.72 | F48: =F46*F47 -> 41192.02 | G48: =G46*G47 -> 41415.66 | H48: =H46*H47 -> 43219.02 | J48: =J46*J47 -> 41616.526 | K48: =K46*K47 -> 41818.366 | L48: =L46*L47 -> 42445.642 | M48: =M46*M47 -> 43513.149 | N48: =N46*N47 -> 44607.505
A50: U.S. Deferred(ADV) | C50: 1351 | D50: 1262 | E50: 1064 | F50: 1015 | G50: 1052 | H50: 1061 | J50: =G50*(1+J101) -> 1067.78 | K50: =J50*(1+K101) -> 1089.1356 | L50: =K50*(1+L101) -> 1110.9183 | M50: =L50*(1+M101) -> 1133.1367 | N50: =M50*(1+N101) -> 1155.7994
A51: Revenue/package | C51: 14.46 | D51: 16.56 | E51: 18.91 | F51: 18.97 | G51: 18.75 | H51: 18.76 | J51: =G51*(1+J102) -> 18.9375 | K51: =J51*(1+K102) -> 19.126875 | L51: =K51*(1+L102) -> 19.318144 | M51: =L51*(1+M102) -> 19.511325 | N51: =M51*(1+N102) -> 19.706438
...

Sheet Income statement
A1: CONSOLIDATED STATEMENTS OF INCOME
A2: (IN MILLIONS, EXCEPT PER SHARE AMOUNTS)
B4: 2021 | C4: 2022 | D4: 2023 | E4: 2024 | F4: 2025 | G4: Q1 2026 | H4: 2026E | I4: 2027E | J4: 2028E | K4: 2029E | L4: 2030E
A5: REVENUE | B5: 83959 | C5: 93512 | D5: 90155 | E5: 87693 | F5: 87926 | G5: 22244 | H5: =Revenue!J36 -> 89241.195 | I5: =Revenue!K36 -> 90885.189 | J5: =Revenue!L36 -> 92899.462 | K5: =Revenue!M36 -> 94849.339 | L5: =Revenue!N36 -> 96850.637
A6: OPERATING EXPENSES
A7: Salaries and employee benefits | B7: 30173 | C7: 32058 | D7: ='Operating expenses'!B79 -> 31019 | E7: ='Operating expenses'!C79 -> 30961 | F7: ='Operating expenses'!D79 -> 31232 | G7: ='Operating expenses'!E79 -> 30770.008 | H7: ='Operating expenses'!E79 -> 30770.008 | I7: ='Operating expenses'!F79 -> 30565.171 | J7: ='Operating expenses'!G79 -> 31259.895 | K7: ='Operating expenses'!H79 -> 31934.966 | L7: ='Operating expenses'!I79 -> 32628.071
A8: Purchased transportation | B8: 21674 | C8: 24118 | D8: ='Operating expenses'!B80 -> 21790 | E8: ='Operating expenses'!C80 -> 20921 | F8: ='Operating expenses'!D80 -> 21768 | G8: 5488 | H8: ='Operating expenses'!E80 -> 21827.318 | I8: ='Operating expenses'!F80 -> 22224.878 | J8: ='Operating expenses'!G80 -> 22704.681 | K8: ='Operating expenses'!H80 -> 23164.898 | L8: ='Operating expenses'!I80 -> 23637.043
A9: Rentals and landing fees | B9: 4155 | C9: 4712 | D9: ='Operating expenses'!B81 -> 4738 | E9: ='Operating expenses'!C81 -> 4571 | F9: ='Operating expenses'!D81 -> 4647 | G9: 1192 | H9: ='Operating expenses'!E81 -> 4802.0229 | I9: ='Operating expenses'!F81 -> 5071.2757 | J9: ='Operating expenses'!G81 -> 5359.9383 | K9: ='Operating expenses'!H81 -> 5666.7948 | L9: ='Operating expenses'!I81 -> 5993.153
A10: Depreciation and amortization | B10: 3793 | C10: 3970 | D10: ='Operating expenses'!B82 -> 4176 | E10: ='Operating expenses'!C82 -> 4287 | F10: ='Operating expenses'!D82 -> 4264 | G10: 1092 | H10: ='Operating expenses'!E82 -> 4361.647 | I10: ='Operating expenses'!F82 -> 4333.2817 | J10: ='Operating expenses'!G82 -> 4349.0182 | K10: ='Operating expenses'!H82 -> 4430.443 | L10: ='Operating expenses'!I82 -> 4523.7068
A11: Fuel | B11: 2882 | C11: 5115 | D11: ='Operating expenses'!B83 -> 5909 | E11: ='Operating expenses'!C83 -> 4710 | F11: ='Operating expenses'!D83 -> 3775 | G11: 873 | H11: ='Operating expenses'!E83 -> 3868.2323 | I11: ='Operating expenses'!F83 -> 3937.9223 | J11: ='Operating expenses'!G83 -> 4024.4012 | K11: ='Operating expenses'!H83 -> 4107.7214 | L11: ='Operating expenses'!I83 -> 4193.2248
A12: Maintanence and repairs | B12: 3328 | C12: 3372 | D12: ='Operating expenses'!B84 -> 3357 | E12: ='Operating expenses'!C84 -> 3291 | F12: ='Operating expenses'!D84 -> 3245 | G12: 843 | H12: ='Operating expenses'!E84 -> 3236.3171 | I12: ='Operating expenses'!F84 -> 3205.0393 | J12: ='Operating expenses'!G84 -> 3276.1332 | K12: ='Operating expenses'!H84 -> 3253.1752 | L12: ='Operating expenses'!I84 -> 3321.7485
A13: Goodwill and other asset impairment charges | B13: 0 | C13: 0 | D13: ='Operating expenses'!B85 -> 117 | E13: ='Operating expenses'!C85 -> 157 | F13: ='Operating expenses'!D85 -> 21 | H13: ='Operating expenses'!E85 -> 21 | I13: ='Operating expenses'!F85 -> 21 | J13: ='Operating expenses'!G85 -> 21 | K13: ='Operating expenses'!H85 -> 21 | L13: ='Operating expenses'!I85 -> 21
A14: Business optimization and realignment costs | B14: 116 | C14: 278 | D14: ='Operating expenses'!B86 -> 309 | E14: ='Operating expenses'!C86 -> 582 | F14: ='Operating expenses'!D86 -> 756 | G14: 67 | H14: ='Operating expenses'!E86 -> 500 | I14: ='Operating expenses'!F86 -> 200 | J14: ='Operating expenses'!G86 -> 100 | K14: ='Operating expenses'!H86 -> 0 | L14: ='Operating expenses'!I86 -> 0
A15: Other | B15: 11981 | C15: 13644 | D15: ='Operating expenses'!B87 -> 13828 | E15: ='Operating expenses'!C87 -> 12654 | F15: ='Operating expenses'!D87 -> 13001 | G15: =3396+45 -> 3441 | H15: ='Operating expenses'!E87 -> 13354.807 | I15: ='Operating expenses'!F87 -> 13535.084 | J15: ='Operating expenses'!G87 -> 13924.897 | K15: ='Operating expenses'!H87 -> 14229.398 | L15: ='Operating expenses'!I87 -> 14544.992
A16: TOTAL OPERATING EXPENSES | B16: =SUM(B7:B15) -> 78102 | C16: =SUM(C7:C15) -> 87267 | D16: =SUM(D7:D15) -> 85243 | E16: =SUM(E7:E15) -> 82134 | F16: =SUM(F7:F15) -> 82709 | G16: =SUM(G7:G15) -> 43766.008 | H16: =SUM(H7:H15) -> 82741.353 | I16: =SUM(I7:I15) -> 83093.652 | ... L16: =SUM(L7:L15) -> 88862.938
A17: OPERATING INCOME | B17: =B5-B16 -> 5857 | C17: =C5-C16 -> 6245 | D17: =D5-D16 -> 4912 | E17: =E5-E16 -> 5559 | F17: =F5-F16 -> 5217 | G17: 1186 | H17: =H5-H16 -> 6499.842 | I17: =I5-I16 -> 7791.5372 | J17: =J5-J16 -> 7879.4977 | K17: =K5-K16 -> 8040.942 | L17: =L5-L16 -> 7987.6989
A18: OTHER INCOME(EXPENSE)
A19: Interest expense | B19: -793 | C19: -689 | D19: -694 | E19: -745 | F19: -789 | G19: -119 | H19: =-'Debt schedule'!G12 -> -859.551 | I19: =-'Debt schedule'!H12 -> -967.764 | J19: =-'Debt schedule'!I12 -> -1093.176 | K19: =-'Debt schedule'!J12 -> -1147.38 | L19: =-'Debt schedule'!K12 -> -1208.64
A20: Interest income | B20: 52 | C20: 53 | D20: 198 | E20: 370 | F20: 363 | H20: =H60*'Balance sheet'!G23 -> 211.13958 | I20: =I60*'Balance sheet'!H23 -> 215.02917 | J20: =J60*'Balance sheet'!I23 -> 219.79483 | K20: =K60*'Balance sheet'!J23 -> 224.40813 | L20: =L60*'Balance sheet'!K23 -> 229.14308
A21: Other retirement plans income | B21: 1983 | C21: -726 | D21: 1054 | E21: 722 | F21: 713 | G21: 60 | H21: =H61*H7 -> 758.18863 | I21: =I61*I7 -> 753.14133 | J21: =J61*J7 -> 770.25969 | K21: =K61*K7 -> 786.89379 | L21: =L61*L7 -> 803.97223
A22: Loss on debt extinguishment | B22: -393 | C22: 0 | D22: 0 | E22: 0 | F22: 0 | H22: =F22 -> 0 | I22: =G22 -> 0 | J22: =H22 -> 0 | K22: =I22 -> 0 | L22: =J22 -> 0
A23: Other,net | B23: -32 | C23: 13 | D23: -107 | E23: -70 | F23: -63 | G23: 7 | H23: =H63 -> -60 | I23: =I63 -> -60 | J23: =J63 -> -60 | K23: =K63 -> -60 | L23: =L63 -> -60
A24: TOTAL OTHER INCOME(EXPENSE) | B24: =SUM(B19:B23) -> 817 | C24: =SUM(C19:C23) -> -1349 | D24: =SUM(D19:D23) -> 451 | E24: =SUM(E19:E23) -> 277 | F24: =SUM(F19:F23) -> 224 | G24: =SUM(G19:G23) -> -52 | H24: =SUM(H19:H23) -> 49.777203 | I24: =SUM(I19:I23) -> -59.593501 | ... L24: =SUM(L19:L23) -> -235.52469
A25: INCOME BEFORE INCOME TAXES | B25: =B17+B24 -> 6674 | C25: =C17+C24 -> 4896 | D25: =D17+D24 -> 5363 | E25: =E17+E24 -> 5836 | F25: =F17+F24 -> 5441 | G25: =G17+G24 -> 1134 | H25: =H17+H24 -> 6549.6192 | I25: =I17+I24 -> 7731.9437 | ... L25: =L17+L24 -> 7752.1742
A26: PROVISION FOR INCOME TAXES | B26: 1443 | C26: 1070 | D26: 1391 | E26: 1505 | F26: 1349 | G26: 310 | H26: =H25*H66 -> 1637.4048 | I26: =I25*I66 -> 1932.9859 | J26: =J25*J66 -> 1929.0941 | K26: =K25*K66 -> 1961.216 | L26: =L25*L66 -> 1938.0436
A27: NET INCOME | B27: =B25-B26 -> 5231 | C27: =C25-C26 -> 3826 | D27: =D25-D26 -> 3972 | E27: =E25-E26 -> 4331 | F27: =F25-F26 -> 4092 | G27: =G25-G26 -> 824 | H27: =H25-H26 -> 4912.2144 | I27: =I25-I26 -> 5798.9578 | ... L27: =L25-L26 -> 5814.1307
A28: BASIC EARNINGS PER COMMON SHARE | B28: 19.79 | C28: 14.54 | D28: 15.6 | E28: 17.41 | F28: 16.96 | G28: 3.48 | H28: ='Debt schedule'!C32 -> 21.630182 | I28: ='Debt schedule'!D32 -> 26.68273 | J28: ='Debt schedule'!E32 -> 27.820797 | K28: ='Debt schedule'!F32 -> 29.542318 | L28: ='Debt schedule'!G32 -> 30.485165
A29: DILUTED EARNINGS PER COMMON SHARE | B29: 19.45 | C29: 14.33 | D29: 15.48 | E29: 17.21 | F29: 16.81 | G29: 3.46
A30: NET INCOME | B30: =B25-B26 -> 5231 | C30: =C25-C26 -> 3826 | D30: =D25-D26 -> 3972 | E30: =E25-E26 -> 4331 | F30: =F25-F26 -> 4092 | G30: =G25-G26 -> 824 | H30: =H25-H26 -> 4912.2144 | I30: =I25-I26 -> 5798.9578 | ... L30: =L25-L26 -> 5814.1307
A31: OTHER COMPREHENSIVE INCOME(LOSS)
A32: Foreign currency translation adhustments | B32: 422 | C32: -363 | D32: -214 | E32: -60 | F32: 2 | H32: 0 | I32: 0 | J32: 0 | K32: 0 | L32: 0
A33: prior service credit | E33: 36 | H33: 0 | I33: 0 | J33: 0 | K33: 0 | L33: 0
A34: Amortization of prior service credit and other | B34: -7 | C34: -8 | D34: -10 | E34: -8 | F34: -5 | H34: -5 | I34: -5 | J34: -5 | K34: -5 | L34: -5
A35: TOTAL OTHER COMP.INCOME(LOSS) | B35: =SUM(B32:B34) -> 415 | C35: =SUM(C32:C34) -> -371 | D35: =SUM(D32:D34) -> -224 | E35: =SUM(E32:E34) -> -32 | F35: =SUM(F32:F34) -> -3 | H35: =SUM(H32:H34) -> -5 | I35: =SUM(I32:I34) -> -5 | J35: =SUM(J32:J34) -> -5 | K35: =SUM(K32:K34) -> -5 | L35: =SUM(L32:L34) -> -5
B36: =B30+B35 -> 5646 | C36: =C30+C35 -> 3455 | D36: =D30+D35 -> 3748 | E36: =E30+E35 -> 4299 | F36: =F30+F35 -> 4089 | H36: =H30+H35 -> 4907.2144 | I36: =I30+I35 -> 5793.9578 | J36: =J30+J35 -> 5782.2822 | K36: =K30+K35 -> 5878.648 | L36: =L30+L35 -> 5809.1307
A39: Assumptions
B40: 2021 | C40: 2022 | D40: 2023 | E40: 2024 | F40: 2025 | G40: Q1 2026 | H40: 2026E | I40: 2027E | J40: 2028E | K40: 2029E | L40: 2020E
A41: REVENUE | C41: =(C5-B5)/B5 -> 0.11378173 | D41: =(D5-C5)/C5 -> -0.035899136 | E41: =(E5-D5)/D5 -> -0.027308524 | F41: =(F5-E5)/E5 -> 0.0026569966 | H41: =(H5-F5)/F5 -> 0.014957972 | I41: =(I5-H5)/H5 -> 0.01842192 | J41: =(J5-I5)/I5 -> 0.022162833 | K41: =(K5-J5)/J5 -> 0.02098911 | L41: =(L5-K5)/K5 -> 0.021099758 | O41: +3–4%/yr — modest parcel volume growth and small price increases after markets normalize.
A42: OPERATING EXPENSES
A43: Salaries and employee benefits | B43: =B7/B$5 -> 0.35937779 | C43: =C7/C$5 -> 0.34282231 | D43: =D7/D$5 -> 0.344063 | E43: =E7/E$5 -> 0.35306125 | F43: =F7/F$5 -> 0.35520779 | H43: 0.355 | I43: 0.355 | J43: 0.355 | K43: 0.355 | L43: 0.355 | O43: ~35.5% of revenue — wage inflation partly offset by DRIVE efficiencies and the Europe workforce reduction (~$150mm annualized savings from 2026).
...

Sheet Operating expenses
A2: FedEx Express Segment
A3: Operating Expense | B3: 2023 | C3: 2024 | D3: 2025 | E3: 2026 | F3: 2027 | G3: 2028 | H3: 2029 | I3: 2030
A4: sales | B4: =Revenue!E4 -> 75884 | C4: =Revenue!F4 -> 74663 | D4: =Revenue!G4 -> 75304 | E4: =Revenue!J4 -> 77338.698 | F4: =Revenue!K4 -> 78695.627 | G4: =Revenue!L4 -> 80336.673 | H4: =Revenue!M4 -> 81896.234 | I4: =Revenue!N4 -> 83495.33
A5: Salaries & Employee Benefits | B5: 24523 | C5: 24606 | D5: 25091 | E5: =E4*E6 -> 24748.384 | F5: =F4*F6 -> 24395.644 | G5: =G4*G6 -> 24904.369 | H5: =H4*H6 -> 25387.833 | I5: =I4*I6 -> 25883.552
E6: =+CHOOSE(Cover!$I$15,E7,E8,E9) -> 0.32 | F6: =+CHOOSE(Cover!$I$15,F7,F8,F9) -> 0.31 | G6: =+CHOOSE(Cover!$I$15,G7,G8,G9) -> 0.31 | H6: =+CHOOSE(Cover!$I$15,H7,H8,H9) -> 0.31 | I6: =+CHOOSE(Cover!$I$15,I7,I8,I9) -> 0.31
A7: Bull | E7: 0.31 | F7: 0.31 | G7: 0.31 | H7: 0.31 | I7: 0.31 | N7: *operating expense decrese by Network 2.0 , which has already been shown in Q1 2026.
A8: Base | B8: =B5/B4 -> 0.3231643 | C8: =C5/C4 -> 0.32956083 | D8: =D5/D4 -> 0.33319611 | E8: 0.32 | F8: 0.31 | G8: 0.31 | H8: 0.31 | I8: 0.31 | N8: *expecting continued operational efficiency, saving 1B from 2026(management foreword)
A9: Bear | E9: 0.32 | F9: 0.32 | G9: 0.32 | H9: 0.32 | I9: 0.32
A10: Purchased Transportation | B10: 19677 | C10: 19330 | D10: 19974 | E10: =E4*E11 -> 20108.062 | F10: =F4*F11 -> 20460.863 | G10: =G4*G11 -> 20887.535 | H10: =H4*H11 -> 21293.021 | I10: =I4*I11 -> 21708.786
E11: =+CHOOSE(Cover!$I$16,E12,E13,E14) -> 0.26 | F11: =+CHOOSE(Cover!$I$16,F12,F13,F14) -> 0.26 | G11: =+CHOOSE(Cover!$I$16,G12,G13,G14) -> 0.26 | H11: =+CHOOSE(Cover!$I$16,H12,H13,H14) -> 0.26 | I11: =+CHOOSE(Cover!$I$16,I12,I13,I14) -> 0.26
A12: Bull | E12: 0.25 | F12: 0.24 | G12: 0.24 | H12: 0.24 | I12: 0.24
A13: Base | B13: =B10/B4 -> 0.25930367 | C13: =C10/C4 -> 0.25889664 | D13: =D10/D4 -> 0.26524487 | E13: 0.26 | F13: 0.26 | G13: 0.26 | H13: 0.26 | I13: 0.26 | N13: *expecting continued operational efficiency, saving 1B from 2026
A14: Bear | E14: 0.27 | F14: 0.27 | G14: 0.27 | H14: 0.27 | I14: 0.27
A15: Rentals & Landing Fees | B15: 4035 | C15: 3863 | D15: 3939 | E15: =E4*E16 -> 4045.431 | F15: =E15*(1+F16) -> 4257.0393 | G15: =F15*(1+G16) -> 4479.7164 | H15: =G15*(1+H16) -> 4714.0413 | I15: =H15*(1+I16) -> 4960.6233
B16: =B15/B4 -> 0.053173264 | C16: =C15/C4 -> 0.051739148 | D16: =D15/D4 -> 0.052307978 | E16: =D16 -> 0.052307978 | F16: =E16 -> 0.052307978 | G16: =F16 -> 0.052307978 | H16: =G16 -> 0.052307978 | I16: =H16 -> 0.052307978 | N16: *maintained at 2025 levels as no effect on landing fees
A17: Depreciation & Amortization | B17: 3655 | C17: 3754 | D17: 3722 | E17: =E4*E18 -> 3812.0554 | F17: =F4*F18 -> 3777.3901 | G17: =G4*G18 -> 3775.8236 | H17: =H4*H18 -> 3849.123 | I17: =I4*I18 -> 3924.2805
B18: =B17/B4 -> 0.048165621 | C18: =C17/C4 -> 0.050279255 | D18: =D17/D4 -> 0.049426325 | E18: =AVERAGE(B18:D18) -> 0.0492904 | F18: 0.048 | G18: 0.047 | H18: 0.047 | I18: 0.047 | N18: *tapered to 4.7 as new equipment will decrease dep.
A19: Fuel | B19: 5157 | C19: 4137 | D19: 3316 | E19: =E4*E20 -> 3405.5976 | F19: =F4*F20 -> 3465.3498 | G19: =G4*G20 -> 3537.613 | H19: =H4*H20 -> 3606.288 | I19: =I4*I20 -> 3676.704
B20: =B19/B4 -> 0.06795899 | C20: =C19/C4 -> 0.055408971 | D20: =D19/D4 -> 0.044034845 | E20: 0.044034845 | F20: 0.044034845 | G20: 0.044034845 | H20: 0.044034845 | I20: 0.044034845 | N20: *Kept at 2025 level
A21: Maintenance & Repairs | B21: 2910 | C21: 2848 | D21: 2799 | E21: =E4*E22 -> 2784.1931 | F21: =F4*F22 -> 2754.3469 | G21: =G4*G22 -> 2811.7835 | H21: =H4*H22 -> 2784.472 | I21: =I4*I22 -> 2838.8412
B22: =B21/B4 -> 0.038348005 | C22: =C21/C4 -> 0.03814473 | D22: =D21/D4 -> 0.03716934 | E22: 0.036 | F22: 0.035 | G22: 0.035 | H22: 0.034 | I22: 0.034 | N22: Tapered to 3.4 expecting less reapirs because of new equipmwnt
A23: Asset Impairment Charges | B23: 70 | C23: 157 | D23: 21 | E23: 21 | F23: 21 | G23: 21 | H23: 21 | I23: 21
A24: Business Optimization Costs | B24: 47 | C24: 251 | D24: 384 | E24: 250 | F24: 100 | G24: 0 | H24: 0 | I24: 0
A25: Intercompany Allocations (Charges) | B25: -689 | C25: -684 | D25: -791 | E25: =E4*E26 -> -812.37266 | F25: =F4*F26 -> -826.62595 | G25: =G4*G26 -> -843.86365 | H25: =H4*H26 -> -860.24542 | I25: =I4*I26 -> -877.04247 | N25: *maintaining same as 2025
B26: =B25/B4 -> -0.0090796479 | C26: =C25/C4 -> -0.0091611642 | D26: =D25/D4 -> -0.01050409 | E26: -0.01050409 | F26: -0.01050409 | G26: -0.01050409 | H26: -0.01050409 | I26: -0.01050409
A27: Other | B27: 12306 | C27: 11582 | D27: 11964 | E27: =E28*E4 -> 12275.412 | F27: =F28*F4 -> 12400.397 | G27: =G28*G4 -> 12724.604 | H27: =H28*H4 -> 12958.384 | I27: =I28*I4 -> 13197.674
B28: =B27/B4 -> 0.16216857 | C28: =C27/C4 -> 0.15512369 | D28: =D27/D4 -> 0.15887602 | E28: =AVERAGE(B28:D28) -> 0.15872276 | F28: =AVERAGE(C28:E28) -> 0.15757416 | G28: =AVERAGE(D28:F28) -> 0.15839098 | H28: =AVERAGE(E28:G28) -> 0.1582293 | I28: =AVERAGE(F28:H28) -> 0.15806481
A29: Total Operating Expenses | B29: =SUM(B5:B27) -> 71691.781 | C29: =SUM(C5:C27) -> 69844.775 | D29: =SUM(D5:D27) -> 70419.771 | E29: =SUM(E5:E27) -> 70640.243 | F29: =SUM(F5:F27) -> 70807.853 | G29: =SUM(G5:G27) -> 72301.029 | H29: =SUM(H5:H27) -> 73756.363 | I29: =SUM(I5:I27) -> 75336.865
A31: FedEx Freight Segment
A32: Operating Expense | B32: 2023 | C32: 2024 | D32: 2025 | E32: 2026 | F32: 2027 | G32: 2028 | H32: 2029 | I32: 2030
A33: sales YOY | B33: =Revenue!E5 -> 10084 | C33: =Revenue!F5 -> 9429 | D33: =Revenue!G5 -> 8892 | E33: =Revenue!J5 -> 8962.7005 | F33: =Revenue!K5 -> 9156.043 | G33: =Revenue!L5 -> 9432.6225 | H33: =Revenue!M5 -> 9717.5566 | I33: =Revenue!N5 -> 10011.098
A34: Salaries & Employee Benefits | B34: 4057 | C34: 3923 | D34: 3865 | E34: =E33*E35 -> 3895.7307 | F34: =F33*F35 -> 3979.769 | G34: =G33*G35 -> 4099.9872 | H34: =H33*H35 -> 4223.8368 | I34: =I33*I35 -> 4351.4275
B35: =B34/B33 -> 0.40232051 | C35: =C34/C33 -> 0.41605685 | D35: =D34/D33 -> 0.43466037 | E35: =D35 -> 0.43466037 | F35: =E35 -> 0.43466037 | G35: =F35 -> 0.43466037 | H35: =G35 -> 0.43466037 | I35: =H35 -> 0.43466037 | N35: *expected to decrease by optimisation and balanced by wage inflation
A36: Purchased Transportation | B36: 1078 | C36: 877 | D36: 807 | E36: =E33*E37 -> 813.41647 | F36: =F33*F37 -> 830.96342 | G36: =G33*G37 -> 856.06459 | H36: =H33*H37 -> 881.924 | I36: =I33*I37 -> 908.56455
B37: =B36/B33 -> 0.10690202 | C37: =C36/C33 -> 0.093010924 | D37: =D36/D33 -> 0.090755735 | E37: =D37 -> 0.090755735 | F37: =E37 -> 0.090755735 | G37: =F37 -> 0.090755735 | H37: =G37 -> 0.090755735 | I37: =H37 -> 0.090755735 | N37: *expeccted to be low as new equipment is being introduced
A38: Rentals & Landing Fees | B38: 269 | C38: 280 | D38: 287 | E38: =E39*E33 -> 289.28194 | F38: =F39*F33 -> 295.52231 | G38: =G39*G33 -> 304.44924 | H38: =H39*H33 -> 313.64583 | I38: =I39*I33 -> 323.12023
B39: =B38/B33 -> 0.026675922 | C39: =C38/C33 -> 0.02969562 | D39: =D38/D33 -> 0.032276203 | E39: =D39 -> 0.032276203 | F39: =E39 -> 0.032276203 | G39: =F39 -> 0.032276203 | H39: =G39 -> 0.032276203 | I39: =H39 -> 0.032276203 | N39: *similar or slightly higher than 2025 levels
A40: Depreciation & Amortization | B40: 387 | C40: 404 | D40: 416 | E40: =E41*E33 -> 419.30762 | F40: =F41*F33 -> 421.17798 | G40: =G41*G33 -> 433.90063 | H40: =H41*H33 -> 437.29005 | I40: =I41*I33 -> 450.49941
B41: =B40/B33 -> 0.038377628 | C41: =C40/C33 -> 0.042846537 | D41: =D40/D33 -> 0.046783626 | E41: =D41 -> 0.046783626 | F41: 0.046 | G41: 0.046 | H41: 0.045 | I41: 0.045 | N41: *Tapered down to 4.5 as expected to lower dep for newer vehicles
A42: Fuel | B42: 748 | C42: 571 | D42: 457 | E42: =E43*E33 -> 460.63362 | F42: =F43*F33 -> 470.57036 | G42: =G43*G33 -> 484.78503 | H42: =H43*H33 -> 499.42908 | I42: =I43*I33 -> 514.51549
...

Sheet Debt schedule
C3: Debt schedule | I3: Debt (10-K disclosures & management outlook)
A6: Year | B6: 2021 | C6: 2022 | D6: 2023 | E6: 2024 | F6: 2025 | G6: 2026 | H6: 2027 | I6: 2028 | J6: 2029 | K6: 2030
A7: Opening Debt Principal (mm) | C7: =B10 -> 20733 | D7: =C10 -> 20182 | E7: =D10 -> 20453 | F7: =E10 -> 20135 | G7: =F10 -> 19151 | H7: =G10 -> 21780 | I7: =H10 -> 24304 | J7: =I10 -> 27752 | K7: =J10 -> 29617
A8: Maturities (mm) | F8: 0 | G8: 1371 | H8: 1476 | I8: 552 | J8: 1135 | K8: 1802 | P8: Given in 10-K/10-Q — taken from the contractual debt maturity table by fiscal year.
A9: new debt | G9: 4000 | H9: 4000 | I9: 4000 | J9: 3000 | K9: 3000
A10: Closing Debt Principal (mm) | B10: ='Balance sheet'!B34 -> 20733 | C10: ='Balance sheet'!C34 -> 20182 | D10: ='Balance sheet'!D34 -> 20453 | E10: ='Balance sheet'!E34 -> 20135 | F10: ='Balance sheet'!F34 -> 19151 | G10: =G7-G8+G9 -> 21780 | H10: =H7-H8+H9 -> 24304 | I10: =I7-I8+I9 -> 27752 | J10: =J7-J8+J9 -> 29617 | K10: =K7-K8+K9 -> 30815
A11: Avg debt | B11: =AVERAGE(B10,B7) -> 20733 | C11: =AVERAGE(C10,C7) -> 20457.5 | D11: =AVERAGE(D10,D7) -> 20317.5 | E11: =AVERAGE(E10,E7) -> 20294 | F11: =AVERAGE(F10,F7) -> 19643 | G11: =AVERAGE(G10,G7) -> 20465.5 | H11: =AVERAGE(H10,H7) -> 23042 | I11: =AVERAGE(I10,I7) -> 26028 | ... K11: =AVERAGE(K10,K7) -> 30216
A12: Interest expense | B12: =-'Income statement'!B19 -> 793 | C12: =-'Income statement'!C19 -> 689 | D12: =-'Income statement'!D19 -> 694 | E12: =-'Income statement'!E19 -> 745 | F12: =-'Income statement'!F19 -> 789 | G12: =G11*0.042 -> 859.551 | H12: =H11*0.042 -> 967.764 | I12: =I11*0.042 -> 1093.176 | J12: =J11*0.04 -> 1147.38 | K12: =K11*0.04 -> 1208.64 | P12: Modeled — average debt × assumed blended coupon; reflects scheduled paydowns.
A13: Coupon rate | B13: =B12/B11 -> 0.038248203 | C13: =C12/C11 -> 0.03367958 | D13: =D12/D11 -> 0.034157746 | E13: =E12/E11 -> 0.036710358 | F13: =F12/F11 -> 0.040166981 | G13: =G12/G11 -> 0.042 | H13: =H12/H11 -> 0.042 | I13: =I12/I11 -> 0.042 | ... K13: =K12/K11 -> 0.04
A15: capex schedule | B15: FY 2025 | C15: FY 2026 | D15: 2026E | E15: 2027E | F15: 2028E | G15: 2029E | H15: 2030E
A16: By Asset Type | L16: Given in latest 10-Q — year-to-date capex by class (where disclosed).
A17: Aircraft and related equipment | B17: 1251 | C17: 60 | D17: 889 | E17: 1114 | F17: 989 | G17: 410 | H17: 204
A18: Package handling and ground support equipment | B18: 935 | C18: 205 | D18: 1200 | E18: 1250 | F18: 1300 | G18: 1200 | H18: 1100
A19: Information technology | B19: 504 | C19: 118 | D19: 600 | E19: 550 | F19: 525 | G19: 500 | H19: 475
A20: Vehicles and trailers | B20: 434 | C20: 47 | D20: 650 | E20: 600 | F20: 575 | G20: 550 | H20: 525
A21: Facilities and other | B21: 931 | C21: 193 | D21: 1161 | E21: 1000 | F21: 950 | G21: 900 | H21: 850
A22: Total | B22: 4055 | C22: 623 | D22: 4500 | E22: 4514 | F22: 4339 | G22: 3560 | H22: 3154 | L22: Modeled — forward plan based on fleet/ground automation program cadence and historical mix.
C23: Shares outstanding
A26: Year | B26: 2025 | C26: 2026 | D26: 2027 | E26: 2028 | F26: 2029 | G26: 2030
A27: Opening Diluted Shares (mm) | B27: 243 | C27: =B29 -> 232.1 | D27: =C29 -> 222.09 | E27: =D29 -> 212.56 | F27: =E29 -> 203.48 | G27: =F29 -> 194.83
A28: Buybacks (mm) | B28: 10.9 | C28: =C37 -> 10.007786 | D28: =D37 -> 9.5312248 | E28: =E37 -> 9.077357 | F28: =F37 -> 8.6451019 | G28: =G37 -> 8.2334304 | L28: Modeled — shares repurchased derived from assumed buyback dollars ÷ est. average price (authorizations disclosed but volumes not).
A29: Ending Diluted Shares (mm) | B29: =ROUND(B27-B28,2) -> 232.1 | C29: =ROUND(C27-C28,2) -> 222.09 | D29: =ROUND(D27-D28,2) -> 212.56 | E29: =ROUND(E27-E28,2) -> 203.48 | F29: =ROUND(F27-F28,2) -> 194.83 | G29: =ROUND(G27-G28,2) -> 186.6
A30: Avg Diluted Shares (mm) | B30: =(B27+B29)/2 -> 237.55 | C30: =ROUND(AVERAGE(C27,C29),2) -> 227.1 | D30: =ROUND(AVERAGE(D27,D29),2) -> 217.33 | E30: =ROUND(AVERAGE(E27,E29),2) -> 208.02 | F30: =ROUND(AVERAGE(F27,F29),2) -> 199.16 | G30: =ROUND(AVERAGE(G27,G29),2) -> 190.72
A31: Net income | B31: ='Income statement'!F27 -> 4092 | C31: ='Income statement'!H27 -> 4912.2144 | D31: ='Income statement'!I27 -> 5798.9578 | E31: ='Income statement'!J27 -> 5787.2822 | F31: ='Income statement'!K27 -> 5883.648 | G31: ='Income statement'!L27 -> 5814.1307
A32: Eps | B32: =B31/B30 -> 17.225847 | C32: =C31/C30 -> 21.630182 | D32: =D31/D30 -> 26.68273 | E32: =E31/E30 -> 27.820797 | F32: =F31/F30 -> 29.542318 | G32: =G31/G30 -> 30.485165
B35: 2500 | C35: 2500 | D35: 2500 | E35: 2500 | F35: 2500 | G35: 2500
B36: 237.91 | C36: =B36*(1+0.05) -> 249.8055 | D36: =C36*(1+0.05) -> 262.29577 | E36: =D36*(1+0.05) -> 275.41056 | F36: =E36*(1+0.05) -> 289.18109 | G36: =F36*(1+0.05) -> 303.64015
B37: =B35/B36 -> 10.508175 | C37: =C35/C36 -> 10.007786 | D37: =D35/D36 -> 9.5312248 | E37: =E35/E36 -> 9.077357 | F37: =F35/F36 -> 8.6451019 | G37: =G35/G36 -> 8.2334304

Sheet CapEx
A3: Capital Expenditures
A4: FY 2023 – FY 2026
A5: Years ended May 31
A6: In millions
E7: Q1 YTD
B8: FY 2023 | C8: FY 2024 | D8: FY 2025 | E8: FY 2026 | F8: 2026E | G8: 2027E | H8: 2028E | I8: 2029E | J8: 2030E
A9: By Asset Type
A10: Aircraft and related equipment | B10: 1684 | C10: 1627 | D10: 1251 | E10: 60 | F10: 889 | G10: 1114 | H10: 1114 | I10: 1114 | J10: 1114 | L10: Assumed to decline post-FY26 as major aircraft modernization under Network 2.0 concludes and fleet age profile stabilizes.
A11: Package handling and ground support equipment | B11: 1851 | C11: 974 | D11: 935 | E11: 205 | F11: 1200 | G11: 1250 | H11: 1300 | I11: 1250 | J11: 1250 | L11: Peaks through FY26 with automation and hub consolidation projects, then normalizes as Network 2.0 transitions from build-out to maintenance.
A12: Information technology | B12: 802 | C12: 656 | D12: 504 | E12: 118 | F12: 600 | G12: 550 | H12: 525 | I12: 500 | J12: 475 | L12: Gradually tapers after FY26 as key digital infrastructure and routing-optimization platforms are fully deployed, leaving steady maintenance spend.
A13: Vehicles and trailers | B13: 719 | C13: 709 | D13: 434 | E13: 47 | F13: 650 | G13: 600 | H13: 575 | I13: 550 | J13: 525 | L13: Moderate decline due to completion of large-scale Ground fleet refresh and increased reliance on leased or partner-supplied EV vehicles.
A14: Facilities and other | B14: 1118 | C14: 1210 | D14: 931 | E14: 193 | F14: 1161 | G14: 1000 | H14: 950 | I14: 950 | J14: 950 | L14: Decreases from FY26 onward as major hub expansions and building upgrades are completed, consistent with capital discipline and FCF priorities.
A15: Total | B15: 6174 | C15: 5176 | D15: 4055 | E15: 623 | F15: =SUM(F10:F14) -> 4500 | G15: =SUM(G10:G14) -> 4514 | H15: =SUM(H10:H14) -> 4464 | I15: =SUM(I10:I14) -> 4364 | J15: =SUM(J10:J14) -> 4314 | L15: FY26 ≈ $4.5 B per management guidance; decline through FY30 reflects completion of modernization cycle and focus on shareholder returns.
A17: By Segment
A18: Federal Express segment | B18: 5480 | C18: 4591 | D18: 3505 | E18: 568 | L18: Fore-word
A19: FedEx Freight segment | B19: 557 | C19: 461 | D19: 437 | E19: 32 | L19: “FY26 CapEx ≈ $4.5 B driven by aircraft and Network 2.0 investments.”
A20: Other | B20: 137 | C20: 124 | D20: 113 | E20: 23 | L20: “Investments in Network 2.0 and sort facility automation continue in FY26.”
A21: Total | B21: 6174 | C21: 5176 | D21: 4055 | E21: 623 | L21: “We expect lower incremental spend in subsequent years as platform deployments are completed.”
L22: “Vehicle purchases moderated as fleet modernization and electrification partnerships progress.”
L23: “Network 2.0 continues to focus on facility optimization, automation, and hub consolidation, which are expected to deliver efficiency and cost benefits in FY26 and beyond.”
D28: Moderate decline due to completion of large-scale Ground fleet refresh and increased reliance on leased or partner-supplied EV vehicles.

Sheet Balance sheet
A1: CONSOLIDATED BALANCE SHEETS
A2: (IN MILLIONS, EXCEPT SHARE DATA)
B3: 2021 | C3: 2022 | D3: 2023 | E3: 2024 | F3: 2025 | G3: 2026E | H3: 2027E | I3: 2028E | J3: 2029E | K3: 2030E
A4: ASSETS
A5: CURRENT ASSETS
A6: Cash and cash equivalents | B6: 7087 | C6: 6897 | D6: 6856 | E6: 6501 | F6: 5502 | G6: ='Derived cash flow'!C57 -> 6308.2147 | H6: ='Derived cash flow'!D57 -> 9169.9292 | I6: ='Derived cash flow'!E57 -> 12178.583 | J6: ='Derived cash flow'!F57 -> 15202.02 | K6: ='Derived cash flow'!G57 -> 17608.292
A7: Receivables | B7: 12069 | C7: 11863 | D7: 10188 | E7: 10087 | F7: 11368 | G7: =(G66*'Income statement'!H5)/365 -> 11207.474 | H7: =(H66*'Income statement'!I5)/365 -> 11413.938 | I7: =(I66*'Income statement'!J5)/365 -> 11666.903 | J7: =(J66*'Income statement'!K5)/365 -> 11911.781 | K7: =(K66*'Income statement'!L5)/365 -> 12163.116
A8: Spare parts | B8: 587 | C8: 637 | D8: 604 | E8: 614 | F8: 602 | G8: ='Income statement'!H12*'Balance sheet'!G67 -> 593.7341 | H8: ='Income statement'!I12*'Balance sheet'!H67 -> 587.9959 | I8: ='Income statement'!J12*'Balance sheet'!I67 -> 601.03877 | J8: ='Income statement'!K12*'Balance sheet'!J67 -> 596.82689 | K8: ='Income statement'!L12*'Balance sheet'!K67 -> 609.40733
A9: Prepaid expenses | B9: 837 | C9: 968 | D9: 962 | E9: 1005 | F9: 914 | G9: =G68*'Income statement'!H16 -> 933.01513 | H9: =H68*'Income statement'!I16 -> 936.98775 | I9: =I68*'Income statement'!J16 -> 958.7094 | J9: =J68*'Income statement'!K16 -> 978.87628 | K9: =K68*'Income statement'!L16 -> 1002.0439
A10: Total current assets | B10: =SUM(B6:B9) -> 20580 | C10: =SUM(C6:C9) -> 20365 | D10: =SUM(D6:D9) -> 18610 | E10: =SUM(E6:E9) -> 18207 | F10: =SUM(F6:F9) -> 18386 | G10: =SUM(G6:G9) -> 19042.438 | H10: =SUM(H6:H9) -> 22108.85 | I10: =SUM(I6:I9) -> 25405.234 | ... K10: =SUM(K6:K9) -> 31382.86
A11: PROPERTY AND EQUIPMENT
A12: Aircraft and related equipment | B12: 26268 | C12: 27874 | D12: 29108 | E12: 30525 | F12: 31584 | G12: =G71 -> 32473 | H12: =H71 -> 33587 | I12: =I71 -> 34701 | J12: =J71 -> 35815 | K12: =K71 -> 36929
A13: Package handling and ground support equipment | B13: 13012 | C13: 14930 | D13: 16839 | E13: 17880 | F13: 18878 | G13: =G72 -> 20078 | H13: =H72 -> 21328 | I13: =I72 -> 22628 | J13: =J72 -> 23878 | K13: =K72 -> 25128
A14: Information technology | B14: 7486 | C14: 8098 | D14: 8792 | E14: 9203 | F14: 9706 | G14: =G73 -> 10306 | H14: =H73 -> 10856 | I14: =I73 -> 11381 | J14: =J73 -> 11881 | K14: =K73 -> 12356
A15: Vehicles and trailers | B15: 9282 | C15: 9806 | D15: 10191 | E15: 10568 | F15: 10949 | G15: =G74 -> 11599 | H15: =H74 -> 12199 | I15: =I74 -> 12774 | J15: =J74 -> 13324 | K15: =K74 -> 13849
A16: Facilities and other | B16: 14029 | C16: 14567 | D16: 15694 | E16: 16215 | F16: 16505 | G16: =G75 -> 17666 | H16: =H75 -> 18666 | I16: =I75 -> 19616 | J16: =J75 -> 20566 | K16: =K75 -> 21516
A17: Total PP&E | B17: =SUM(B12:B16) -> 70077 | C17: =SUM(C12:C16) -> 75275 | D17: =SUM(D12:D16) -> 80624 | E17: =SUM(E12:E16) -> 84391 | F17: =SUM(F12:F16) -> 87622 | G17: =SUM(G12:G16) -> 92122 | H17: =SUM(H12:H16) -> 96636 | I17: =SUM(I12:I16) -> 101100 | ... K17: =SUM(K12:K16) -> 109778
A18: Depreciation and amortization, accumulated | B18: -34325 | C18: -37184 | D18: -39926 | E18: -42900 | F18: -45980 | G18: =G17*G77 -> -46284.087 | H18: =H17*H77 -> -48552.018 | I18: =I17*I77 -> -50794.828 | J18: =J17*J77 -> -52987.396 | K18: =K17*K77 -> -55154.843
A19: Net PP&E | B19: =B17+B18 -> 35752 | C19: =C17+C18 -> 38091 | D19: =D17+D18 -> 40698 | E19: =E17+E18 -> 41491 | F19: =F17+F18 -> 41642 | G19: =G17+G18 -> 45837.913 | H19: =H17+H18 -> 48083.982 | I19: =I17+I18 -> 50305.172 | ... K19: =K17+K18 -> 54623.157
A20: OTHER LONG-TERM ASSETS | E20: =E18-D18 -> -2974
A21: Operating lease right-of-use assets | B21: 15383 | C21: 16613 | D21: 17347 | E21: 17115 | F21: 16453 | G21: =G80 -> 15753 | H21: =H80 -> 15103 | I21: =I80 -> 14503 | J21: =J80 -> 14003 | K21: =K80 -> 13603
A22: Goodwill | B22: 6992 | C22: 6544 | D22: 6435 | E22: 6423 | F22: 6603 | G22: 6603 | H22: 6603 | I22: 6603 | J22: 6603 | K22: 6603
A23: Other assets | B23: 4070 | C23: 4381 | D23: 4053 | E23: 3771 | F23: 4543 | G23: =G82*'Income statement'!H5 -> 4193.4847 | H23: =H82*'Income statement'!I5 -> 4270.7367 | I23: =I82*'Income statement'!J5 -> 4365.3883 | J23: =J82*'Income statement'!K5 -> 4457.014 | K23: =K82*'Income statement'!L5 -> 4551.0559
A24: Total other long-term assets | B24: =SUM(B21:B23) -> 26445 | C24: =SUM(C21:C23) -> 27538 | D24: =SUM(D21:D23) -> 27835 | E24: =SUM(E21:E23) -> 27309 | F24: =SUM(F21:F23) -> 27599 | G24: =SUM(G21:G23) -> 26549.485 | H24: =SUM(H21:H23) -> 25976.737 | I24: =SUM(I21:I23) -> 25471.388 | ... K24: =SUM(K21:K23) -> 24757.056
A25: TOTAL ASSETS | B25: =B24+B19+B10 -> 82777 | C25: =C24+C19+C10 -> 85994 | D25: =D24+D19+D10 -> 87143 | E25: =E24+E19+E10 -> 87007 | F25: =F24+F19+F10 -> 87627 | G25: =G24+G19+G10 -> 91429.836 | H25: =H24+H19+H10 -> 96169.569 | I25: =I24+I19+I10 -> 101181.79 | ... K25: =K24+K19+K10 -> 110763.07
A26: LIABILITIES AND COMMON STOCKHOLDERS INVESTMENT
A27: CURRENT LIABILITIES
A28: Current portion of long-term debt | B28: 146 | C28: 82 | D28: 126 | E28: 68 | F28: 1428 | G28: ='Debt schedule'!G8 -> 1371 | H28: ='Debt schedule'!H8 -> 1476 | I28: ='Debt schedule'!I8 -> 552 | J28: ='Debt schedule'!J8 -> 1135 | K28: ='Debt schedule'!K8 -> 1802
A29: Accrued salaries and employee benefits | B29: 2903 | C29: 2531 | D29: 2475 | E29: 2673 | F29: 2731 | G29: ='Income statement'!H7*G88 -> 2638.3995 | H29: ='Income statement'!I7*H88 -> 2620.8356 | I29: ='Income statement'!J7*I88 -> 2680.4053 | J29: ='Income statement'!K7*J88 -> 2738.2898 | K29: ='Income statement'!L7*K88 -> 2797.7206
A30: Accounts payable | B30: 3841 | C30: 4030 | D30: 3848 | E30: 3189 | F30: 3692 | G30: =G89*'Income statement'!H16 -> 3723.3609 | H30: =H89*'Income statement'!I16 -> 3739.2143 | I30: =I89*'Income statement'!J16 -> 3825.8984 | J30: =J89*'Income statement'!K16 -> 3906.3779 | K30: =K89*'Income statement'!L16 -> 3998.8322
A31: Operating lease liabilities | B31: 2208 | C31: 2443 | D31: 2390 | E31: 2463 | F31: 2565 | G31: =G90*C147 -> 2362.95 | H31: =H90*D147 -> 2265.45 | I31: =I90*E147 -> 2175.45 | J31: =J90*F147 -> 2100.45 | K31: =K90*G147 -> 2040.45
A32: Accrued expenses | B32: 4562 | C32: 5188 | D32: 4747 | E32: 4962 | F32: 4995 | G32: =G91*'Income statement'!H16 -> 4871.0549 | H32: =H91*'Income statement'!I16 -> 4891.795 | I32: =I91*'Income statement'!J16 -> 5005.1987 | J32: =J91*'Income statement'!K16 -> 5110.4853 | K32: =K91*'Income statement'!L16 -> 5231.4379
A33: Total current liabilities | B33: =SUM(B28:B32) -> 13660 | C33: =SUM(C28:C32) -> 14274 | D33: =SUM(D28:D32) -> 13586 | E33: =SUM(E28:E32) -> 13355 | F33: =SUM(F28:F32) -> 15411 | G33: =SUM(G28:G32) -> 14966.765 | H33: =SUM(H28:H32) -> 14993.295 | I33: =SUM(I28:I32) -> 14238.952 | ... K33: =SUM(K28:K32) -> 15870.441
A34: Long term debt | B34: 20733 | C34: 20182 | D34: 20453 | E34: 20135 | F34: 19151 | G34: ='Debt schedule'!G10 -> 21780 | H34: ='Debt schedule'!H10 -> 24304 | I34: ='Debt schedule'!I10 -> 27752 | J34: ='Debt schedule'!J10 -> 29617 | K34: ='Debt schedule'!K10 -> 30815
A35: OTHER LONG-TERM LIABILITIES
A36: Deferred income taxes | B36: 3927 | C36: 4093 | D36: 4489 | E36: 4482 | F36: 4205 | G36: =G19*G95 -> 4919.2944 | H36: =H19*H95 -> 5136.1002 | I36: =I19*I95 -> 5366.9381 | J36: =J19*J95 -> 5560.687 | K36: =K19*K95 -> 5765.6598
A37: Pension | B37: 3501 | C37: 4448 | D37: 3130 | E37: 2010 | F37: 1698 | G37: =G96 -> 1897 | H37: =H96 -> 1939 | I37: =I96 -> 2000 | J37: =J96 -> 2063 | K37: =K96 -> 2137
A38: Self-insurance accruals | B38: 2430 | C38: 2889 | D38: 3339 | E38: 3701 | F38: 4033 | G38: =G97*'Income statement'!H16 -> 4340.7875 | H38: =H97*'Income statement'!I16 -> 4666.7836 | I38: =I97*'Income statement'!J16 -> 5089.6136 | J38: =J97*'Income statement'!K16 -> 5517.9372 | K38: =K97*'Income statement'!L16 -> 5977.3979
A39: Operating lease liabilities | B39: 13375 | C39: 14487 | D39: 15363 | E39: 15053 | F39: 14272 | G39: =G98*C147 -> 13390.05 | H39: =H98*D147 -> 12837.55 | I39: =I98*E147 -> 12327.55 | J39: =J98*F147 -> 11902.55 | K39: =K98*G147 -> 11562.55
A40: Other Liabilities | B40: 983 | C40: 682 | D40: 695 | E40: 689 | F40: 783 | G40: =G99*'Income statement'!H5 -> 775.90568 | H40: =H99*'Income statement'!I5 -> 790.19935 | I40: =I99*'Income statement'!J5 -> 807.71241 | J40: =J99*'Income statement'!K5 -> 824.66557 | K40: =K99*'Income statement'!L5 -> 842.06581
...

Sheet Derived cash flow
A1: Free cash flow | B1: 2025 | C1: 2026 | D1: 2027 | E1: 2028 | F1: 2029 | G1: 2030
A2: Net Income | B2: ='Income statement'!F27 -> 4092 | C2: ='Income statement'!H27 -> 4912.2144 | D2: ='Income statement'!I27 -> 5798.9578 | E2: ='Income statement'!J27 -> 5787.2822 | F2: ='Income statement'!K27 -> 5883.648 | G2: ='Income statement'!L27 -> 5814.1307
A4: ASSETS
A5: CURRENT ASSETS
A6: Cash and cash equivalents
A7: Receivables | B7: ='Balance sheet'!E7-'Balance sheet'!F7 -> -1281 | C7: ='Balance sheet'!F7-'Balance sheet'!G7 -> 160.52566 | D7: ='Balance sheet'!G7-'Balance sheet'!H7 -> -206.46319 | E7: ='Balance sheet'!H7-'Balance sheet'!I7 -> -252.96519 | F7: ='Balance sheet'!I7-'Balance sheet'!J7 -> -244.8779 | G7: ='Balance sheet'!J7-'Balance sheet'!K7 -> -251.33568
A8: Spare parts | B8: ='Balance sheet'!E8-'Balance sheet'!F8 -> 12 | C8: ='Balance sheet'!F8-'Balance sheet'!G8 -> 8.2658981 | D8: ='Balance sheet'!G8-'Balance sheet'!H8 -> 5.7382067 | E8: ='Balance sheet'!H8-'Balance sheet'!I8 -> -13.042871 | F8: ='Balance sheet'!I8-'Balance sheet'!J8 -> 4.211872 | G8: ='Balance sheet'!J8-'Balance sheet'!K8 -> -12.580438
A9: Prepaid expenses | B9: ='Balance sheet'!E9-'Balance sheet'!F9 -> 91 | C9: ='Balance sheet'!F9-'Balance sheet'!G9 -> -19.015127 | D9: ='Balance sheet'!G9-'Balance sheet'!H9 -> -3.9726235 | E9: ='Balance sheet'!H9-'Balance sheet'!I9 -> -21.721653 | F9: ='Balance sheet'!I9-'Balance sheet'!J9 -> -20.166878 | G9: ='Balance sheet'!J9-'Balance sheet'!K9 -> -23.167593
A10: Total current assets
A11: PROPERTY AND EQUIPMENT
A12: Aircraft and related equipment
A13: Package handling and ground support equipment
A14: Information technology
A15: Vehicles and trailers
A16: Facilities and other
A17: Total PP&E
A18: Depreciation and amortization
A19: Net PP&E | B19: ='Balance sheet'!E19-'Balance sheet'!F19 -> -151 | C19: ='Balance sheet'!F19-'Balance sheet'!G19 -> -4195.9134 | D19: ='Balance sheet'!G19-'Balance sheet'!H19 -> -2246.0687 | E19: ='Balance sheet'!H19-'Balance sheet'!I19 -> -2221.1898 | F19: ='Balance sheet'!I19-'Balance sheet'!J19 -> -2171.432 | G19: ='Balance sheet'!J19-'Balance sheet'!K19 -> -2146.553
A20: OTHER LONG-TERM ASSETS | B20: ='Balance sheet'!E20-'Balance sheet'!F20 -> -2974 | C20: ='Balance sheet'!F20-'Balance sheet'!G20 -> 0 | D20: ='Balance sheet'!G20-'Balance sheet'!H20 -> 0 | E20: ='Balance sheet'!H20-'Balance sheet'!I20 -> 0 | F20: ='Balance sheet'!I20-'Balance sheet'!J20 -> 0 | G20: ='Balance sheet'!J20-'Balance sheet'!K20 -> 0
A21: Operating lease right-of-use assets | B21: ='Balance sheet'!E21-'Balance sheet'!F21 -> 662 | C21: ='Balance sheet'!F21-'Balance sheet'!G21 -> 700 | D21: ='Balance sheet'!G21-'Balance sheet'!H21 -> 650 | E21: ='Balance sheet'!H21-'Balance sheet'!I21 -> 600 | F21: ='Balance sheet'!I21-'Balance sheet'!J21 -> 500 | G21: ='Balance sheet'!J21-'Balance sheet'!K21 -> 400
A22: Goodwill | B22: ='Balance sheet'!E22-'Balance sheet'!F22 -> -180 | C22: ='Balance sheet'!F22-'Balance sheet'!G22 -> 0 | D22: ='Balance sheet'!G22-'Balance sheet'!H22 -> 0 | E22: ='Balance sheet'!H22-'Balance sheet'!I22 -> 0 | F22: ='Balance sheet'!I22-'Balance sheet'!J22 -> 0 | G22: ='Balance sheet'!J22-'Balance sheet'!K22 -> 0
A23: Other assets | B23: ='Balance sheet'!E23-'Balance sheet'!F23 -> -772 | C23: ='Balance sheet'!F23-'Balance sheet'!G23 -> 349.51532 | D23: ='Balance sheet'!G23-'Balance sheet'!H23 -> -77.252039 | E23: ='Balance sheet'!H23-'Balance sheet'!I23 -> -94.651624 | F23: ='Balance sheet'!I23-'Balance sheet'!J23 -> -91.625615 | G23: ='Balance sheet'!J23-'Balance sheet'!K23 -> -94.041914
A24: Total other long-term assets
A25: TOTAL ASSETS
A26: LIABILITIES AND COMMON STOCKHOLDERS INVESTMENT
A27: CURRENT LIABILITIES
A28: Current portion of long-term debt | B28: ='Balance sheet'!F28-'Balance sheet'!E28 -> 1360 | C28: ='Balance sheet'!G28-'Balance sheet'!F28 -> -57 | D28: ='Balance sheet'!H28-'Balance sheet'!G28 -> 105 | E28: ='Balance sheet'!I28-'Balance sheet'!H28 -> -924 | F28: ='Balance sheet'!J28-'Balance sheet'!I28 -> 583 | G28: ='Balance sheet'!K28-'Balance sheet'!J28 -> 667
A29: Accrued salaries and employee benefits | B29: ='Balance sheet'!F29-'Balance sheet'!E29 -> 58 | C29: ='Balance sheet'!G29-'Balance sheet'!F29 -> -92.600487 | D29: ='Balance sheet'!H29-'Balance sheet'!G29 -> -17.563959 | E29: ='Balance sheet'!I29-'Balance sheet'!H29 -> 59.569706 | F29: ='Balance sheet'!J29-'Balance sheet'!I29 -> 57.884568 | G29: ='Balance sheet'!K29-'Balance sheet'!J29 -> 59.430774
A30: Accounts payable | B30: ='Balance sheet'!F30-'Balance sheet'!E30 -> 503 | C30: ='Balance sheet'!G30-'Balance sheet'!F30 -> 31.360867 | D30: ='Balance sheet'!H30-'Balance sheet'!G30 -> 15.853452 | E30: ='Balance sheet'!I30-'Balance sheet'!H30 -> 86.684073 | F30: ='Balance sheet'!J30-'Balance sheet'!I30 -> 80.479472 | G30: ='Balance sheet'!K30-'Balance sheet'!J30 -> 92.454353
A31: Operating lease liabilities | B31: ='Balance sheet'!F31-'Balance sheet'!E31 -> 102 | C31: ='Balance sheet'!G31-'Balance sheet'!F31 -> -202.05 | D31: ='Balance sheet'!H31-'Balance sheet'!G31 -> -97.5 | E31: ='Balance sheet'!I31-'Balance sheet'!H31 -> -90 | F31: ='Balance sheet'!J31-'Balance sheet'!I31 -> -75 | G31: ='Balance sheet'!K31-'Balance sheet'!J31 -> -60
A32: Accrued expenses | B32: ='Balance sheet'!F32-'Balance sheet'!E32 -> 33 | C32: ='Balance sheet'!G32-'Balance sheet'!F32 -> -123.9451 | D32: ='Balance sheet'!H32-'Balance sheet'!G32 -> 20.740143 | E32: ='Balance sheet'!I32-'Balance sheet'!H32 -> 113.40369 | F32: ='Balance sheet'!J32-'Balance sheet'!I32 -> 105.28658 | G32: ='Balance sheet'!K32-'Balance sheet'!J32 -> 120.95261
A33: Total current liabilities
A34: LONG-TERM DEBT | B34: ='Balance sheet'!F34-'Balance sheet'!E34 -> -984 | C34: ='Balance sheet'!G34-'Balance sheet'!F34 -> 2629 | D34: ='Balance sheet'!H34-'Balance sheet'!G34 -> 2524 | E34: ='Balance sheet'!I34-'Balance sheet'!H34 -> 3448 | F34: ='Balance sheet'!J34-'Balance sheet'!I34 -> 1865 | G34: ='Balance sheet'!K34-'Balance sheet'!J34 -> 1198
A35: OTHER LONG-TERM LIABILITIES | B35: ='Balance sheet'!F35-'Balance sheet'!E35 -> 0 | C35: ='Balance sheet'!G35-'Balance sheet'!F35 -> 0 | D35: ='Balance sheet'!H35-'Balance sheet'!G35 -> 0 | E35: ='Balance sheet'!I35-'Balance sheet'!H35 -> 0 | F35: ='Balance sheet'!J35-'Balance sheet'!I35 -> 0 | G35: ='Balance sheet'!K35-'Balance sheet'!J35 -> 0
A36: Deferred income taxes | B36: ='Balance sheet'!F36-'Balance sheet'!E36 -> -277 | C36: ='Balance sheet'!G36-'Balance sheet'!F36 -> 714.29444 | D36: ='Balance sheet'!H36-'Balance sheet'!G36 -> 216.8058 | E36: ='Balance sheet'!I36-'Balance sheet'!H36 -> 230.83787 | F36: ='Balance sheet'!J36-'Balance sheet'!I36 -> 193.74885 | G36: ='Balance sheet'!K36-'Balance sheet'!J36 -> 204.97284
A37: Pension | B37: ='Balance sheet'!F37-'Balance sheet'!E37 -> -312 | C37: ='Balance sheet'!G37-'Balance sheet'!F37 -> 199 | D37: ='Balance sheet'!H37-'Balance sheet'!G37 -> 42 | E37: ='Balance sheet'!I37-'Balance sheet'!H37 -> 61 | F37: ='Balance sheet'!J37-'Balance sheet'!I37 -> 63 | G37: ='Balance sheet'!K37-'Balance sheet'!J37 -> 74
A38: Self-insurance accruals | B38: ='Balance sheet'!F38-'Balance sheet'!E38 -> 332 | C38: ='Balance sheet'!G38-'Balance sheet'!F38 -> 307.78749 | D38: ='Balance sheet'!H38-'Balance sheet'!G38 -> 325.99608 | E38: ='Balance sheet'!I38-'Balance sheet'!H38 -> 422.83003 | F38: ='Balance sheet'!J38-'Balance sheet'!I38 -> 428.32357 | G38: ='Balance sheet'!K38-'Balance sheet'!J38 -> 459.46075
A39: Operating lease liabilities | B39: ='Balance sheet'!F39-'Balance sheet'!E39 -> -781 | C39: ='Balance sheet'!G39-'Balance sheet'!F39 -> -881.95 | D39: ='Balance sheet'!H39-'Balance sheet'!G39 -> -552.5 | E39: ='Balance sheet'!I39-'Balance sheet'!H39 -> -510 | F39: ='Balance sheet'!J39-'Balance sheet'!I39 -> -425 | G39: ='Balance sheet'!K39-'Balance sheet'!J39 -> -340
A40: Other Liabilities | B40: ='Balance sheet'!F40-'Balance sheet'!E40 -> 94 | C40: ='Balance sheet'!G40-'Balance sheet'!F40 -> -7.0943215 | D40: ='Balance sheet'!H40-'Balance sheet'!G40 -> 14.293672 | E40: ='Balance sheet'!I40-'Balance sheet'!H40 -> 17.513056 | F40: ='Balance sheet'!J40-'Balance sheet'!I40 -> 16.953164 | G40: ='Balance sheet'!K40-'Balance sheet'!J40 -> 17.400244
A41: Total other long-term liabilities
...

Sheet Comps
C1: USD
A2: COMPARABLE COMPANY ANALYSIS
A3: COMPANY DATA
