Workbook

Sheet Cover
E5: GENERAL DYNAMICS Corporation
E6: NYSE: GD
D11: Valuation Date: | E11: =TODAY() -> 46111 | H11: Scenario Switchboard
D12: Company Name: | E12: General Dynamics Corporation
D13: Sector: | E13: Industrials — Aerospace & Defense | H13: Revenue & Operating Expenses
D14: Industry: | E14: Aerospace & Defense | H14: Marine revenue | I14: 2
D15: Rating: | E15: =IF(E23>=Ke!D32,"BUY","SELL") -> BUY | H15: Marine op.margin | I15: 2
H16: Combat revenue | I16: 2
D17: Current Price | E17: =Ke!D17 -> 340.71 | H17: Combat op.margin | I17: 2
D18: Valuation Price | E18: =DCF!B8 -> 388.20096 | H18: IT revenue | I18: 2
D19: 12-month Valuation Price | E19: =DCF!B9 -> 408.20567 | H19: IT op .margin | I19: 2
D20: Valuation Appreciation | E20: =E18/E17-1 -> 0.13938823
D21: 12-mo Valuation Appreciation | E21: =E19/E17-1 -> 0.19810298 | H21: Scenario Key
D22: Dividend Yield | E22: 0.0182 | H22: Bull | I22: 1
D23: Total Valuation Appreciation | E23: =E21+E22 -> 0.21630298 | H23: Base | I23: 2
H24: Bear | I24: 3

Sheet DCF
G2: Share count in Millions
A3: Cost of Equity | B3: =Ke!D32 -> 0.075163557 | G3: =TODAY() -> 46111 | H3: Today | I3: 270.38976
A4: Number of Shares in thousands: | G4: =G3+365 -> 46476 | H4: One year | I4: =Equity!G21 -> 266.88682
G5: =G4+366 -> 46842 | H5: Two year | I5: =Equity!H21 -> 263.06703
A6: Actual Price: | B6: =Ke!D17 -> 340.71 | C6: At close oct 22, 2025
A8: Model Valuation: | B8: =B24 -> 388.20096
A9: Model 12 Month Price Target: | B9: =B46 -> 408.20567
A12: Model Current Valuation with Sensitivity of Ke
D14: 46387 | E14: 46752 | F14: 47118 | G14: 47483 | H14: 47848 | I14: 48213
A15: Time period (years) | D15: =MAX((D14-$G$3)/365,0) -> 0.75616438 | E15: =MAX((E14-$G$3)/365,0) -> 1.7561644 | F15: =MAX((F14-$G$3)/365,0) -> 2.7589041 | G15: =MAX((G14-$G$3)/365,0) -> 3.7589041 | H15: =MAX((H14-$G$3)/365,0) -> 4.7589041 | I15: =MAX((I14-$G$3)/365,0) -> 5.7589041
A16: Nominal FCFE: | D16: ='Cash flow'!G48 -> 3788.3468 | E16: ='Cash flow'!H48 -> 4309.4143 | F16: ='Cash flow'!I48 -> 4807.6934 | G16: ='Cash flow'!J48 -> 5300.9532 | H16: ='Cash flow'!K48 -> 5890.0695 | I16: ='Cash flow'!L48 -> 6112.9996
A17: PV FCFE: | D17: =D16*D15/((1+$B$3)^D15) -> 2711.8523 | E17: =E16/((1+$B$3)^E15) -> 3794.406 | F17: =F16/((1+$B$3)^F15) -> 3936.421 | G17: =G16/((1+$B$3)^G15) -> 4036.8649 | H17: =H16/((1+$B$3)^H15) -> 4171.9214 | I17: =I16/((1+$B$3)^I15) -> 4027.1289
A19: Terminal Growth Rate | B19: 0.025
A21: Terminal Value in 2030 | B21: =I16*(1+B19)/(B3-B19) -> 124907.9
A22: PV of Terminal Value | B22: =B21/(1+B3)^(I15) -> 82286.971
A23: Total PV: | B23: =SUM(D17:I17)+B22 -> 104965.57
A24: Valuation per Share ($): | B24: =B23/I3 -> 388.20096
C25: Terminal Growth Rate
B26: =B24 -> 388.20096 | C26: =D26-L27 -> 0.005 | D26: =E26-L27 -> 0.01 | E26: =F26-L27 -> 0.015 | F26: 0.02 | G26: =F26+L27 -> 0.025 | H26: =G26+L27 -> 0.03 | I26: =H26+L27 -> 0.035 | L26: 0.005
B27: =B28+L27 -> 0.090163557 | C27: 242.28174 | D27: 253.26128 | E27: 265.70158 | F27: 279.91491 | G27: 296.30943 | H27: 315.42893 | I27: 338.0144 | L27: 0.005
B28: =B29+L27 -> 0.085163557 | C28: 258.2885 | D28: 271.00394 | E28: 285.53164 | F28: 302.28877 | G28: 321.83115 | H28: 344.91617 | I28: 372.60313
B29: =B30+L27 -> 0.080163557 | C29: 276.44382 | D29: 291.29434 | E29: 308.42383 | F29: 328.40047 | G29: 351.99846 | H29: 380.30065 | I29: 414.86945
A30: Cost Of Equity Ke | B30: =Ke!D32 -> 0.075163557 | C30: 297.20756 | D30: 314.71947 | E30: 335.14209 | F30: 359.26691 | G30: 388.20096 | H30: 423.54152 | I30: 467.68123
B31: =B30-L27 -> 0.070163557 | C31: 321.18072 | D31: 342.06143 | E31: 366.72738 | F31: 396.31044 | G31: 432.44371 | H31: 477.5735 | I31: 535.53755
B32: =B31-L27 -> 0.065163557 | C32: 349.16409 | D32: 374.38593 | E32: 404.6357 | F32: 441.58329 | G32: 487.73016 | H32: 547.00053 | I32: 625.92056
B33: =B32-L27 -> 0.060163557 | C33: 382.24884 | D33: 413.18358 | E33: 450.96781 | F33: 498.15963 | G33: 558.77212 | H33: 639.47921 | I33: 752.25932
A36: Model 12 Month Price Target with Sensitivity of Ke
D38: =D14 -> 46387 | E38: =E14 -> 46752 | F38: =F14 -> 47118 | G38: =G14 -> 47483 | H38: =H14 -> 47848 | I38: =I14 -> 48213
A39: Time period | D39: =MAX((D38-$G$4)/365,0) -> 0 | E39: =MAX((E38-$G$4)/365,0) -> 0.75616438 | F39: =MAX((F38-$G$4)/365,0) -> 1.7589041 | G39: =MAX((G38-$G$4)/365,0) -> 2.7589041 | H39: =MAX((H38-$G$4)/365,0) -> 3.7589041 | I39: =MAX((I38-$G$4)/365,0) -> 4.7589041
A40: Nominal FCFE: | D40: ='Cash flow'!G48 -> 3788.3468 | E40: ='Cash flow'!H48 -> 4309.4143 | F40: ='Cash flow'!I48 -> 4807.6934 | G40: ='Cash flow'!J48 -> 5300.9532 | H40: ='Cash flow'!K48 -> 5890.0695 | I40: ='Cash flow'!L48 -> 6112.9996
A41: PV FCFE: | D41: =D40*D39/((1+$B$3)^D39) -> 0 | E41: =E40*E39/((1+$B$3)^E39) -> 3084.8535 | F41: =F40/((1+$B$3)^F39) -> 4232.2964 | G41: =G40/((1+$B$3)^G39) -> 4340.29 | H41: =H40/((1+$B$3)^H39) -> 4485.4979 | I41: =I40/((1+$B$3)^I39) -> 4329.8223
A43: Terminal Value in 2030 | B43: =I40*(1+B19)/(B3-B19) -> 124907.9
A44: PV of Terminal Value | B44: =B43/(1+B3)^I39 -> 88471.952
A45: Total PV: | B45: =SUM(D41:I41)+B44 -> 108944.71
A46: Valuation per Share ($): | B46: =B45/I4 -> 408.20567
C47: Terminal Growth Rate
B48: =B46 -> 408.20567 | C48: =D48-$L$26 -> 0.005 | D48: =E48-$L$26 -> 0.01 | E48: =F48-$L$26 -> 0.015 | F48: 0.02 | G48: =F48+$L$26 -> 0.025 | H48: =G48+$L$26 -> 0.03 | I48: =H48+$L$26 -> 0.035
B49: =B50+$L$27 -> 0.090163557 | C49: 252.94327 | D49: 265.06987 | E49: 278.80982 | F49: 294.50806 | G49: 312.61534 | H49: 333.7323 | I49: 358.67732
B50: =B51+$L$27 -> 0.085163557 | C50: 269.31332 | D50: 283.29277 | E50: 299.26462 | F50: 317.68751 | G50: 339.17254 | H50: 364.55235 | I50: 394.99158
B51: =B52+$L$27 -> 0.080163557 | C51: 287.87242 | D51: 304.12396 | E51: 322.86945 | F51: 344.73071 | G51: 370.55495 | H51: 401.5272 | I51: 439.35725
...

Sheet Ke
B2: Company name | D2: Company ticker
B3: General dynamics corporation | D3: GD
B4: Cost of Equity
B5: (Blue = input, Black = calculation)
B7: S&P 500 data | F7: Source
C8: S&P500 Forward P/E | D8: 20.57 | F8: WSJ
C9: Projected EPS growth rate (g S&P) | D9: 0.122 | E9: Yahoo Finance | F9: CapIQ / Bloomberg | G9: (5 years)
C10: Risk-free rate (Rf) | D10: 0.043 | F10: Market quote
C11: Implied required return on equity (Rs&p500) | D11: =((1+D9)/D8)+D9 -> 0.17654545
C12: Implied equity risk premium (Rm) | D12: =+D11-D10 -> 0.13354545
B15: Beta
B16: General Dynamics
C17: Current Price (P) | D17: 340.71 | F17: Yahoo!Finance
C18: Forward EPS (E) | D18: 16.33 | F18: Yahoo!Finance | J18: Company | K18: D/E Ratio | L18: Tax Rate | M18: Beta | N18: bU = bL / (1+ ((1-t)D/E)) | O18: bL = bu (1+ ((1-t)D/E))
C19: P/E ratio | D19: =D17/D18 -> 20.864054 | J19: LMT | K19: ='Comps no formuals'!G6/'Comps no formuals'!F6 -> 0.14794266 | L19: 0.165 | M19: ='Comps no formuals'!K6 -> 0.21173258 | N19: =M19/(1+((1-L19)*K19)) -> 0.18845263 | O19: =N19*(1+((1-$L$26)*$K$26)) -> 0.20225864
C20: Projected EPS growth rate (g) | D20: 0.105 | F20: LSEG>Estmates>Recommendations & Target Price | G20: (5 years) | J20: RTX | K20: ='Comps no formuals'!G7/'Comps no formuals'!F7 -> 0.140293 | L20: 0.189 | M20: ='Comps no formuals'!K7 -> 0.40948776 | N20: =M20/(1+((1-L20)*K20)) -> 0.36765665 | O20: =N20*(1+((1-$L$26)*$K$26)) -> 0.39459112
C21: Implied required return on equity (Re) | D21: =+((1+D20)/D19)+D20 -> 0.1579619 | J21: NOC | K21: ='Comps no formuals'!G8/'Comps no formuals'!F8 -> 0.15486418 | L21: 0.163 | M21: ='Comps no formuals'!K8 -> 0.02049081 | N21: =M21/(1+((1-L21)*K21)) -> 0.018139539 | O21: =N21*(1+((1-$L$26)*$K$26)) -> 0.019468439
C22: Forward (Bf) | D22: =(D21-D10)/D12 -> 0.86084475 | J22: LHX | K22: ='Comps no formuals'!G9/'Comps no formuals'!F9 -> 0.16363777 | L22: 0.15 | M22: ='Comps no formuals'!K9 -> 0.59925533 | N22: =M22/(1+((1-L22)*K22)) -> 0.52608154 | O22: =N22*(1+((1-$L$26)*$K$26)) -> 0.56462219
C23: Historical (Bh) | D23: 0.37 | F23: Yahoo!Finance | M23: ='Comps no formuals'!K10 -> 0.37863835 | O23: =+AVERAGE(O19:O22) -> 0.2952351
C24: Average Beta | D24: =+(D22+D23)/2 -> 0.61542237
C25: Comperable Beta | D25: =+O23 -> 0.2952351 | F25: Calculation | K25: D/E Ratio | L25: Tax Rate | O25: Relevered
J26: GD | K26: ='Comps no formuals'!G10/'Comps no formuals'!F10 -> 0.08890758 | L26: 0.176 | M26: ='Comps no formuals'!K10 -> 0.37863835 | N26: =M26/(1+((1-L26)*K26)) -> 0.3527928 | O26: =N26*(1+((1-L26)*K26)) -> 0.37863835
B27: Cost of Equity:
C28: Historic equity risk premium | D28: 0.065
C29: Using Forward Beta | D29: =+$D$10+D22*($D$28) -> 0.098954909 | E29: 0.3
C30: Using Historic Beta | D30: =+$D$10+D23*($D$28) -> 0.06705 | E30: 0.4
C31: Comperable Beta | D31: =+$D$10+D25*($D$28) -> 0.062190281 | E31: 0.3
C32: Weighted COE | D32: =+SUMPRODUCT(D29:D31,E29:E31) -> 0.075163557
C34: Market COE (beta = 1) | D34: =+D10+1*D28 -> 0.108

Sheet Revenue model
A1: General Dynamics Corporation
A2: Bottom-Up Revenue Model
A3: (Dollars in millions, except units and per-unit amounts)
A5: Year Ended December 31 | B5: 2021 | C5: 2022 | D5: 2023 | E5: 2024 | F5: 2025 | G5: 2026E | H5: 2027E | I5: 2028E | J5: 2029E | K5: 2030E | L5: 2031E | N5: Projection Assumptions
A7: AEROSPACE | N7: AEROSPACE
A8: Aircraft manufacturing | B8: 5864 | C8: 5876 | D8: 5710 | E8: 7811 | F8: 9413 | G8: =G13*G15 -> 9722.7949 | H8: =H13*H15 -> 10041.216 | I8: =I13*I15 -> 10470.138 | J8: =J13*J15 -> 10915.757 | K8: =K13*K15 -> 11378.69 | L8: =L13*L15 -> 11859.575
A9: Aircraft services | B9: 2271 | C9: 2691 | D9: 2911 | E9: 3438 | F9: 3697 | G9: =F9*(1+G18) -> 3881.85 | H9: =G9*(1+H18) -> 4075.9425 | I9: =H9*(1+I18) -> 4279.7396 | J9: =I9*(1+J18) -> 4493.7266 | K9: =J9*(1+K18) -> 4718.4129 | L9: =K9*(1+L18) -> 4954.3336
A10: Total Aerospace Revenue | B10: =B8+B9 -> 8135 | C10: =C8+C9 -> 8567 | D10: =D8+D9 -> 8621 | E10: =E8+E9 -> 11249 | F10: =F8+F9 -> 13110 | G10: =G8+G9 -> 13604.645 | H10: =H8+H9 -> 14117.159 | I10: =I8+I9 -> 14749.877 | ... L10: =L8+L9 -> 16813.909
A12: Key Drivers:
A13: Gulfstream deliveries (units) | B13: 119 | C13: 120 | D13: 111 | E13: 136 | F13: 158 | G13: =ROUND(F13*(1+G14), 0) -> 160 | H13: =ROUND(G13*(1+H14), 0) -> 162 | I13: =ROUND(H13*(1+I14), 0) -> 164 | J13: =ROUND(I13*(1+J14), 0) -> 166 | K13: =ROUND(J13*(1+K14), 0) -> 168 | L13: =ROUND(K13*(1+L14), 0) -> 170
C14: =C13/B13-1 -> 0.0084033613 | D14: =D13/C13-1 -> -0.075 | E14: =E13/D13-1 -> 0.22522523 | F14: =F13/E13-1 -> 0.16176471 | G14: 0.01 | H14: 0.01 | I14: 0.01 | J14: 0.01 | K14: 0.01 | L14: 0.01 | N14: Gulfstream deliveries: 3% growth in 2026E tapering to 1% by 2030–31E. Supported by strong backlog ($21.8B in 2025) and management guidance for ~158 deliveries in 2025 with continued ramp. Growth decelerates as delivery ramp matures and approaches steady-state production capacity.
A15: Implied ASP per aircraft ($M) | B15: =B8/B13 -> 49.277311 | C15: =C8/C13 -> 48.966667 | D15: =D8/D13 -> 51.441441 | E15: =E8/E13 -> 57.433824 | F15: =F8/F13 -> 59.575949 | G15: =F15*(1+G16) -> 60.767468 | H15: =G15*(1+H16) -> 61.982818 | I15: =H15*(1+I16) -> 63.842302 | J15: =I15*(1+J16) -> 65.757571 | K15: =J15*(1+K16) -> 67.730298 | L15: =K15*(1+L16) -> 69.762207 | N15: ASP per aircraft: 3% annual price escalation in 2026E, stepping up to 4% from 2029E onward. Reflects Gulfstream's historical pricing power (2021–2025 implied ASP CAGR ~4.8%) and premium market positioning. Conservative vs. historical given mix normalization as new models ramp.
C16: =C15/B15-1 -> -0.0063040018 | D16: =D15/C15-1 -> 0.050539989 | E16: =E15/D15-1 -> 0.11648939 | F16: =F15/E15-1 -> 0.037297288 | G16: 0.02 | H16: =G16 -> 0.02 | I16: 0.03 | J16: 0.03 | K16: =J16 -> 0.03 | L16: =K16 -> 0.03
A17: Aircraft mfg. revenue growth | B17: n/a | C17: =C8/B8-1 -> 0.0020463847 | D17: =D8/C8-1 -> -0.028250511 | E17: =E8/D8-1 -> 0.36795096 | F17: =F8/E8-1 -> 0.20509538 | G17: =G8/F8-1 -> 0.032911392 | H17: =H8/G8-1 -> 0.03275 | I17: =I8/H8-1 -> 0.042716049 | J17: =J8/I8-1 -> 0.042560976 | ... L17: =L8/K8-1 -> 0.042261905 | N17: Aircraft mfg. revenue: Derived as deliveries × ASP. No independent assumption — flows from the unit and pricing drivers above.
A18: Aircraft services revenue growth | B18: n/a | C18: =C9/B9-1 -> 0.18494055 | D18: =D9/C9-1 -> 0.081753995 | E18: =E9/D9-1 -> 0.18103744 | F18: =F9/E9-1 -> 0.075334497 | G18: 0.05 | H18: =G18 -> 0.05 | I18: =H18 -> 0.05 | J18: =I18 -> 0.05 | K18: =J18 -> 0.05 | L18: =K18 -> 0.05 | N18: Aircraft services: 5% annual growth throughout projection. Historical growth volatile (8–18%) driven by expanding installed fleet and recurring aftermarket demand. 5% is a moderated steady-state assumption reflecting fleet growth net of cycle normalization.
A19: Operating Earnings | B19: 1031 | C19: 1130 | D19: 1182 | E19: 1464 | F19: 1746 | G19: =G20*G10 -> 1904.6503 | H19: =H20*H10 -> 1976.4023 | I19: =I20*I10 -> 2064.9828 | J19: =J20*J10 -> 2157.3277 | K19: =K20*K10 -> 2253.5944 | L19: =L20*L10 -> 2353.9472 | N19: Aerospace Operating Earnings: Derived from operating margin × total segment revenue.
A20: Operating Margin | B20: =B19/B10 -> 0.12673632 | C20: =C19/C10 -> 0.13190148 | D20: =D19/D10 -> 0.13710706 | E20: =E19/E10 -> 0.1301449 | F20: =F19/F10 -> 0.13318078 | G20: 0.14 | H20: 0.14 | I20: 0.14 | J20: 0.14 | K20: 0.14 | L20: 0.14 | N20: Aerospace Operating Margin: 13.5% in 2026E, rising to 14% by 2028E and held flat thereafter. 2026 management forward guidance is ~14% operating margin. Tapered entry from 13.0% actual in 2024 / 13.3% in 2025 reflects gradual margin expansion as Gulfstream production ramp yields operating leverage. Historical range: 12.7–13.7%.
A22: MARINE SYSTEMS | N22: MARINE SYSTEMS
A23: Nuclear-powered submarines | B23: 7117 | C23: 7310 | D23: 8631 | E23: 10392 | F23: 12608 | G23: =F23*(1+G29) -> 13490.56 | H23: =G23*(1+H29) -> 14434.899 | I23: =H23*(1+I29) -> 15445.342 | J23: =I23*(1+J29) -> 16526.516 | K23: =J23*(1+K29) -> 17683.372 | L23: =K23*(1+L29) -> 18921.208 | N23: Submarine revenue: 10% growth in 2026E, tapering to 5% by 2031E. Driven by Columbia-class SSBN production ramp and Virginia-class Block V orders. Backlog of $52.3B (2025) provides multi-year visibility. Growth decelerates as Columbia production stabilizes.
A24: Surface ships | B24: 2328 | C24: 2561 | D24: 2698 | E24: 2819 | F24: 2932 | G24: =F24*(1+G30) -> 3019.96 | H24: =G24*(1+H30) -> 3110.5588 | I24: =H24*(1+I30) -> 3203.8756 | J24: =I24*(1+J30) -> 3332.0306 | K24: =J24*(1+K30) -> 3465.3118 | L24: =K24*(1+L30) -> 3603.9243 | N24: Surface ships: 4% annual growth held flat. Reflects steady DDG-51 and DDG(X) program contributions. Historical growth volatile (4–10%); 4% is conservative given stable Navy shipbuilding budget expectations.
A25: Repair and other services | B25: 1081 | C25: 1169 | D25: 1132 | E25: 1132 | F25: 1183 | G25: =F25*(1+G32) -> 1206.66 | H25: =G25*(1+H32) -> 1230.7932 | I25: =H25*(1+I32) -> 1255.4091 | J25: =I25*(1+J32) -> 1280.5172 | K25: =J25*(1+K32) -> 1306.1276 | L25: =K25*(1+L32) -> 1332.2501 | N25: Repair & other services: 2% annual growth. Stable recurring maintenance and modernization work on the existing fleet. Historical range volatile (-3% to +8%); 2% reflects normalized sustainment demand.
A26: Total Marine Systems Revenue | B26: =B23+B24+B25 -> 10526 | C26: =C23+C24+C25 -> 11040 | D26: =D23+D24+D25 -> 12461 | E26: =E23+E24+E25 -> 14343 | F26: =F23+F24+F25 -> 16723 | G26: =G23+G24+G25 -> 17717.18 | H26: =H23+H24+H25 -> 18776.251 | I26: =I23+I24+I25 -> 19904.627 | ... L26: =L23+L24+L25 -> 23857.383
A28: Key Drivers:
A29: Submarine revenue growth | B29: n/a | C29: =C23/B23-1 -> 0.027118168 | D29: =D23/C23-1 -> 0.18071135 | E29: =E23/D23-1 -> 0.20403198 | F29: =F23/E23-1 -> 0.21324095 | G29: =CHOOSE(Cover!$I$14,'Revenue model'!G92,'Revenue model'!G93,'Revenue model'!G94) -> 0.07 | H29: =CHOOSE(Cover!$I$14,'Revenue model'!H92,'Revenue model'!H93,'Revenue model'!H94) -> 0.07 | I29: =CHOOSE(Cover!$I$14,'Revenue model'!I92,'Revenue model'!I93,'Revenue model'!I94) -> 0.07 | J29: =CHOOSE(Cover!$I$14,'Revenue model'!J92,'Revenue model'!J93,'Revenue model'!J94) -> 0.07 | K29: =CHOOSE(Cover!$I$14,'Revenue model'!K92,'Revenue model'!K93,'Revenue model'!K94) -> 0.07 | L29: =CHOOSE(Cover!$I$14,'Revenue model'!L92,'Revenue model'!L93,'Revenue model'!L94) -> 0.07 | N29: Marine submarine growth: 10% in 2026E tapering to 5% by 2031E. See row 23 for detail.
A30: Surface ships revenue growth | B30: n/a | C30: =C24/B24-1 -> 0.10008591 | D30: =D24/C24-1 -> 0.053494729 | E30: =E24/D24-1 -> 0.044848036 | F30: =F24/E24-1 -> 0.040085137 | G30: =CHOOSE(Cover!$I$14,'Revenue model'!G96,'Revenue model'!G97,'Revenue model'!G98) -> 0.03 | H30: =CHOOSE(Cover!$I$14,'Revenue model'!H96,'Revenue model'!H97,'Revenue model'!H98) -> 0.03 | I30: =CHOOSE(Cover!$I$14,'Revenue model'!I96,'Revenue model'!I97,'Revenue model'!I98) -> 0.03 | J30: =CHOOSE(Cover!$I$14,'Revenue model'!J96,'Revenue model'!J97,'Revenue model'!J98) -> 0.04 | K30: =CHOOSE(Cover!$I$14,'Revenue model'!K96,'Revenue model'!K97,'Revenue model'!K98) -> 0.04 | L30: =CHOOSE(Cover!$I$14,'Revenue model'!L96,'Revenue model'!L97,'Revenue model'!L98) -> 0.04 | N30: Marine surface ships growth: 4% annual. See row 24 for detail.
A31: Operating Earnings | B31: 874 | C31: 897 | D31: 874 | E31: 935 | F31: 1177 | G31: =G33*G26 -> 1293.3541 | H31: =H33*H26 -> 1370.6663 | I31: =I33*I26 -> 1472.9424 | J31: =J33*J26 -> 1564.2907 | K31: =K33*K26 -> 1684.1109 | L31: =L33*L26 -> 1789.3037 | N31: Marine Operating Earnings: Derived from operating margin × total segment revenue.
A32: Repair and other services growth | C32: =C25/B25-1 -> 0.081406105 | D32: =D25/C25-1 -> -0.031650984 | E32: =E25/D25-1 -> 0 | F32: =F25/E25-1 -> 0.045053004 | G32: 0.02 | H32: 0.02 | I32: 0.02 | J32: 0.02 | K32: 0.02 | L32: 0.02 | N32: Marine repair services growth: 2% annual. See row 25 for detail.
A33: Operating Margin | B33: =B31/B26 -> 0.083032491 | C33: =C31/C26 -> 0.08125 | D33: =D31/D26 -> 0.070138833 | E33: =E31/E26 -> 0.065188594 | F33: =F31/F26 -> 0.070382108 | G33: =CHOOSE(Cover!$I$15,'Revenue model'!G100,'Revenue model'!G101,'Revenue model'!G102) -> 0.073 | H33: =CHOOSE(Cover!$I$15,'Revenue model'!H100,'Revenue model'!H101,'Revenue model'!H102) -> 0.073 | I33: =CHOOSE(Cover!$I$15,'Revenue model'!I100,'Revenue model'!I101,'Revenue model'!I102) -> 0.074 | J33: =CHOOSE(Cover!$I$15,'Revenue model'!J100,'Revenue model'!J101,'Revenue model'!J102) -> 0.074 | K33: =CHOOSE(Cover!$I$15,'Revenue model'!K100,'Revenue model'!K101,'Revenue model'!K102) -> 0.075 | L33: =CHOOSE(Cover!$I$15,'Revenue model'!L100,'Revenue model'!L101,'Revenue model'!L102) -> 0.075 | N33: Marine Operating Margin: 7.3% in 2026E per management guidance (~7.3%), rising modestly to 7.4% in 2028E+. Historically compressed (7.0–8.3%) due to cost-plus contract mix in submarine programs. Limited margin expansion expected given program mix and Navy pricing dynamics.
A35: COMBAT SYSTEMS | N35: COMBAT SYSTEMS
A36: Military vehicles | B36: 4699 | C36: 4581 | D36: 5036 | E36: 5101 | F36: 4970 | G36: =F36*(1+G42) -> 5019.7 | H36: =G36*(1+H42) -> 5120.094 | I36: =H36*(1+I42) -> 5222.4959 | J36: =I36*(1+J42) -> 5326.9458 | K36: =J36*(1+K42) -> 5433.4847 | L36: =K36*(1+L42) -> 5542.1544 | N36: Military vehicles: 2% annual growth. Reflects steady Abrams tank and Stryker vehicle production. Historical growth volatile (-2.5% to +10%); 2% is a conservative steady-state reflecting stable but not accelerating Army procurement budgets.
A37: Weapons systems and munitions | B37: 2006 | C37: 2024 | D37: 2442 | E37: 2932 | F37: 3104 | G37: =F37*(1+G43) -> 3274.72 | H37: =G37*(1+H43) -> 3503.9504 | I37: =H37*(1+I43) -> 3749.2269 | J37: =I37*(1+J43) -> 4011.6728 | K37: =J37*(1+K43) -> 4292.4899 | L37: =K37*(1+L43) -> 4592.9642 | N37: Weapons systems & munitions: 7% annual growth (2027E+). Driven by sustained global ammunition restocking cycle post-Ukraine conflict and elevated allied nation replenishment orders. Multi-year demand cycle supported by historically low inventory levels. 2026E at 5.5% per guidance.
A38: Engineering and other services | B38: 646 | C38: 703 | D38: 790 | E38: 964 | F38: 1172 | G38: =F38*(1+G44) -> 1382.96 | H38: =G38*(1+H44) -> 1590.404 | I38: =H38*(1+I44) -> 1828.9646 | J38: =I38*(1+J44) -> 2103.3093 | K38: =J38*(1+K44) -> 2418.8057 | L38: =K38*(1+L44) -> 2781.6265 | N38: Engineering & other services: 15% annual growth (2027E+). Strong but moderated from 18% to reflect more sustainable long-term trajectory as European programs transition from engineering to production. Supported by Combat Systems book-to-bill of 2.1x and $27.2B backlog. 2026E at 18% per guidance.
A39: Total Combat Systems Revenue | B39: =B36+B37+B38 -> 7351 | C39: =C36+C37+C38 -> 7308 | D39: =D36+D37+D38 -> 8268 | E39: =E36+E37+E38 -> 8997 | F39: =F36+F37+F38 -> 9246 | G39: =G36+G37+G38 -> 9677.38 | H39: =H36+H37+H38 -> 10214.448 | I39: =I36+I37+I38 -> 10800.687 | ... L39: =L36+L37+L38 -> 12916.745
A41: Key Drivers:
A42: Military vehicles revenue growth | B42: n/a | C42: =C36/B36-1 -> -0.025111726 | D42: =D36/C36-1 -> 0.099323292 | E42: =E36/D36-1 -> 0.012907069 | F42: =F36/E36-1 -> -0.025681239 | G42: =CHOOSE(Cover!$I$16,'Revenue model'!G106,'Revenue model'!G107,'Revenue model'!G108) -> 0.01 | H42: =CHOOSE(Cover!$I$16,'Revenue model'!H106,'Revenue model'!H107,'Revenue model'!H108) -> 0.02 | I42: =CHOOSE(Cover!$I$16,'Revenue model'!I106,'Revenue model'!I107,'Revenue model'!I108) -> 0.02 | J42: =CHOOSE(Cover!$I$16,'Revenue model'!J106,'Revenue model'!J107,'Revenue model'!J108) -> 0.02 | K42: =CHOOSE(Cover!$I$16,'Revenue model'!K106,'Revenue model'!K107,'Revenue model'!K108) -> 0.02 | L42: =CHOOSE(Cover!$I$16,'Revenue model'!L106,'Revenue model'!L107,'Revenue model'!L108) -> 0.02
A43: Weapons systems revenue growth | B43: n/a | C43: =C37/B37-1 -> 0.0089730808 | D43: =D37/C37-1 -> 0.20652174 | E43: =E37/D37-1 -> 0.2006552 | F43: =F37/E37-1 -> 0.058663029 | G43: =CHOOSE(Cover!$I$16,'Revenue model'!G110,'Revenue model'!G111,'Revenue model'!G112) -> 0.055 | H43: =CHOOSE(Cover!$I$16,'Revenue model'!H110,'Revenue model'!H111,'Revenue model'!H112) -> 0.07 | I43: =CHOOSE(Cover!$I$16,'Revenue model'!I110,'Revenue model'!I111,'Revenue model'!I112) -> 0.07 | J43: =CHOOSE(Cover!$I$16,'Revenue model'!J110,'Revenue model'!J111,'Revenue model'!J112) -> 0.07 | K43: =CHOOSE(Cover!$I$16,'Revenue model'!K110,'Revenue model'!K111,'Revenue model'!K112) -> 0.07 | L43: =CHOOSE(Cover!$I$16,'Revenue model'!L110,'Revenue model'!L111,'Revenue model'!L112) -> 0.07
A44: Engineering and other services growth | C44: =C38/B38-1 -> 0.088235294 | D44: =D38/C38-1 -> 0.12375533 | E44: =E38/D38-1 -> 0.22025316 | F44: =F38/E38-1 -> 0.21576763 | G44: =CHOOSE(Cover!$I$16,'Revenue model'!G114,'Revenue model'!G115,'Revenue model'!G116) -> 0.18 | H44: =CHOOSE(Cover!$I$16,'Revenue model'!H114,'Revenue model'!H115,'Revenue model'!H116) -> 0.15 | I44: =CHOOSE(Cover!$I$16,'Revenue model'!I114,'Revenue model'!I115,'Revenue model'!I116) -> 0.15 | J44: =CHOOSE(Cover!$I$16,'Revenue model'!J114,'Revenue model'!J115,'Revenue model'!J116) -> 0.15 | K44: =CHOOSE(Cover!$I$16,'Revenue model'!K114,'Revenue model'!K115,'Revenue model'!K116) -> 0.15 | L44: =CHOOSE(Cover!$I$16,'Revenue model'!L114,'Revenue model'!L115,'Revenue model'!L116) -> 0.15
A45: Operating Earnings | B45: 1067 | C45: 1075 | D45: 1147 | E45: 1276 | F45: 1331 | G45: =G46*G39 -> 1364.5106 | H45: =H46*H39 -> 1440.2372 | I45: =I46*I39 -> 1533.6976 | J45: =J46*J39 -> 1624.7538 | K45: =K46*K39 -> 1736.7036 | L45: =L46*L39 -> 1847.0946
A46: Operating Margin | B46: =B45/B39 -> 0.14515032 | C46: =C45/C39 -> 0.14709907 | D46: =D45/D39 -> 0.13872762 | E46: =E45/E39 -> 0.14182505 | F46: =F45/F39 -> 0.14395414 | G46: =CHOOSE(Cover!$I$17,'Revenue model'!G118,'Revenue model'!G119,'Revenue model'!G120) -> 0.141 | H46: =CHOOSE(Cover!$I$17,'Revenue model'!H118,'Revenue model'!H119,'Revenue model'!H120) -> 0.141 | I46: =CHOOSE(Cover!$I$17,'Revenue model'!I118,'Revenue model'!I119,'Revenue model'!I120) -> 0.142 | J46: =CHOOSE(Cover!$I$17,'Revenue model'!J118,'Revenue model'!J119,'Revenue model'!J120) -> 0.142 | K46: =CHOOSE(Cover!$I$17,'Revenue model'!K118,'Revenue model'!K119,'Revenue model'!K120) -> 0.143 | L46: =CHOOSE(Cover!$I$17,'Revenue model'!L118,'Revenue model'!L119,'Revenue model'!L120) -> 0.143 | N46: Combat Operating Margin: 14.1% in 2026E per management guidance (~14.1%), rising to 14.2–14.3% by 2028–30E. Reflects strong mix shift toward higher-margin munitions and engineering services. Historical range: 13.9–14.8%. Modest expansion assumed as higher-margin revenue lines grow faster.
A48: TECHNOLOGIES | N48: TECHNOLOGIES
...

Sheet Income statement
A1: General Dynamics Corporation
A2: Consolidated Statement of Earnings
A3: (Dollars in millions, except per-share amounts)
A5: Year Ended December 31 | B5: 2021 | C5: 2022 | D5: 2023 | E5: 2024 | F5: 2025 | G5: 2026 | H5: 2027 | I5: 2028 | J5: 2029 | K5: 2030 | L5: 2031 | N5: Projection Assumptions
A6: Revenue:
A7: Products | B7: 22428 | C7: 23022 | D7: 24595 | E7: 28635 | F7: 33021 | G7: ='Revenue model'!G8+'Revenue model'!G23+'Revenue model'!G24+'Revenue model'!G36+'Revenue model'!G37 -> 34527.735 | H7: ='Revenue model'!H8+'Revenue model'!H23+'Revenue model'!H24+'Revenue model'!H36+'Revenue model'!H37 -> 36210.719 | I7: ='Revenue model'!I8+'Revenue model'!I23+'Revenue model'!I24+'Revenue model'!I36+'Revenue model'!I37 -> 38091.078 | J7: ='Revenue model'!J8+'Revenue model'!J23+'Revenue model'!J24+'Revenue model'!J36+'Revenue model'!J37 -> 40112.922 | K7: ='Revenue model'!K8+'Revenue model'!K23+'Revenue model'!K24+'Revenue model'!K36+'Revenue model'!K37 -> 42253.349 | L7: ='Revenue model'!L8+'Revenue model'!L23+'Revenue model'!L24+'Revenue model'!L36+'Revenue model'!L37 -> 44519.826 | N7: Product revenue: Linked from Revenue model. Sum of aircraft mfg, submarine, surface ships, military vehicles, and weapons systems revenue across all four segments.
A8: Services | B8: 16041 | C8: 16385 | D8: 17677 | E8: 19081 | F8: 19529 | G8: ='Revenue model'!G9+'Revenue model'!G25+'Revenue model'!G38+'Revenue model'!G49+'Revenue model'!G50 -> 20294.548 | H8: ='Revenue model'!H9+'Revenue model'!H25+'Revenue model'!H38+'Revenue model'!H49+'Revenue model'!H50 -> 21083.207 | I8: ='Revenue model'!I9+'Revenue model'!I25+'Revenue model'!I38+'Revenue model'!I49+'Revenue model'!I50 -> 21924.442 | J8: ='Revenue model'!J9+'Revenue model'!J25+'Revenue model'!J38+'Revenue model'!J49+'Revenue model'!J50 -> 22823.787 | K8: ='Revenue model'!K9+'Revenue model'!K25+'Revenue model'!K38+'Revenue model'!K49+'Revenue model'!K50 -> 23787.514 | L8: ='Revenue model'!L9+'Revenue model'!L25+'Revenue model'!L38+'Revenue model'!L49+'Revenue model'!L50 -> 24822.74 | N8: Service revenue: Linked from Revenue model. Sum of aircraft services, marine repair, combat engineering, IT services, and C5ISR across all four segments.
A9: Total Revenue | B9: =B7+B8 -> 38469 | C9: =C7+C8 -> 39407 | D9: =D7+D8 -> 42272 | E9: =E7+E8 -> 47716 | F9: =F7+F8 -> 52550 | G9: =G7+G8 -> 54822.283 | H9: =H7+H8 -> 57293.926 | I9: =I7+I8 -> 60015.52 | ... L9: =L7+L8 -> 69342.567
A11: Operating costs and expenses:
A12: Products | B12: -18524 | C12: -18981 | D12: -20591 | E12: -24332 | F12: -27965 | G12: =G7*($F$12/$F$7) -> -29241.032 | H12: =H7*($F$12/$F$7) -> -30666.326 | I12: =I7*($F$12/$F$7) -> -32258.775 | J12: =J7*($F$12/$F$7) -> -33971.045 | K12: =K7*($F$12/$F$7) -> -35783.741 | L12: =L7*($F$12/$F$7) -> -37703.187 | N12: Product COGS: Allocated as a share of total OpEx (excl. G&A) using the 2025 actual product-to-service COGS split ratio (~62.8%/37.2%). Assumes product vs. service cost mix remains stable. Historically stable at 48–53% of revenue.
A13: Services | B13: -13537 | C13: -13804 | D13: -15009 | E13: -16020 | F13: -16634 | G13: =G8*($F$13/$F$8) -> -17286.062 | H13: =H8*($F$13/$F$8) -> -17957.81 | I13: =I8*($F$13/$F$8) -> -18674.339 | J13: =J8*($F$13/$F$8) -> -19440.364 | K13: =K8*($F$13/$F$8) -> -20261.227 | L13: =L8*($F$13/$F$8) -> -21142.99 | N13: Service COGS: Remainder of total OpEx (excl. G&A) after product COGS allocation. Same split methodology as products. Historically stable at 31–35% of revenue.
A14: General and administrative (G&A) | B14: -2245 | C14: -2411 | D14: -2427 | E14: -2568 | F14: -2595 | G14: =G9*($F$14/$F$9) -> -2707.2088 | H14: =H9*($F$14/$F$9) -> -2829.2624 | I14: =I9*($F$14/$F$9) -> -2963.6589 | J14: =J9*($F$14/$F$9) -> -3107.9117 | K14: =K9*($F$14/$F$9) -> -3261.1996 | L14: =L9*($F$14/$F$9) -> -3424.2428 | N14: G&A expense: Projected as a % of revenue using the 2025 actual G&A-to-revenue ratio (~4.9%), rounded. Historical range: 4.9–5.8% of revenue. Declining trend reflects operating leverage as revenue scales faster than corporate overhead.
A15: Total Operating Costs and Expenses | B15: =B12+B13+B14 -> -34306 | C15: =C12+C13+C14 -> -35196 | D15: =D12+D13+D14 -> -38027 | E15: =E12+E13+E14 -> -42920 | F15: =F12+F13+F14 -> -47194 | G15: =G17-G9 -> -49148.045 | H15: =H17-H9 -> -51361.502 | I15: =I17-I9 -> -53749.786 | J15: =J17-J9 -> -56360.337 | K15: =K17-K9 -> -59084.102 | L15: =L17-L9 -> -62031.295
A17: Operating Earnings | B17: =B9+B15 -> 4163 | C17: =C9+C15 -> 4211 | D17: =D9+D15 -> 4245 | E17: =E9+E15 -> 4796 | F17: =F9+F15 -> 5356 | G17: ='Revenue model'!G74 -> 5674.2382 | H17: ='Revenue model'!H74 -> 5932.424 | I17: ='Revenue model'!I74 -> 6265.7333 | J17: ='Revenue model'!J74 -> 6576.3719 | K17: ='Revenue model'!K74 -> 6956.7607 | L17: ='Revenue model'!L74 -> 7311.2713
A19: Other, net | B19: 134 | C19: 189 | D19: 82 | E19: 68 | F19: 61 | G19: 50 | H19: 50 | I19: 50 | J19: 50 | K19: 50 | L19: 50 | N19: Other, net: Flat at $50M for all projection years. Historical range volatile ($61–$189M) including gains/losses on investments and other non-operating items. $50M is a conservative normalized estimate below the 2021–2025 average of ~$97M.
A20: Interest, net | B20: -424 | C20: -364 | D20: -343 | E20: -324 | F20: -314 | G20: =-(Schedules!G95) -> -339.20223 | H20: =-(Schedules!H95) -> -370.28125 | I20: =-(Schedules!I95) -> -411.705 | J20: =-(Schedules!J95) -> -454.12375 | K20: =-(Schedules!K95) -> -497.975 | L20: =-(Schedules!L95) -> -516.85 | N20: Interest expense, net: Linked from Schedules debt schedule. Calculated as weighted-average interest rate × average total debt balance. Rate held at ~4.1–4.25% reflecting blended coupon on existing fixed-rate notes plus new issuances.
A22: Earnings Before Income Tax | B22: =B17+B19+B20 -> 3873 | C22: =C17+C19+C20 -> 4036 | D22: =D17+D19+D20 -> 3984 | E22: =E17+E19+E20 -> 4540 | F22: =F17+F19+F20 -> 5103 | G22: =G17+G19+G20 -> 5385.036 | H22: =H17+H19+H20 -> 5612.1428 | I22: =I17+I19+I20 -> 5904.0283 | ... L22: =L17+L19+L20 -> 6844.4213
A24: Provision for income tax, net | B24: -616 | C24: -646 | D24: -669 | E24: -758 | F24: -893 | G24: =G22*G30 -> -942.35491 | H24: =H22*H30 -> -982.09749 | I24: =I22*I30 -> -1033.176 | J24: =J22*J30 -> -1080.1132 | K24: =K22*K30 -> -1139.0056 | L24: =L22*L30 -> -1197.7402 | N24: Income tax provision: Projected using 2025 effective tax rate (~17.5%) held constant. Historical range: 15.9–17.5%. The 2025 rate is used as the best current estimate; no significant tax law changes assumed. Applied as EBT × (tax provision / EBT from 2025).
A26: Net Earnings | B26: =B22+B24 -> 3257 | C26: =C22+C24 -> 3390 | D26: =D22+D24 -> 3315 | E26: =E22+E24 -> 3782 | F26: =F22+F24 -> 4210 | G26: =G22+G24 -> 4442.681 | H26: =H22+H24 -> 4630.0453 | I26: =I22+I24 -> 4870.8523 | ... L26: =L22+L24 -> 5646.6811
A28: Key Margins
A29: Operating Margin | B29: =B17/B9 -> 0.10821701 | C29: =C17/C9 -> 0.10685919 | D29: =D17/D9 -> 0.10042108 | E29: =E17/E9 -> 0.10051136 | F29: =F17/F9 -> 0.10192198 | G29: =G17/G9 -> 0.10350241 | H29: =H17/H9 -> 0.10354368 | I29: =I17/I9 -> 0.10440188 | ... L29: =L17/L9 -> 0.10543699
A30: Effective Tax Rate | B30: =B24/B22 -> -0.15904983 | C30: =C24/C22 -> -0.16005946 | D30: =D24/D22 -> -0.16792169 | E30: =E24/E22 -> -0.16696035 | F30: =F24/F22 -> -0.1749951 | G30: =F30 -> -0.1749951 | H30: =G30 -> -0.1749951 | I30: =H30 -> -0.1749951 | J30: =I30 -> -0.1749951 | K30: =J30 -> -0.1749951 | L30: =K30 -> -0.1749951
A31: Net Margin | B31: =B26/B9 -> 0.084665575 | C31: =C26/C9 -> 0.086025325 | D31: =D26/D9 -> 0.078420704 | E31: =E26/E9 -> 0.079260625 | F31: =F26/F9 -> 0.080114177 | G31: =G26/G9 -> 0.08103787 | H31: =H26/H9 -> 0.080812149 | I31: =I26/I9 -> 0.081159879 | ... L31: =L26/L9 -> 0.081431672
A36: Common size statement | B36: 2021 | C36: 2022 | D36: 2023 | E36: 2024 | F36: 2025 | G36: 2026 | H36: 2027 | I36: 2028 | J36: 2029 | K36: 2030 | L36: 2031
A37: Revenue:
A38: Products | B38: =B7/B9 -> 0.5830149 | C38: =C7/C9 -> 0.58421093 | D38: =D7/D9 -> 0.58182721 | E38: =E7/E9 -> 0.60011317 | F38: =F7/F9 -> 0.62837298 | G38: =G7/G9 -> 0.62981206 | H38: =H7/H9 -> 0.63201672 | I38: =I7/I9 -> 0.63468713 | ... L38: =L7/L9 -> 0.64202738
A39: Services | B39: =B8/B9 -> 0.4169851 | C39: =C8/C9 -> 0.41578907 | D39: =D8/D9 -> 0.41817279 | E39: =E8/E9 -> 0.39988683 | F39: =F8/F9 -> 0.37162702 | G39: =G8/G9 -> 0.37018794 | H39: =H8/H9 -> 0.36798328 | I39: =I8/I9 -> 0.36531287 | ... L39: =L8/L9 -> 0.35797262
A40: Total Revenue | B40: =B9/B9 -> 1 | C40: =C9/C9 -> 1 | D40: =D9/D9 -> 1 | E40: =E9/E9 -> 1 | F40: =F9/F9 -> 1 | G40: =G9/G9 -> 1 | H40: =H9/H9 -> 1 | I40: =I9/I9 -> 1 | ... L40: =L9/L9 -> 1
A42: Operating costs and expenses:
A43: Products | B43: =B12/B7 -> -0.82593187 | C43: =C12/C7 -> -0.82447224 | D43: =D12/D7 -> -0.83720268 | E43: =E12/E7 -> -0.84972935 | F43: =F12/F7 -> -0.84688532 | G43: =G12/G7 -> -0.84688532 | H43: =H12/H7 -> -0.84688532 | I43: =I12/I7 -> -0.84688532 | ... L43: =L12/L7 -> -0.84688532
A44: Services | B44: =B13/B8 -> -0.84390001 | C44: =C13/C8 -> -0.84247788 | D44: =D13/D8 -> -0.84906941 | E44: =E13/E8 -> -0.83957864 | F44: =F13/F8 -> -0.85175892 | G44: =G13/G8 -> -0.85175892 | H44: =H13/H8 -> -0.85175892 | I44: =I13/I8 -> -0.85175892 | ... L44: =L13/L8 -> -0.85175892
A45: General and administrative (G&A) | B45: =B14/B9 -> -0.058358678 | C45: =C14/C9 -> -0.061182023 | D45: =D14/D9 -> -0.057413891 | E45: =E14/E9 -> -0.053818426 | F45: =F14/F9 -> -0.049381541 | G45: =G14/G9 -> -0.049381541 | H45: =H14/H9 -> -0.049381541 | I45: =I14/I9 -> -0.049381541 | ... L45: =L14/L9 -> -0.049381541
A46: Total Operating Costs and Expenses | B46: =B15/B9 -> -0.89178299 | C46: =C15/C9 -> -0.89314081 | D46: =D15/D9 -> -0.89957892 | E46: =E15/E9 -> -0.89948864 | F46: =F15/F9 -> -0.89807802 | G46: =G15/G9 -> -0.89649759 | H46: =H15/H9 -> -0.89645632 | I46: =I15/I9 -> -0.89559812 | ... L46: =L15/L9 -> -0.89456301
A48: Operating Earnings | B48: =B17/B9 -> 0.10821701 | C48: =C17/C9 -> 0.10685919 | D48: =D17/D9 -> 0.10042108 | E48: =E17/E9 -> 0.10051136 | F48: =F17/F9 -> 0.10192198 | G48: =G17/G9 -> 0.10350241 | H48: =H17/H9 -> 0.10354368 | I48: =I17/I9 -> 0.10440188 | ... L48: =L17/L9 -> 0.10543699
A50: Other, net | B50: =B19/B9 -> 0.0034833242 | C50: =C19/C9 -> 0.0047961022 | D50: =D19/D9 -> 0.0019398183 | E50: =E19/E9 -> 0.0014250985 | F50: =F19/F9 -> 0.0011607992 | G50: =G19/G9 -> 0.0009120379 | H50: =H19/H9 -> 0.00087269286 | I50: =I19/I9 -> 0.00083311784 | ... L50: =L19/L9 -> 0.00072105782
A51: Interest, net | B51: =B20/B9 -> -0.011021862 | C51: =C20/C9 -> -0.0092369376 | D51: =D20/D9 -> -0.0081141181 | E51: =E20/E9 -> -0.0067901752 | F51: =F20/F9 -> -0.0059752617 | G51: =G20/G9 -> -0.0061873057 | H51: =H20/H9 -> -0.0064628361 | I51: =I20/I9 -> -0.0068599756 | ... L51: =L20/L9 -> -0.0074535747
A53: Earnings Before Income Tax | B53: =B22/B9 -> 0.10067847 | C53: =C22/C9 -> 0.10241835 | D53: =D22/D9 -> 0.094246783 | E53: =E22/E9 -> 0.095146282 | F53: =F22/F9 -> 0.097107517 | G53: =G22/G9 -> 0.098227138 | H53: =H22/H9 -> 0.097953538 | I53: =I22/I9 -> 0.098375026 | ... L53: =L22/L9 -> 0.09870447
A55: Provision for income tax, net | B55: =B24/B9 -> -0.016012893 | C55: =C24/C9 -> -0.016393027 | D55: =D24/D9 -> -0.015826079 | E55: =E24/E9 -> -0.015885657 | F55: =F24/F9 -> -0.01699334 | G55: =G24/G9 -> -0.017189268 | H55: =H24/H9 -> -0.017141389 | I55: =I24/I9 -> -0.017215148 | ... L55: =L24/L9 -> -0.017272799
A57: Net Earnings | B57: =B26/B9 -> 0.084665575 | C57: =C26/C9 -> 0.086025325 | D57: =D26/D9 -> 0.078420704 | E57: =E26/E9 -> 0.079260625 | F57: =F26/F9 -> 0.080114177 | G57: =G26/G9 -> 0.08103787 | H57: =H26/H9 -> 0.080812149 | I57: =I26/I9 -> 0.081159879 | ... L57: =L26/L9 -> 0.081431672

Sheet Balance sheet
A1: General Dynamics Corporation
A2: Consolidated Balance Sheet
A3: (Dollars in millions)
A5: 46387 | B5: 2021 | C5: 2022 | D5: 2023 | E5: 2024 | F5: 2025 | G5: 2026 | H5: 2027 | I5: 2028 | J5: 2029 | K5: 2030 | L5: 2031 | N5: Projection Assumptions
A6: ASSETS
A7: Current assets:
A8: Cash and equivalents | B8: 1603 | C8: 1242 | D8: 1913 | E8: 1697 | F8: 2333 | G8: ='Cash flow'!G56 -> 2844.2744 | H8: ='Cash flow'!H56 -> 3601.6706 | I8: ='Cash flow'!I56 -> 4561.0231 | J8: ='Cash flow'!J56 -> 5725.1223 | K8: ='Cash flow'!K56 -> 7167.2798 | L8: ='Cash flow'!L56 -> 8521.6069
A9: Accounts receivable | B9: 3041 | C9: 3008 | D9: 3004 | E9: 2977 | F9: 2406 | G9: =Schedules!G116 -> 2553.3666 | H9: =Schedules!H116 -> 2668.4842 | I9: =Schedules!I116 -> 2795.2434 | J9: =Schedules!J116 -> 2931.2988 | K9: =Schedules!K116 -> 3075.8758 | L9: =Schedules!L116 -> 3229.6538 | N9: Accounts receivable: Projected using DSO of 17 days (held flat). Historical DSO ranged 17–29 days; 17 days matches 2025 actual and reflects GD’s efficient collections on government contracts with predictable payment cycles.
A10: Unbilled receivables | B10: 8498 | C10: 8795 | D10: 7997 | E10: 8248 | F10: 8380 | G10: =G59*'Income statement'!G9 -> 8771.5653 | H10: =H59*'Income statement'!H9 -> 9167.0281 | I10: =I59*'Income statement'!I9 -> 9602.4831 | J10: =J59*'Income statement'!J9 -> 10069.873 | K10: =K59*'Income statement'!K9 -> 10566.538 | L10: =L59*'Income statement'!L9 -> 11094.811 | N10: Unbilled receivables: Projected at 16% of revenue (held flat). Historical range: 16–22% of revenue. 2025 actual of 15.9% used as baseline. Reflects contract revenue recognition timing on long-duration defense programs.
A11: Inventories | B11: 5340 | C11: 6322 | D11: 8578 | E11: 9724 | F11: 9232 | G11: =Schedules!G117 -> 9560.3618 | H11: =Schedules!H117 -> 9991.2608 | I11: =Schedules!I117 -> 10465.708 | J11: =Schedules!J117 -> 10974.947 | K11: =Schedules!K117 -> 11516.089 | L11: =Schedules!L117 -> 12091.68 | N11: Inventories: Projected using DSI of 75 days (held flat). Historical DSI ranged 61–88 days; 75 days reflects 2025 actual and normalized inventory levels after the 2023–2024 Gulfstream production ramp build-up.
A12: Other current assets | B12: 1505 | C12: 1696 | D12: 2123 | E12: 1740 | F12: 1897 | G12: =G61*'Income statement'!G9 -> 2192.8913 | H12: =H61*'Income statement'!H9 -> 2291.757 | I12: =I61*'Income statement'!I9 -> 2400.6208 | J12: =J61*'Income statement'!J9 -> 2517.4683 | K12: =K61*'Income statement'!K9 -> 2641.6345 | L12: =L61*'Income statement'!L9 -> 2773.7027 | N12: Other current assets: Projected at 4.0% of revenue (held flat). Historical range: 3.6–5.0%. Stable relationship to revenue; includes prepaid expenses and other miscellaneous current items.
A13: Total current assets | B13: =SUM(B8:B12) -> 19987 | C13: =SUM(C8:C12) -> 21063 | D13: =SUM(D8:D12) -> 23615 | E13: =SUM(E8:E12) -> 24386 | F13: =SUM(F8:F12) -> 24248 | G13: =SUM(G8:G12) -> 25922.459 | H13: =SUM(H8:H12) -> 27720.201 | I13: =SUM(I8:I12) -> 29825.079 | ... L13: =SUM(L8:L12) -> 37711.454
A15: Noncurrent assets:
A16: Property, plant and equipment, net | B16: 5417 | C16: 5900 | D16: 6198 | E16: 6467 | F16: 7525 | G16: =Schedules!G50 -> 8880 | H16: =Schedules!H50 -> 10065 | I16: =Schedules!I50 -> 10960 | J16: =Schedules!J50 -> 11552 | K16: =Schedules!K50 -> 11827 | L16: =Schedules!L50 -> 12107 | N16: PP&E, net: Linked from Schedules PP&E schedule. Driven by CapEx at 2.2% of revenue and D&A at 4.5% of average gross PP&E. See Schedules sheet for detailed rollforward.
A17: Intangible assets, net | B17: 1978 | C17: 1824 | D17: 1656 | E17: 1520 | F17: 1375 | G17: =F17+G66 -> 1225 | H17: =G17+H66 -> 1075 | I17: =H17+I66 -> 925 | J17: =I17+J66 -> 775 | K17: =J17+K66 -> 625 | L17: =K17+L66 -> 475 | N17: Intangible assets, net: Annual amortization of -$150M (held flat). Historical annual decline ranged -$136M to -$168M. Reflects steady amortization of acquired intangibles from CSRA acquisition with no significant new acquisitions assumed.
A18: Goodwill | B18: 20098 | C18: 20334 | D18: 20586 | E18: 20556 | F18: 21009 | G18: 21009 | H18: 21009 | I18: 21009 | J18: 21009 | K18: 21009 | L18: 21009 | N18: Goodwill: Held flat at $21,009M (2025 level). No impairments or acquisitions assumed. Goodwill primarily from 2018 CSRA acquisition ($9.7B) and historical deals. Would only change with M&A activity.
A19: Other assets | B19: 2593 | C19: 2464 | D19: 2755 | E19: 2951 | F19: 3092 | G19: ='Income statement'!G9*'Balance sheet'!G68 -> 3462.4584 | H19: ='Income statement'!H9*'Balance sheet'!H68 -> 3618.5621 | I19: ='Income statement'!I9*'Balance sheet'!I68 -> 3790.4522 | J19: ='Income statement'!J9*'Balance sheet'!J68 -> 3974.9483 | K19: ='Income statement'!K9*'Balance sheet'!K68 -> 4171 | L19: ='Income statement'!L9*'Balance sheet'!L68 -> 4379.5286 | N19: Other noncurrent assets: Held flat at $3,092M (2025 level). Includes operating lease ROU assets, deferred tax assets, and other long-term items. Stable historical trajectory with no specific growth driver identified.
A20: Total noncurrent assets | B20: =SUM(B16:B19) -> 30086 | C20: =SUM(C16:C19) -> 30522 | D20: =SUM(D16:D19) -> 31195 | E20: =SUM(E16:E19) -> 31494 | F20: =SUM(F16:F19) -> 33001 | G20: =SUM(G16:G19) -> 34576.458 | H20: =SUM(H16:H19) -> 35767.562 | I20: =SUM(I16:I19) -> 36684.452 | ... L20: =SUM(L16:L19) -> 37970.529
A22: Total assets | B22: =B13+B20 -> 50073 | C22: =C13+C20 -> 51585 | D22: =D13+D20 -> 54810 | E22: =E13+E20 -> 55880 | F22: =F13+F20 -> 57249 | G22: =G13+G20 -> 60498.918 | H22: =H13+H20 -> 63487.763 | I22: =I13+I20 -> 66509.531 | ... L22: =L13+L20 -> 75681.983
A24: LIABILITIES AND SHAREHOLDERS' EQUITY
A25: Current liabilities:
A26: Short-term debt and current portion of long-term debt | B26: 1005 | C26: 1253 | D26: 507 | E26: 1502 | F26: 1006 | G26: =Schedules!G88 -> 1257 | H26: =Schedules!H88 -> 1007 | I26: =Schedules!I88 -> 7 | J26: =Schedules!J88 -> 1007 | K26: =Schedules!K88 -> 500 | L26: =Schedules!L88 -> 0 | N26: Short-term debt: Current portion of LTD from debt maturity schedule. Equals notes maturing within 12 months per 2025 10-K Note K debt maturity detail. Linked from Schedules debt schedule.
A27: Accounts payable | B27: 3167 | C27: 3398 | D27: 3095 | E27: 3344 | F27: 2678 | G27: =Schedules!G118 -> 2804.3728 | H27: =Schedules!H118 -> 2930.7698 | I27: =Schedules!I118 -> 3069.9411 | J27: =Schedules!J118 -> 3219.3178 | K27: =Schedules!K118 -> 3378.0529 | L27: =Schedules!L118 -> 3546.8929 | N27: Accounts payable: Projected using DPO of 22 days (held flat). Historical DPO ranged 22–38 days; 22 days matches 2025 actual. Reflects GD’s disciplined payables management and shorter payment cycles typical of defense primes.
A28: Customer advances and deposits | B28: 6266 | C28: 7436 | D28: 9564 | E28: 9491 | F28: 9824 | G28: =G77*'Income statement'!G9 -> 10566.257 | H28: =H77*'Income statement'!H9 -> 11042.633 | I28: =I77*'Income statement'!I9 -> 11567.183 | J28: =J77*'Income statement'!J9 -> 12130.203 | K28: =K77*'Income statement'!K9 -> 12728.487 | L28: =L77*'Income statement'!L9 -> 13364.846 | N28: Customer advances & deposits: Projected at ~19.3% of revenue (5-yr historical average). Historical range: 16.3–22.6%. Reflects advance payments received on large defense contracts, particularly submarines and combat vehicles. Averaged to smooth volatility.
A29: Other current liabilities | B29: 3540 | C29: 3254 | D29: 3266 | E29: 3487 | F29: 3288 | G29: =G78*'Income statement'!G9 -> 3289.337 | H29: =H78*'Income statement'!H9 -> 3437.6356 | I29: =I78*'Income statement'!I9 -> 3600.9312 | J29: =J78*'Income statement'!J9 -> 3776.2025 | K29: =K78*'Income statement'!K9 -> 3962.4518 | L29: =L78*'Income statement'!L9 -> 4160.554 | N29: Other current liabilities: Projected at 6.0% of revenue (held flat). Historical range: 6.3–9.2%; 6.0% is slightly below historical average reflecting normalization of accrued compensation and other current obligations.
A30: Total current liabilities | B30: =SUM(B26:B29) -> 13978 | C30: =SUM(C26:C29) -> 15341 | D30: =SUM(D26:D29) -> 16432 | E30: =SUM(E26:E29) -> 17824 | F30: =SUM(F26:F29) -> 16796 | G30: =SUM(G26:G29) -> 17916.967 | H30: =SUM(H26:H29) -> 18418.038 | I30: =SUM(I26:I29) -> 18245.056 | ... L30: =SUM(L26:L29) -> 21072.293
A32: Noncurrent liabilities:
A33: Long-term debt | B33: 10490 | C33: 9243 | D33: 8754 | E33: 7260 | F33: 7007 | G33: =Schedules!G89 -> 7231 | H33: =Schedules!H89 -> 7930 | I33: =Schedules!I89 -> 9354 | J33: =Schedules!J89 -> 8753 | K33: =Schedules!K89 -> 9659 | L33: =Schedules!L89 -> 10515 | N33: Long-term debt: Linked from Schedules debt schedule. Reflects total debt book value less current portion. New issuances of $1,650M/yr in 2026–28E and $1,000–1,600M/yr thereafter to maintain target D/V ratio of ~24%.
A34: Other liabilities | B34: 7964 | C34: 8433 | D34: 8325 | E34: 8733 | F34: 7824 | G34: ='Income statement'!G9*'Balance sheet'!G83 -> 8223.3424 | H34: ='Income statement'!H9*'Balance sheet'!H83 -> 8594.0889 | I34: ='Income statement'!I9*'Balance sheet'!I83 -> 9002.3279 | J34: ='Income statement'!J9*'Balance sheet'!J83 -> 9440.5063 | K34: ='Income statement'!K9*'Balance sheet'!K83 -> 9906.1294 | L34: ='Income statement'!L9*'Balance sheet'!L83 -> 10401.385 | N34: Other noncurrent liabilities: Held flat at $7,824M (2025 level). Includes pension obligations, deferred revenue (noncurrent), and other long-term liabilities. Pension obligations expected to remain stable given GD’s funded status.
A35: Total noncurrent liabilities | B35: =SUM(B33:B34) -> 18454 | C35: =SUM(C33:C34) -> 17676 | D35: =SUM(D33:D34) -> 17079 | E35: =SUM(E33:E34) -> 15993 | F35: =SUM(F33:F34) -> 14831 | G35: =SUM(G33:G34) -> 15454.342 | H35: =SUM(H33:H34) -> 16524.089 | I35: =SUM(I33:I34) -> 18356.328 | ... L35: =SUM(L33:L34) -> 20916.385
A37: Total liabilities | B37: =B30+B35 -> 32432 | C37: =C30+C35 -> 33017 | D37: =D30+D35 -> 33511 | E37: =E30+E35 -> 33817 | F37: =F30+F35 -> 31627 | G37: =G30+G35 -> 33371.309 | H37: =H30+H35 -> 34942.127 | I37: =I30+I35 -> 36601.384 | ... L37: =L30+L35 -> 41988.678
A39: Shareholders' equity:
A40: Common stock | B40: 482 | C40: 482 | D40: 482 | E40: 482 | F40: 482 | G40: =Equity!G45 -> 482 | H40: =Equity!H45 -> 482 | I40: =Equity!I45 -> 482 | J40: =Equity!J45 -> 482 | K40: =Equity!K45 -> 482 | L40: =Equity!L45 -> 482 | N40: Common stock: Held flat at $482M. Par value of common shares; does not change with repurchases.
A41: Surplus | B41: 3278 | C41: 3556 | D41: 3760 | E41: 4062 | F41: 4403 | G41: =Equity!G32 -> 4743 | H41: =Equity!H32 -> 5083 | I41: =Equity!I32 -> 5423 | J41: =Equity!J32 -> 5763 | K41: =Equity!K32 -> 6103 | L41: =Equity!L32 -> 6443 | N41: Surplus (APIC): Grows by $340M/yr reflecting annual stock-based compensation expense. Historical SBC ranged $204–$341M; $340M is consistent with recent trend and reflects ongoing equity compensation programs.
A42: Retained earnings | B42: 35420 | C42: 37403 | D42: 39270 | E42: 41487 | F42: 44080 | G42: =Equity!G13 -> 46745.609 | H42: =Equity!H13 -> 49523.636 | I42: =Equity!I13 -> 52446.147 | J42: =Equity!J13 -> 55501.428 | K42: =Equity!K13 -> 58723.296 | L42: =Equity!L13 -> 62111.305 | N42: Retained earnings: Beginning balance + net earnings – dividends. Dividends grow 5% annually from 2025 base ($1,617M), reflecting GD’s consistent dividend growth track record (increased for 27+ consecutive years).
A43: Treasury stock | B43: -19619 | C43: -20721 | D43: -21054 | E43: -22450 | F43: -22860 | G43: =Equity!G22 -> -24360 | H43: =Equity!H22 -> -26060 | I43: =Equity!I22 -> -27960 | J43: =Equity!J22 -> -30060 | K43: =Equity!K22 -> -32360 | L43: =Equity!L22 -> -34860 | N43: Treasury stock: $1,500M annual share repurchases assumed. Historical buybacks volatile ($333M–$1,856M); $1,500M reflects management’s stated commitment to returning capital via repurchases. Share count declines ~1.7% annually at projected prices.
A44: Accumulated other comprehensive loss | B44: -1920 | C44: -2152 | D44: -1159 | E44: -1518 | F44: -483 | G44: =Equity!G41 -> -483 | H44: =Equity!H41 -> -483 | I44: =Equity!I41 -> -483 | J44: =Equity!J41 -> -483 | K44: =Equity!K41 -> -483 | L44: =Equity!L41 -> -483 | N44: AOCI: Gradual recovery toward zero. +$100M/yr in 2026–28E, then +$50M/yr. Reflects expected improvement in pension-related AOCI as interest rates normalize and pension funded status improves. Historical swings large ($+1,035M to -$359M).
A45: Total shareholders' equity | B45: =SUM(B40:B44) -> 17641 | C45: =SUM(C40:C44) -> 18568 | D45: =SUM(D40:D44) -> 21299 | E45: =SUM(E40:E44) -> 22063 | F45: =SUM(F40:F44) -> 25622 | G45: =SUM(G40:G44) -> 27127.609 | H45: =SUM(H40:H44) -> 28545.636 | I45: =SUM(I40:I44) -> 29908.147 | ... L45: =SUM(L40:L44) -> 33693.305
A47: Total liabilities and shareholders' equity | B47: =B37+B45 -> 50073 | C47: =C37+C45 -> 51585 | D47: =D37+D45 -> 54810 | E47: =E37+E45 -> 55880 | F47: =F37+F45 -> 57249 | G47: =G37+G45 -> 60498.918 | H47: =H37+H45 -> 63487.763 | I47: =I37+I45 -> 66509.531 | ... L47: =L37+L45 -> 75681.983
A49: Balance Check (Assets - L&E) | B49: =B22-B47 -> 0 | C49: =C22-C47 -> 0 | D49: =D22-D47 -> 0 | E49: =E22-E47 -> 0 | F49: =F22-F47 -> 0 | G49: =G22-G47 -> 0 | H49: =H22-H47 -> 0 | I49: =I22-I47 -> 0 | ... L49: =L22-L47 -> 0
...

Sheet Cash flow
A3: NET INCOME | G3: ='Income statement'!G26 -> 4442.681 | H3: ='Income statement'!H26 -> 4630.0453 | I3: ='Income statement'!I26 -> 4870.8523 | J3: ='Income statement'!J26 -> 5092.135 | K3: ='Income statement'!K26 -> 5369.7801 | L3: ='Income statement'!L26 -> 5646.6811
A4: 46387 | G4: 2026 | H4: 2027 | I4: 2028 | J4: 2029 | K4: 2030 | L4: 2031
A5: ASSETS
A6: Current assets:
A7: Cash and equivalents
A8: Accounts receivable | G8: ='Balance sheet'!F9-'Balance sheet'!G9 -> -147.3666 | H8: ='Balance sheet'!G9-'Balance sheet'!H9 -> -115.11762 | I8: ='Balance sheet'!H9-'Balance sheet'!I9 -> -126.75916 | J8: ='Balance sheet'!I9-'Balance sheet'!J9 -> -136.05538 | K8: ='Balance sheet'!J9-'Balance sheet'!K9 -> -144.57705 | L8: ='Balance sheet'!K9-'Balance sheet'!L9 -> -153.77798
A9: Unbilled receivables | G9: ='Balance sheet'!F10-'Balance sheet'!G10 -> -391.56527 | H9: ='Balance sheet'!G10-'Balance sheet'!H10 -> -395.46287 | I9: ='Balance sheet'!H10-'Balance sheet'!I10 -> -435.455 | J9: ='Balance sheet'!I10-'Balance sheet'!J10 -> -467.39025 | K9: ='Balance sheet'!J10-'Balance sheet'!K10 -> -496.66468 | L9: ='Balance sheet'!K10-'Balance sheet'!L10 -> -528.27258
A10: Inventories | G10: ='Balance sheet'!F11-'Balance sheet'!G11 -> -328.36179 | H10: ='Balance sheet'!G11-'Balance sheet'!H11 -> -430.89898 | I10: ='Balance sheet'!H11-'Balance sheet'!I11 -> -474.44746 | J10: ='Balance sheet'!I11-'Balance sheet'!J11 -> -509.23874 | K10: ='Balance sheet'!J11-'Balance sheet'!K11 -> -541.14236 | L10: ='Balance sheet'!K11-'Balance sheet'!L11 -> -575.59101
A11: Other current assets | G11: ='Balance sheet'!F12-'Balance sheet'!G12 -> -295.89132 | H11: ='Balance sheet'!G12-'Balance sheet'!H12 -> -98.865717 | I11: ='Balance sheet'!H12-'Balance sheet'!I12 -> -108.86375 | J11: ='Balance sheet'!I12-'Balance sheet'!J12 -> -116.84756 | K11: ='Balance sheet'!J12-'Balance sheet'!K12 -> -124.16617 | L11: ='Balance sheet'!K12-'Balance sheet'!L12 -> -132.06814
A12: Total current assets
G13: ='Balance sheet'!F14-'Balance sheet'!G14 -> 0 | H13: ='Balance sheet'!G14-'Balance sheet'!H14 -> 0 | I13: ='Balance sheet'!H14-'Balance sheet'!I14 -> 0 | J13: ='Balance sheet'!I14-'Balance sheet'!J14 -> 0 | K13: ='Balance sheet'!J14-'Balance sheet'!K14 -> 0 | L13: ='Balance sheet'!K14-'Balance sheet'!L14 -> 0
A14: Noncurrent assets: | G14: ='Balance sheet'!F15-'Balance sheet'!G15 -> 0 | H14: ='Balance sheet'!G15-'Balance sheet'!H15 -> 0 | I14: ='Balance sheet'!H15-'Balance sheet'!I15 -> 0 | J14: ='Balance sheet'!I15-'Balance sheet'!J15 -> 0 | K14: ='Balance sheet'!J15-'Balance sheet'!K15 -> 0 | L14: ='Balance sheet'!K15-'Balance sheet'!L15 -> 0
A15: Property, plant and equipment, net | G15: ='Balance sheet'!F16-'Balance sheet'!G16 -> -1355 | H15: ='Balance sheet'!G16-'Balance sheet'!H16 -> -1185 | I15: ='Balance sheet'!H16-'Balance sheet'!I16 -> -895 | J15: ='Balance sheet'!I16-'Balance sheet'!J16 -> -592 | K15: ='Balance sheet'!J16-'Balance sheet'!K16 -> -275 | L15: ='Balance sheet'!K16-'Balance sheet'!L16 -> -280
A16: Intangible assets, net | G16: ='Balance sheet'!F17-'Balance sheet'!G17 -> 150 | H16: ='Balance sheet'!G17-'Balance sheet'!H17 -> 150 | I16: ='Balance sheet'!H17-'Balance sheet'!I17 -> 150 | J16: ='Balance sheet'!I17-'Balance sheet'!J17 -> 150 | K16: ='Balance sheet'!J17-'Balance sheet'!K17 -> 150 | L16: ='Balance sheet'!K17-'Balance sheet'!L17 -> 150
A17: Goodwill | G17: ='Balance sheet'!F18-'Balance sheet'!G18 -> 0 | H17: ='Balance sheet'!G18-'Balance sheet'!H18 -> 0 | I17: ='Balance sheet'!H18-'Balance sheet'!I18 -> 0 | J17: ='Balance sheet'!I18-'Balance sheet'!J18 -> 0 | K17: ='Balance sheet'!J18-'Balance sheet'!K18 -> 0 | L17: ='Balance sheet'!K18-'Balance sheet'!L18 -> 0
A18: Other assets | G18: ='Balance sheet'!F19-'Balance sheet'!G19 -> -370.45844 | H18: ='Balance sheet'!G19-'Balance sheet'!H19 -> -156.10369 | I18: ='Balance sheet'!H19-'Balance sheet'!I19 -> -171.89006 | J18: ='Balance sheet'!I19-'Balance sheet'!J19 -> -184.49607 | K18: ='Balance sheet'!J19-'Balance sheet'!K19 -> -196.05176 | L18: ='Balance sheet'!K19-'Balance sheet'!L19 -> -208.52856
A19: Total noncurrent assets
A21: Total assets
A23: LIABILITIES AND SHAREHOLDERS' EQUITY
A24: Current liabilities:
A25: Short-term debt and current portion of long-term debt | G25: ='Balance sheet'!G26-'Balance sheet'!F26 -> 251 | H25: ='Balance sheet'!H26-'Balance sheet'!G26 -> -250 | I25: ='Balance sheet'!I26-'Balance sheet'!H26 -> -1000 | J25: ='Balance sheet'!J26-'Balance sheet'!I26 -> 1000 | K25: ='Balance sheet'!K26-'Balance sheet'!J26 -> -507 | L25: ='Balance sheet'!L26-'Balance sheet'!K26 -> -500
A26: Accounts payable | G26: ='Balance sheet'!G27-'Balance sheet'!F27 -> 126.37279 | H26: ='Balance sheet'!H27-'Balance sheet'!G27 -> 126.39703 | I26: ='Balance sheet'!I27-'Balance sheet'!H27 -> 139.17126 | J26: ='Balance sheet'!J27-'Balance sheet'!I27 -> 149.3767 | K26: ='Balance sheet'!K27-'Balance sheet'!J27 -> 158.73509 | L26: ='Balance sheet'!L27-'Balance sheet'!K27 -> 168.84003
A27: Customer advances and deposits | G27: ='Balance sheet'!G28-'Balance sheet'!F28 -> 742.25699 | H27: ='Balance sheet'!H28-'Balance sheet'!G28 -> 476.3759 | I27: ='Balance sheet'!I28-'Balance sheet'!H28 -> 524.55056 | J27: ='Balance sheet'!J28-'Balance sheet'!I28 -> 563.01987 | K27: ='Balance sheet'!K28-'Balance sheet'!J28 -> 598.28394 | L27: ='Balance sheet'!L28-'Balance sheet'!K28 -> 636.35892
A28: Other current liabilities | G28: ='Balance sheet'!G29-'Balance sheet'!F29 -> 1.3369762 | H28: ='Balance sheet'!H29-'Balance sheet'!G29 -> 148.29858 | I28: ='Balance sheet'!I29-'Balance sheet'!H29 -> 163.29563 | J28: ='Balance sheet'!J29-'Balance sheet'!I29 -> 175.27135 | K28: ='Balance sheet'!K29-'Balance sheet'!J29 -> 186.24925 | L28: ='Balance sheet'!L29-'Balance sheet'!K29 -> 198.10222
A29: Total current liabilities
G30: ='Balance sheet'!G31-'Balance sheet'!F31 -> 0 | H30: ='Balance sheet'!H31-'Balance sheet'!G31 -> 0 | I30: ='Balance sheet'!I31-'Balance sheet'!H31 -> 0 | J30: ='Balance sheet'!J31-'Balance sheet'!I31 -> 0 | K30: ='Balance sheet'!K31-'Balance sheet'!J31 -> 0 | L30: ='Balance sheet'!L31-'Balance sheet'!K31 -> 0
A31: Noncurrent liabilities: | G31: ='Balance sheet'!G32-'Balance sheet'!F32 -> 0 | H31: ='Balance sheet'!H32-'Balance sheet'!G32 -> 0 | I31: ='Balance sheet'!I32-'Balance sheet'!H32 -> 0 | J31: ='Balance sheet'!J32-'Balance sheet'!I32 -> 0 | K31: ='Balance sheet'!K32-'Balance sheet'!J32 -> 0 | L31: ='Balance sheet'!L32-'Balance sheet'!K32 -> 0
A32: Long-term debt | G32: ='Balance sheet'!G33-'Balance sheet'!F33 -> 224 | H32: ='Balance sheet'!H33-'Balance sheet'!G33 -> 699 | I32: ='Balance sheet'!I33-'Balance sheet'!H33 -> 1424 | J32: ='Balance sheet'!J33-'Balance sheet'!I33 -> -601 | K32: ='Balance sheet'!K33-'Balance sheet'!J33 -> 906 | L32: ='Balance sheet'!L33-'Balance sheet'!K33 -> 856
A33: Other liabilities | G33: ='Balance sheet'!G34-'Balance sheet'!F34 -> 399.34244 | H33: ='Balance sheet'!H34-'Balance sheet'!G34 -> 370.74644 | I33: ='Balance sheet'!I34-'Balance sheet'!H34 -> 408.23907 | J33: ='Balance sheet'!J34-'Balance sheet'!I34 -> 438.17836 | K33: ='Balance sheet'!K34-'Balance sheet'!J34 -> 465.62314 | L33: ='Balance sheet'!L34-'Balance sheet'!K34 -> 495.25554
A34: Total noncurrent liabilities
G35: ='Balance sheet'!G36-'Balance sheet'!F36 -> 0 | H35: ='Balance sheet'!H36-'Balance sheet'!G36 -> 0 | I35: ='Balance sheet'!I36-'Balance sheet'!H36 -> 0 | J35: ='Balance sheet'!J36-'Balance sheet'!I36 -> 0 | K35: ='Balance sheet'!K36-'Balance sheet'!J36 -> 0 | L35: ='Balance sheet'!L36-'Balance sheet'!K36 -> 0
A36: Total liabilities
G37: ='Balance sheet'!G38-'Balance sheet'!F38 -> 0 | H37: ='Balance sheet'!H38-'Balance sheet'!G38 -> 0 | I37: ='Balance sheet'!I38-'Balance sheet'!H38 -> 0 | J37: ='Balance sheet'!J38-'Balance sheet'!I38 -> 0 | K37: ='Balance sheet'!K38-'Balance sheet'!J38 -> 0 | L37: ='Balance sheet'!L38-'Balance sheet'!K38 -> 0
A38: Shareholders' equity: | G38: ='Balance sheet'!G39-'Balance sheet'!F39 -> 0 | H38: ='Balance sheet'!H39-'Balance sheet'!G39 -> 0 | I38: ='Balance sheet'!I39-'Balance sheet'!H39 -> 0 | J38: ='Balance sheet'!J39-'Balance sheet'!I39 -> 0 | K38: ='Balance sheet'!K39-'Balance sheet'!J39 -> 0 | L38: ='Balance sheet'!L39-'Balance sheet'!K39 -> 0
A39: Common stock | G39: ='Balance sheet'!G40-'Balance sheet'!F40 -> 0 | H39: ='Balance sheet'!H40-'Balance sheet'!G40 -> 0 | I39: ='Balance sheet'!I40-'Balance sheet'!H40 -> 0 | J39: ='Balance sheet'!J40-'Balance sheet'!I40 -> 0 | K39: ='Balance sheet'!K40-'Balance sheet'!J40 -> 0 | L39: ='Balance sheet'!L40-'Balance sheet'!K40 -> 0
A40: Surplus | G40: ='Balance sheet'!G41-'Balance sheet'!F41 -> 340 | H40: ='Balance sheet'!H41-'Balance sheet'!G41 -> 340 | I40: ='Balance sheet'!I41-'Balance sheet'!H41 -> 340 | J40: ='Balance sheet'!J41-'Balance sheet'!I41 -> 340 | K40: ='Balance sheet'!K41-'Balance sheet'!J41 -> 340 | L40: ='Balance sheet'!L41-'Balance sheet'!K41 -> 340
A43: Accumulated other comprehensive loss | G43: ='Balance sheet'!G44-'Balance sheet'!F44 -> 0 | H43: ='Balance sheet'!H44-'Balance sheet'!G44 -> 0 | I43: ='Balance sheet'!I44-'Balance sheet'!H44 -> 0 | J43: ='Balance sheet'!J44-'Balance sheet'!I44 -> 0 | K43: ='Balance sheet'!K44-'Balance sheet'!J44 -> 0 | L43: ='Balance sheet'!L44-'Balance sheet'!K44 -> 0
A44: Total shareholders' equity
A46: Total liabilities and shareholders' equity
A48: FCFE | G48: =SUM(G8:G43)+G3 -> 3788.3468 | H48: =SUM(H8:H43)+H3 -> 4309.4143 | I48: =SUM(I8:I43)+I3 -> 4807.6934 | J48: =SUM(J8:J43)+J3 -> 5300.9532 | K48: =SUM(K8:K43)+K3 -> 5890.0695 | L48: =SUM(L8:L43)+L3 -> 6112.9996
...

Sheet Equity
A1: General Dynamics Corporation
A2: Shareholders' Equity Schedule
A3: (Dollars in millions)
B5: 2021 | C5: 2022 | D5: 2023 | E5: 2024 | F5: 2025 | G5: 2026 | H5: 2027 | I5: 2028 | J5: 2029 | K5: 2030 | L5: 2031 | N5: Projection Assumptions
N6: SHAREHOLDERS' EQUITY SCHEDULE
A7: RETAINED EARNINGS ROLLFORWARD
A8: Beginning Balance | B8: 33512 | C8: =B13 -> 35420 | D8: =C13 -> 37403 | E8: =D13 -> 39270 | F8: =E13 -> 41487 | G8: =F13 -> 44080 | H8: =G13 -> 46745.609 | I8: =H13 -> 49523.636 | J8: =I13 -> 52446.147 | ... L8: =K13 -> 58723.296
